Workbook

Sheet 00_Dashboard
A1: ECAR | OBRA ROQUE — TABLERO DE CONTROL
A2: Flujo: Estado Actual → Para Programar → Planificación → Orden Diaria → Parte Diario → Control Semanal.
A4: ESTADO DE OBRA | B4: VALOR | D4: OPERACIÓN | E4: VALOR | G4: CALIDAD / ESPECIALES | H4: VALOR
A5: Ítems cargados | B5: =COUNTIF('01_Estado_Actual'!$E$5:$E$1204,">0") -> 1200 | D5: Plan Maestro cargado | E5: =COUNTIF('03_Planificacion'!$B$5:$B$84,"<>") -> 0 | G5: Servicios proyecto | H5: =SUM('07_Base_Tecnica'!$Q$5:$Q$54) -> 227
A6: Terminadas | B6: =COUNTIF('01_Estado_Actual'!$L$5:$L$1204,"Terminada") -> 307 | D6: Programaciones cargadas | E6: =COUNTIF('03_Planificacion'!$B$99:$B$138,"<>") -> 0 | G6: Vainas colocadas | H6: =MAX(COUNTIF('06_Control_Semanal'!$D$283:$D$533,"Colocada"),SUMIFS('05_Parte_Diario'!$H$5:$H$104,'05_Parte_Diario'!$E$5:$E$104,"06 Servicios - Colocación de vaina / caño camisa")) -> 0
A7: Para Programar | B7: =COUNTIF('01_Estado_Actual'!$L$5:$L$1204,"Para Programar") -> 144 | D7: ODT generadas | E7: =COUNTIF('04_Orden_Diaria'!$C$5:$C$44,"<>") -> 0 | G7: Base servicio aprobada | H7: =COUNTIF('06_Control_Semanal'!$F$283:$F$533,"Aprobado") -> 0
A8: En curso | B8: =COUNTIF('01_Estado_Actual'!$L$5:$L$1204,"En curso") -> 0 | D8: Partes con ejecución | E8: =COUNTIF('05_Parte_Diario'!$H$5:$H$104,">0") -> 0 | G8: Paquete servicio aprobado | H8: =COUNTIF('06_Control_Semanal'!$H$283:$H$533,"Aprobado") -> 0
A9: Bloqueadas | B9: =COUNTIF('01_Estado_Actual'!$L$5:$L$1204,"Bloqueada") -> 0 | D9: Desvíos abiertos | E9: =COUNTIFS('06_Control_Semanal'!$B$133:$B$192,">0",'06_Control_Semanal'!$M$133:$M$192,"<>Terminada") -> 0 | G9: Servicios terminados | H9: =COUNTIF('06_Control_Semanal'!$I$283:$I$533,"Terminado") -> 0
A10: Avance real prom.* | B10: =IFERROR(AVERAGE('01_Estado_Actual'!$H$5:$H$1204),0) -> 0.24359053 | D10: Para Programar sin Plan | E10: =COUNTIF('02_Para_Programar'!$K$5:$K$224,"NO") -> 165 | G10: Hidrantes confirmados | H10: =COUNTIF('06_Control_Semanal'!$C$203:$C$222,"<>") -> 0
A11: Alertas de consistencia | B11: =COUNTIF('01_Estado_Actual'!$T$5:$T$1204,"INCONSISTENCIA - REVISAR MANUALMENTE: Terminada con saldo")+COUNTIF('01_Estado_Actual'!$T$5:$T$1204,"INCONSISTENCIA - REVISAR MANUALMENTE: Para Programar sin saldo") -> 15 | D11: Metas > saldo | E11: =COUNTIF('03_Planificacion'!$S$99:$S$138,"REVISAR > SALDO") -> 0 | G11: Hidrantes terminados | H11: =COUNTIF('06_Control_Semanal'!$D$203:$D$222,100) -> 0
G12: Hidrantes con alerta | H12: =COUNTIF('06_Control_Semanal'!$H$203:$H$222,"ALERTA*") -> 0
A14: CAPACIDAD OPERATIVA
A15: Plan Maestro | B15: 80 actividades | C15: Programación semanal | D15: 40 compromisos | E15: ODT | F15: 40 órdenes | G15: Parte Diario | H15: 100 registros
A16: Nota | B16: Los bloques de Programación/ODT/Parte pueden ampliarse sin cambiar el modelo cuando la operación lo requiera.

Sheet 01_Estado_Actual
A1: ECAR | OBRA ROQUE — ESTADO ACTUAL Y AVANCE | V1: 46287
A2: Corte físico de obra. Total y datos técnicos se conservan; Ejecutado/Saldo/%/Plan/Desvío quedan calculados. Estado define qué pasa a programación.
A4: Código | B4: Sector / Tramo | C4: Actividad | D4: Unidad | E4: Total obra | F4: Ejecutado acumulado | G4: Saldo | H4: % avance real | I4: Planificado a fecha | J4: % avance plan. | K4: Desvío (pp) | L4: Estado | M4: Restricción / Observación | N4: Prioridad | O4: Responsable | P4: Fecha de corte | Q4: Pasaje / Calle | R4: Ø (mm) | S4: Tipo de red | T4: Alerta | U4: Orden PP válido | W4: Clave | X4: Ejecutado base corte
A5: AG-01 | B5: N1 - N2 | C5: 01 Replanteo - Marcación de tramo de cañería principal | D5: m | E5: 165 | F5: =IF(E5="","",MIN(E5,$X5+SUMIFS('05_Parte_Diario'!$H$5:$H$204,'05_Parte_Diario'!$D$5:$D$204,B5,'05_Parte_Diario'!$E$5:$E$204,C5))) -> 0 | G5: =IF(E5="","",MAX(E5-F5,0)) -> 165 | H5: =IFERROR(F5/E5,0) -> 0 | I5: =IF(OR(B5="",C5="",$V$1=""),"",MIN(E5,SUMIFS('03_Planificacion'!$G$99:$G$178,'03_Planificacion'!$E$99:$E$178,B5,'03_Planificacion'!$F$99:$F$178,C5,'03_Planificacion'!$D$99:$D$178,"<="&$V$1))) -> 0 | J5: =IFERROR(I5/E5,0) -> 0 | K5: =IF(OR(E5="",$V$1=""),"",H5-J5) -> 0 | L5: No iniciada | P5: =IF(A5="","",$V$1) -> 46287 | Q5: Pasaje N°13 | R5: 75 | S5: Red distribuidora | T5: =IF(A5="","",IF(AND(L5="Para Programar",G5=0),"INCONSISTENCIA - REVISAR MANUALMENTE: Para Programar sin saldo",IF(AND(L5="Terminada",G5>0),"INCONSISTENCIA - REVISAR MANUALMENTE: Terminada con saldo",""))) | U5: =IF(AND(L5="Para Programar",G5>0),COUNTIFS($L$5:L5,"Para Programar",$G$5:G5,">0"),"") | W5: =IF(OR(B5="",C5=""),"",B5&"|"&C5) -> N1 - N2|01 Replanteo - Marcación de tramo de cañería principal | X5: 0
A6: AG-03 | B6: N1 - N2 | C6: 02 Excavación - Zanja principal | D6: m | E6: 165 | F6: =IF(E6="","",MIN(E6,$X6+SUMIFS('05_Parte_Diario'!$H$5:$H$204,'05_Parte_Diario'!$D$5:$D$204,B6,'05_Parte_Diario'!$E$5:$E$204,C6))) -> 0 | G6: =IF(E6="","",MAX(E6-F6,0)) -> 165 | H6: =IFERROR(F6/E6,0) -> 0 | I6: =IF(OR(B6="",C6="",$V$1=""),"",MIN(E6,SUMIFS('03_Planificacion'!$G$99:$G$178,'03_Planificacion'!$E$99:$E$178,B6,'03_Planificacion'!$F$99:$F$178,C6,'03_Planificacion'!$D$99:$D$178,"<="&$V$1))) -> 0 | J6: =IFERROR(I6/E6,0) -> 0 | K6: =IF(OR(E6="",$V$1=""),"",H6-J6) -> 0 | L6: No iniciada | P6: =IF(A6="","",$V$1) -> 46287 | Q6: Pasaje N°13 | R6: 75 | S6: Red distribuidora | T6: =IF(A6="","",IF(AND(L6="Para Programar",G6=0),"INCONSISTENCIA - REVISAR MANUALMENTE: Para Programar sin saldo",IF(AND(L6="Terminada",G6>0),"INCONSISTENCIA - REVISAR MANUALMENTE: Terminada con saldo",""))) | U6: =IF(AND(L6="Para Programar",G6>0),COUNTIFS($L$5:L6,"Para Programar",$G$5:G6,">0"),"") | W6: =IF(OR(B6="",C6=""),"",B6&"|"&C6) -> N1 - N2|02 Excavación - Zanja principal | X6: 0
A7: AG-05 | B7: N1 - N2 | C7: 03 Base de asiento - Nivelación de fondo de zanja | D7: m | E7: 165 | F7: =IF(E7="","",MIN(E7,$X7+SUMIFS('05_Parte_Diario'!$H$5:$H$204,'05_Parte_Diario'!$D$5:$D$204,B7,'05_Parte_Diario'!$E$5:$E$204,C7))) -> 0 | G7: =IF(E7="","",MAX(E7-F7,0)) -> 165 | H7: =IFERROR(F7/E7,0) -> 0 | I7: =IF(OR(B7="",C7="",$V$1=""),"",MIN(E7,SUMIFS('03_Planificacion'!$G$99:$G$178,'03_Planificacion'!$E$99:$E$178,B7,'03_Planificacion'!$F$99:$F$178,C7,'03_Planificacion'!$D$99:$D$178,"<="&$V$1))) -> 0 | J7: =IFERROR(I7/E7,0) -> 0 | K7: =IF(OR(E7="",$V$1=""),"",H7-J7) -> 0 | L7: No iniciada | P7: =IF(A7="","",$V$1) -> 46287 | Q7: Pasaje N°13 | R7: 75 | S7: Red distribuidora | T7: =IF(A7="","",IF(AND(L7="Para Programar",G7=0),"INCONSISTENCIA - REVISAR MANUALMENTE: Para Programar sin saldo",IF(AND(L7="Terminada",G7>0),"INCONSISTENCIA - REVISAR MANUALMENTE: Terminada con saldo",""))) | U7: =IF(AND(L7="Para Programar",G7>0),COUNTIFS($L$5:L7,"Para Programar",$G$5:G7,">0"),"") | W7: =IF(OR(B7="",C7=""),"",B7&"|"&C7) -> N1 - N2|03 Base de asiento - Nivelación de fondo de zanja | X7: 0
A8: AG-06 | B8: N1 - N2 | C8: 03 Base de asiento - Aporte de material base e=0,10 m | D8: m | E8: 165 | F8: =IF(E8="","",MIN(E8,$X8+SUMIFS('05_Parte_Diario'!$H$5:$H$204,'05_Parte_Diario'!$D$5:$D$204,B8,'05_Parte_Diario'!$E$5:$E$204,C8))) -> 0 | G8: =IF(E8="","",MAX(E8-F8,0)) -> 165 | H8: =IFERROR(F8/E8,0) -> 0 | I8: =IF(OR(B8="",C8="",$V$1=""),"",MIN(E8,SUMIFS('03_Planificacion'!$G$99:$G$178,'03_Planificacion'!$E$99:$E$178,B8,'03_Planificacion'!$F$99:$F$178,C8,'03_Planificacion'!$D$99:$D$178,"<="&$V$1))) -> 0 | J8: =IFERROR(I8/E8,0) -> 0 | K8: =IF(OR(E8="",$V$1=""),"",H8-J8) -> 0 | L8: No iniciada | P8: =IF(A8="","",$V$1) -> 46287 | Q8: Pasaje N°13 | R8: 75 | S8: Red distribuidora | T8: =IF(A8="","",IF(AND(L8="Para Programar",G8=0),"INCONSISTENCIA - REVISAR MANUALMENTE: Para Programar sin saldo",IF(AND(L8="Terminada",G8>0),"INCONSISTENCIA - REVISAR MANUALMENTE: Terminada con saldo",""))) | U8: =IF(AND(L8="Para Programar",G8>0),COUNTIFS($L$5:L8,"Para Programar",$G$5:G8,">0"),"") | W8: =IF(OR(B8="",C8=""),"",B8&"|"&C8) -> N1 - N2|03 Base de asiento - Aporte de material base e=0,10 m | X8: 0
A9: AG-07 | B9: N1 - N2 | C9: 03 Base de asiento - Compactación | D9: m | E9: 165 | F9: =IF(E9="","",MIN(E9,$X9+SUMIFS('05_Parte_Diario'!$H$5:$H$204,'05_Parte_Diario'!$D$5:$D$204,B9,'05_Parte_Diario'!$E$5:$E$204,C9))) -> 0 | G9: =IF(E9="","",MAX(E9-F9,0)) -> 165 | H9: =IFERROR(F9/E9,0) -> 0 | I9: =IF(OR(B9="",C9="",$V$1=""),"",MIN(E9,SUMIFS('03_Planificacion'!$G$99:$G$178,'03_Planificacion'!$E$99:$E$178,B9,'03_Planificacion'!$F$99:$F$178,C9,'03_Planificacion'!$D$99:$D$178,"<="&$V$1))) -> 0 | J9: =IFERROR(I9/E9,0) -> 0 | K9: =IF(OR(E9="",$V$1=""),"",H9-J9) -> 0 | L9: No iniciada | P9: =IF(A9="","",$V$1) -> 46287 | Q9: Pasaje N°13 | R9: 75 | S9: Red distribuidora | T9: =IF(A9="","",IF(AND(L9="Para Programar",G9=0),"INCONSISTENCIA - REVISAR MANUALMENTE: Para Programar sin saldo",IF(AND(L9="Terminada",G9>0),"INCONSISTENCIA - REVISAR MANUALMENTE: Terminada con saldo",""))) | U9: =IF(AND(L9="Para Programar",G9>0),COUNTIFS($L$5:L9,"Para Programar",$G$5:G9,">0"),"") | W9: =IF(OR(B9="",C9=""),"",B9&"|"&C9) -> N1 - N2|03 Base de asiento - Compactación | X9: 0
A10: HI-01 | B10: N1 - N2 | C10: 04 Inspecciones previas - Laboratorio base de asiento | D10: tramo | E10: 1 | F10: =IF(E10="","",MIN(E10,$X10+SUMIFS('05_Parte_Diario'!$H$5:$H$204,'05_Parte_Diario'!$D$5:$D$204,B10,'05_Parte_Diario'!$E$5:$E$204,C10))) -> 0 | G10: =IF(E10="","",MAX(E10-F10,0)) -> 1 | H10: =IFERROR(F10/E10,0) -> 0 | I10: =IF(OR(B10="",C10="",$V$1=""),"",MIN(E10,SUMIFS('03_Planificacion'!$G$99:$G$178,'03_Planificacion'!$E$99:$E$178,B10,'03_Planificacion'!$F$99:$F$178,C10,'03_Planificacion'!$D$99:$D$178,"<="&$V$1))) -> 0 | J10: =IFERROR(I10/E10,0) -> 0 | K10: =IF(OR(E10="",$V$1=""),"",H10-J10) -> 0 | L10: No iniciada | P10: =IF(A10="","",$V$1) -> 46287 | Q10: Pasaje N°13 | R10: 75 | S10: Red distribuidora | T10: =IF(A10="","",IF(AND(L10="Para Programar",G10=0),"INCONSISTENCIA - REVISAR MANUALMENTE: Para Programar sin saldo",IF(AND(L10="Terminada",G10>0),"INCONSISTENCIA - REVISAR MANUALMENTE: Terminada con saldo",""))) | U10: =IF(AND(L10="Para Programar",G10>0),COUNTIFS($L$5:L10,"Para Programar",$G$5:G10,">0"),"") | W10: =IF(OR(B10="",C10=""),"",B10&"|"&C10) -> N1 - N2|04 Inspecciones previas - Laboratorio base de asiento | X10: 0
A11: HI-02 | B11: N1 - N2 | C11: 04 Inspecciones previas - Zanja y materiales | D11: tramo | E11: 1 | F11: =IF(E11="","",MIN(E11,$X11+SUMIFS('05_Parte_Diario'!$H$5:$H$204,'05_Parte_Diario'!$D$5:$D$204,B11,'05_Parte_Diario'!$E$5:$E$204,C11))) -> 0 | G11: =IF(E11="","",MAX(E11-F11,0)) -> 1 | H11: =IFERROR(F11/E11,0) -> 0 | I11: =IF(OR(B11="",C11="",$V$1=""),"",MIN(E11,SUMIFS('03_Planificacion'!$G$99:$G$178,'03_Planificacion'!$E$99:$E$178,B11,'03_Planificacion'!$F$99:$F$178,C11,'03_Planificacion'!$D$99:$D$178,"<="&$V$1))) -> 0 | J11: =IFERROR(I11/E11,0) -> 0 | K11: =IF(OR(E11="",$V$1=""),"",H11-J11) -> 0 | L11: No iniciada | P11: =IF(A11="","",$V$1) -> 46287 | Q11: Pasaje N°13 | R11: 75 | S11: Red distribuidora | T11: =IF(A11="","",IF(AND(L11="Para Programar",G11=0),"INCONSISTENCIA - REVISAR MANUALMENTE: Para Programar sin saldo",IF(AND(L11="Terminada",G11>0),"INCONSISTENCIA - REVISAR MANUALMENTE: Terminada con saldo",""))) | U11: =IF(AND(L11="Para Programar",G11>0),COUNTIFS($L$5:L11,"Para Programar",$G$5:G11,">0"),"") | W11: =IF(OR(B11="",C11=""),"",B11&"|"&C11) -> N1 - N2|04 Inspecciones previas - Zanja y materiales | X11: 0
A12: AG-08 | B12: N1 - N2 | C12: 05 Tendido de cañería - Cañería principal | D12: m | E12: 165 | F12: =IF(E12="","",MIN(E12,$X12+SUMIFS('05_Parte_Diario'!$H$5:$H$204,'05_Parte_Diario'!$D$5:$D$204,B12,'05_Parte_Diario'!$E$5:$E$204,C12))) -> 0 | G12: =IF(E12="","",MAX(E12-F12,0)) -> 165 | H12: =IFERROR(F12/E12,0) -> 0 | I12: =IF(OR(B12="",C12="",$V$1=""),"",MIN(E12,SUMIFS('03_Planificacion'!$G$99:$G$178,'03_Planificacion'!$E$99:$E$178,B12,'03_Planificacion'!$F$99:$F$178,C12,'03_Planificacion'!$D$99:$D$178,"<="&$V$1))) -> 0 | J12: =IFERROR(I12/E12,0) -> 0 | K12: =IF(OR(E12="",$V$1=""),"",H12-J12) -> 0 | L12: No iniciada | P12: =IF(A12="","",$V$1) -> 46287 | Q12: Pasaje N°13 | R12: 75 | S12: Red distribuidora | T12: =IF(A12="","",IF(AND(L12="Para Programar",G12=0),"INCONSISTENCIA - REVISAR MANUALMENTE: Para Programar sin saldo",IF(AND(L12="Terminada",G12>0),"INCONSISTENCIA - REVISAR MANUALMENTE: Terminada con saldo",""))) | U12: =IF(AND(L12="Para Programar",G12>0),COUNTIFS($L$5:L12,"Para Programar",$G$5:G12,">0"),"") | W12: =IF(OR(B12="",C12=""),"",B12&"|"&C12) -> N1 - N2|05 Tendido de cañería - Cañería principal | X12: 0
A13: AG-09 | B13: N1 - N2 | C13: 05 Tendido de cañería - Relevamiento planialtimétrico | D13: m | E13: 165 | F13: =IF(E13="","",MIN(E13,$X13+SUMIFS('05_Parte_Diario'!$H$5:$H$204,'05_Parte_Diario'!$D$5:$D$204,B13,'05_Parte_Diario'!$E$5:$E$204,C13))) -> 0 | G13: =IF(E13="","",MAX(E13-F13,0)) -> 165 | H13: =IFERROR(F13/E13,0) -> 0 | I13: =IF(OR(B13="",C13="",$V$1=""),"",MIN(E13,SUMIFS('03_Planificacion'!$G$99:$G$178,'03_Planificacion'!$E$99:$E$178,B13,'03_Planificacion'!$F$99:$F$178,C13,'03_Planificacion'!$D$99:$D$178,"<="&$V$1))) -> 0 | J13: =IFERROR(I13/E13,0) -> 0 | K13: =IF(OR(E13="",$V$1=""),"",H13-J13) -> 0 | L13: No iniciada | P13: =IF(A13="","",$V$1) -> 46287 | Q13: Pasaje N°13 | R13: 75 | S13: Red distribuidora | T13: =IF(A13="","",IF(AND(L13="Para Programar",G13=0),"INCONSISTENCIA - REVISAR MANUALMENTE: Para Programar sin saldo",IF(AND(L13="Terminada",G13>0),"INCONSISTENCIA - REVISAR MANUALMENTE: Terminada con saldo",""))) | U13: =IF(AND(L13="Para Programar",G13>0),COUNTIFS($L$5:L13,"Para Programar",$G$5:G13,">0"),"") | W13: =IF(OR(B13="",C13=""),"",B13&"|"&C13) -> N1 - N2|05 Tendido de cañería - Relevamiento planialtimétrico | X13: 0
A14: AG-17 | B14: N1 - N2 | C14: 08 Prueba hidráulica - Preparación del sistema | D14: tramo | E14: 1 | F14: =IF(E14="","",MIN(E14,$X14+SUMIFS('05_Parte_Diario'!$H$5:$H$204,'05_Parte_Diario'!$D$5:$D$204,B14,'05_Parte_Diario'!$E$5:$E$204,C14))) -> 0 | G14: =IF(E14="","",MAX(E14-F14,0)) -> 1 | H14: =IFERROR(F14/E14,0) -> 0 | I14: =IF(OR(B14="",C14="",$V$1=""),"",MIN(E14,SUMIFS('03_Planificacion'!$G$99:$G$178,'03_Planificacion'!$E$99:$E$178,B14,'03_Planificacion'!$F$99:$F$178,C14,'03_Planificacion'!$D$99:$D$178,"<="&$V$1))) -> 0 | J14: =IFERROR(I14/E14,0) -> 0 | K14: =IF(OR(E14="",$V$1=""),"",H14-J14) -> 0 | L14: No iniciada | P14: =IF(A14="","",$V$1) -> 46287 | Q14: Pasaje N°13 | R14: 75 | S14: Red distribuidora | T14: =IF(A14="","",IF(AND(L14="Para Programar",G14=0),"INCONSISTENCIA - REVISAR MANUALMENTE: Para Programar sin saldo",IF(AND(L14="Terminada",G14>0),"INCONSISTENCIA - REVISAR MANUALMENTE: Terminada con saldo",""))) | U14: =IF(AND(L14="Para Programar",G14>0),COUNTIFS($L$5:L14,"Para Programar",$G$5:G14,">0"),"") | W14: =IF(OR(B14="",C14=""),"",B14&"|"&C14) -> N1 - N2|08 Prueba hidráulica - Preparación del sistema | X14: 0
A15: AG-18 | B15: N1 - N2 | C15: 08 Prueba hidráulica - Interna N° 1 | D15: tramo | E15: 1 | F15: =IF(E15="","",MIN(E15,$X15+SUMIFS('05_Parte_Diario'!$H$5:$H$204,'05_Parte_Diario'!$D$5:$D$204,B15,'05_Parte_Diario'!$E$5:$E$204,C15))) -> 0 | G15: =IF(E15="","",MAX(E15-F15,0)) -> 1 | H15: =IFERROR(F15/E15,0) -> 0 | I15: =IF(OR(B15="",C15="",$V$1=""),"",MIN(E15,SUMIFS('03_Planificacion'!$G$99:$G$178,'03_Planificacion'!$E$99:$E$178,B15,'03_Planificacion'!$F$99:$F$178,C15,'03_Planificacion'!$D$99:$D$178,"<="&$V$1))) -> 0 | J15: =IFERROR(I15/E15,0) -> 0 | K15: =IF(OR(E15="",$V$1=""),"",H15-J15) -> 0 | L15: No iniciada | P15: =IF(A15="","",$V$1) -> 46287 | Q15: Pasaje N°13 | R15: 75 | S15: Red distribuidora | T15: =IF(A15="","",IF(AND(L15="Para Programar",G15=0),"INCONSISTENCIA - REVISAR MANUALMENTE: Para Programar sin saldo",IF(AND(L15="Terminada",G15>0),"INCONSISTENCIA - REVISAR MANUALMENTE: Terminada con saldo",""))) | U15: =IF(AND(L15="Para Programar",G15>0),COUNTIFS($L$5:L15,"Para Programar",$G$5:G15,">0"),"") | W15: =IF(OR(B15="",C15=""),"",B15&"|"&C15) -> N1 - N2|08 Prueba hidráulica - Interna N° 1 | X15: 0
A16: AG-19 | B16: N1 - N2 | C16: 08 Prueba hidráulica - Interna N° 2 | D16: tramo | E16: 1 | F16: =IF(E16="","",MIN(E16,$X16+SUMIFS('05_Parte_Diario'!$H$5:$H$204,'05_Parte_Diario'!$D$5:$D$204,B16,'05_Parte_Diario'!$E$5:$E$204,C16))) -> 0 | G16: =IF(E16="","",MAX(E16-F16,0)) -> 1 | H16: =IFERROR(F16/E16,0) -> 0 | I16: =IF(OR(B16="",C16="",$V$1=""),"",MIN(E16,SUMIFS('03_Planificacion'!$G$99:$G$178,'03_Planificacion'!$E$99:$E$178,B16,'03_Planificacion'!$F$99:$F$178,C16,'03_Planificacion'!$D$99:$D$178,"<="&$V$1))) -> 0 | J16: =IFERROR(I16/E16,0) -> 0 | K16: =IF(OR(E16="",$V$1=""),"",H16-J16) -> 0 | L16: No iniciada | P16: =IF(A16="","",$V$1) -> 46287 | Q16: Pasaje N°13 | R16: 75 | S16: Red distribuidora | T16: =IF(A16="","",IF(AND(L16="Para Programar",G16=0),"INCONSISTENCIA - REVISAR MANUALMENTE: Para Programar sin saldo",IF(AND(L16="Terminada",G16>0),"INCONSISTENCIA - REVISAR MANUALMENTE: Terminada con saldo",""))) | U16: =IF(AND(L16="Para Programar",G16>0),COUNTIFS($L$5:L16,"Para Programar",$G$5:G16,">0"),"") | W16: =IF(OR(B16="",C16=""),"",B16&"|"&C16) -> N1 - N2|08 Prueba hidráulica - Interna N° 2 | X16: 0
... A76: HI-06 | B76: N9 - N11 | C76: 11 Relleno -0,30 - Inspección laboratorio | D76: tramo | E76: 1 | F76: =IF(E76="","",MIN(E76,$X76+SUMIFS('05_Parte_Diario'!$H$5:$H$204,'05_Parte_Diario'!$D$5:$D$204,B76,'05_Parte_Diario'!$E$5:$E$204,C76))) -> 0 | G76: =IF(E76="","",MAX(E76-F76,0)) -> 1 | H76: =IFERROR(F76/E76,0) -> 0 | I76: =IF(OR(B76="",C76="",$V$1=""),"",MIN(E76,SUMIFS('03_Planificacion'!$G$99:$G$178,'03_Planificacion'!$E$99:$E$178,B76,'03_Planificacion'!$F$99:$F$178,C76,'03_Planificacion'!$D$99:$D$178,"<="&$V$1))) -> 0 | J76: =IFERROR(I76/E76,0) -> 0 | K76: =IF(OR(E76="",$V$1=""),"",H76-J76) -> 0 | L76: No iniciada | P76: =IF(A76="","",$V$1) -> 46287 | Q76: Pasaje N°9 | R76: 75 | S76: Red distribuidora | T76: =IF(A76="","",IF(AND(L76="Para Programar",G76=0),"INCONSISTENCIA - REVISAR MANUALMENTE: Para Programar sin saldo",IF(AND(L76="Terminada",G76>0),"INCONSISTENCIA - REVISAR MANUALMENTE: Terminada con saldo",""))) | U76: =IF(AND(L76="Para Programar",G76>0),COUNTIFS($L$5:L76,"Para Programar",$G$5:G76,">0"),"") | W76: =IF(OR(B76="",C76=""),"",B76&"|"&C76) -> N9 - N11|11 Relleno -0,30 - Inspección laboratorio | X76: 0
A77: AG-01 | B77: N10 - N15 | C77: 01 Replanteo - Marcación de tramo de cañería principal | D77: m | E77: 81 | F77: =IF(E77="","",MIN(E77,$X77+SUMIFS('05_Parte_Diario'!$H$5:$H$204,'05_Parte_Diario'!$D$5:$D$204,B77,'05_Parte_Diario'!$E$5:$E$204,C77))) -> 81 | G77: =IF(E77="","",MAX(E77-F77,0)) -> 0 | H77: =IFERROR(F77/E77,0) -> 1 | I77: =IF(OR(B77="",C77="",$V$1=""),"",MIN(E77,SUMIFS('03_Planificacion'!$G$99:$G$178,'03_Planificacion'!$E$99:$E$178,B77,'03_Planificacion'!$F$99:$F$178,C77,'03_Planificacion'!$D$99:$D$178,"<="&$V$1))) -> 0 | J77: =IFERROR(I77/E77,0) -> 0 | K77: =IF(OR(E77="",$V$1=""),"",H77-J77) -> 1 | L77: Terminada | N77: Media | P77: =IF(A77="","",$V$1) -> 46287 | Q77: Pasaje N°2 | R77: 110 | S77: Red distribuidora | T77: =IF(A77="","",IF(AND(L77="Para Programar",G77=0),"INCONSISTENCIA - REVISAR MANUALMENTE: Para Programar sin saldo",IF(AND(L77="Terminada",G77>0),"INCONSISTENCIA - REVISAR MANUALMENTE: Terminada con saldo",""))) | U77: =IF(AND(L77="Para Programar",G77>0),COUNTIFS($L$5:L77,"Para Programar",$G$5:G77,">0"),"") | W77: =IF(OR(B77="",C77=""),"",B77&"|"&C77) -> N10 - N15|01 Replanteo - Marcación de tramo de cañería principal | X77: 81
A78: AG-03 | B78: N10 - N15 | C78: 02 Excavación - Zanja principal | D78: m | E78: 81 | F78: =IF(E78="","",MIN(E78,$X78+SUMIFS('05_Parte_Diario'!$H$5:$H$204,'05_Parte_Diario'!$D$5:$D$204,B78,'05_Parte_Diario'!$E$5:$E$204,C78))) -> 25 | G78: =IF(E78="","",MAX(E78-F78,0)) -> 56 | H78: =IFERROR(F78/E78,0) -> 0.30864198 | I78: =IF(OR(B78="",C78="",$V$1=""),"",MIN(E78,SUMIFS('03_Planificacion'!$G$99:$G$178,'03_Planificacion'!$E$99:$E$178,B78,'03_Planificacion'!$F$99:$F$178,C78,'03_Planificacion'!$D$99:$D$178,"<="&$V$1))) -> 0 | J78: =IFERROR(I78/E78,0) -> 0 | K78: =IF(OR(E78="",$V$1=""),"",H78-J78) -> 0.30864198 | L78: Terminada | P78: =IF(A78="","",$V$1) -> 46287 | Q78: Pasaje N°2 | R78: 110 | S78: Red distribuidora | T78: =IF(A78="","",IF(AND(L78="Para Programar",G78=0),"INCONSISTENCIA - REVISAR MANUALMENTE: Para Programar sin saldo",IF(AND(L78="Terminada",G78>0),"INCONSISTENCIA - REVISAR MANUALMENTE: Terminada con saldo",""))) -> INCONSISTENCIA - REVISAR MANUALMENTE: Terminada con saldo | U78: =IF(AND(L78="Para Programar",G78>0),COUNTIFS($L$5:L78,"Para Programar",$G$5:G78,">0"),"") | W78: =IF(OR(B78="",C78=""),"",B78&"|"&C78) -> N10 - N15|02 Excavación - Zanja principal | X78: 25
A79: AG-05 | B79: N10 - N15 | C79: 03 Base de asiento - Nivelación de fondo de zanja | D79: m | E79: 81 | F79: =IF(E79="","",MIN(E79,$X79+SUMIFS('05_Parte_Diario'!$H$5:$H$204,'05_Parte_Diario'!$D$5:$D$204,B79,'05_Parte_Diario'!$E$5:$E$204,C79))) -> 0 | G79: =IF(E79="","",MAX(E79-F79,0)) -> 81 | H79: =IFERROR(F79/E79,0) -> 0 | I79: =IF(OR(B79="",C79="",$V$1=""),"",MIN(E79,SUMIFS('03_Planificacion'!$G$99:$G$178,'03_Planificacion'!$E$99:$E$178,B79,'03_Planificacion'!$F$99:$F$178,C79,'03_Planificacion'!$D$99:$D$178,"<="&$V$1))) -> 0 | J79: =IFERROR(I79/E79,0) -> 0 | K79: =IF(OR(E79="",$V$1=""),"",H79-J79) -> 0 | L79: Para Programar | P79: =IF(A79="","",$V$1) -> 46287 | Q79: Pasaje N°2 | R79: 110 | S79: Red distribuidora | T79: =IF(A79="","",IF(AND(L79="Para Programar",G79=0),"INCONSISTENCIA - REVISAR MANUALMENTE: Para Programar sin saldo",IF(AND(L79="Terminada",G79>0),"INCONSISTENCIA - REVISAR MANUALMENTE: Terminada con saldo",""))) | U79: =IF(AND(L79="Para Programar",G79>0),COUNTIFS($L$5:L79,"Para Programar",$G$5:G79,">0"),"") -> 1 | W79: =IF(OR(B79="",C79=""),"",B79&"|"&C79) -> N10 - N15|03 Base de asiento - Nivelación de fondo de zanja | X79: 0
A80: AG-06 | B80: N10 - N15 | C80: 03 Base de asiento - Aporte de material base e=0,10 m | D80: m | E80: 81 | F80: =IF(E80="","",MIN(E80,$X80+SUMIFS('05_Parte_Diario'!$H$5:$H$204,'05_Parte_Diario'!$D$5:$D$204,B80,'05_Parte_Diario'!$E$5:$E$204,C80))) -> 0 | G80: =IF(E80="","",MAX(E80-F80,0)) -> 81 | H80: =IFERROR(F80/E80,0) -> 0 | I80: =IF(OR(B80="",C80="",$V$1=""),"",MIN(E80,SUMIFS('03_Planificacion'!$G$99:$G$178,'03_Planificacion'!$E$99:$E$178,B80,'03_Planificacion'!$F$99:$F$178,C80,'03_Planificacion'!$D$99:$D$178,"<="&$V$1))) -> 0 | J80: =IFERROR(I80/E80,0) -> 0 | K80: =IF(OR(E80="",$V$1=""),"",H80-J80) -> 0 | L80: Para Programar | P80: =IF(A80="","",$V$1) -> 46287 | Q80: Pasaje N°2 | R80: 110 | S80: Red distribuidora | T80: =IF(A80="","",IF(AND(L80="Para Programar",G80=0),"INCONSISTENCIA - REVISAR MANUALMENTE: Para Programar sin saldo",IF(AND(L80="Terminada",G80>0),"INCONSISTENCIA - REVISAR MANUALMENTE: Terminada con saldo",""))) | U80: =IF(AND(L80="Para Programar",G80>0),COUNTIFS($L$5:L80,"Para Programar",$G$5:G80,">0"),"") -> 2 | W80: =IF(OR(B80="",C80=""),"",B80&"|"&C80) -> N10 - N15|03 Base de asiento - Aporte de material base e=0,10 m | X80: 0
A81: AG-07 | B81: N10 - N15 | C81: 03 Base de asiento - Compactación | D81: m | E81: 81 | F81: =IF(E81="","",MIN(E81,$X81+SUMIFS('05_Parte_Diario'!$H$5:$H$204,'05_Parte_Diario'!$D$5:$D$204,B81,'05_Parte_Diario'!$E$5:$E$204,C81))) -> 0 | G81: =IF(E81="","",MAX(E81-F81,0)) -> 81 | H81: =IFERROR(F81/E81,0) -> 0 | I81: =IF(OR(B81="",C81="",$V$1=""),"",MIN(E81,SUMIFS('03_Planificacion'!$G$99:$G$178,'03_Planificacion'!$E$99:$E$178,B81,'03_Planificacion'!$F$99:$F$178,C81,'03_Planificacion'!$D$99:$D$178,"<="&$V$1))) -> 0 | J81: =IFERROR(I81/E81,0) -> 0 | K81: =IF(OR(E81="",$V$1=""),"",H81-J81) -> 0 | L81: Para Programar | N81: Alta | P81: =IF(A81="","",$V$1) -> 46287 | Q81: Pasaje N°2 | R81: 110 | S81: Red distribuidora | T81: =IF(A81="","",IF(AND(L81="Para Programar",G81=0),"INCONSISTENCIA - REVISAR MANUALMENTE: Para Programar sin saldo",IF(AND(L81="Terminada",G81>0),"INCONSISTENCIA - REVISAR MANUALMENTE: Terminada con saldo",""))) | U81: =IF(AND(L81="Para Programar",G81>0),COUNTIFS($L$5:L81,"Para Programar",$G$5:G81,">0"),"") -> 3 | W81: =IF(OR(B81="",C81=""),"",B81&"|"&C81) -> N10 - N15|03 Base de asiento - Compactación | X81: 0
A82: HI-01 | B82: N10 - N15 | C82: 04 Inspecciones previas - Laboratorio base de asiento | D82: tramo | E82: 1 | F82: =IF(E82="","",MIN(E82,$X82+SUMIFS('05_Parte_Diario'!$H$5:$H$204,'05_Parte_Diario'!$D$5:$D$204,B82,'05_Parte_Diario'!$E$5:$E$204,C82))) -> 0 | G82: =IF(E82="","",MAX(E82-F82,0)) -> 1 | H82: =IFERROR(F82/E82,0) -> 0 | I82: =IF(OR(B82="",C82="",$V$1=""),"",MIN(E82,SUMIFS('03_Planificacion'!$G$99:$G$178,'03_Planificacion'!$E$99:$E$178,B82,'03_Planificacion'!$F$99:$F$178,C82,'03_Planificacion'!$D$99:$D$178,"<="&$V$1))) -> 0 | J82: =IFERROR(I82/E82,0) -> 0 | K82: =IF(OR(E82="",$V$1=""),"",H82-J82) -> 0 | L82: No iniciada | P82: =IF(A82="","",$V$1) -> 46287 | Q82: Pasaje N°2 | R82: 110 | S82: Red distribuidora | T82: =IF(A82="","",IF(AND(L82="Para Programar",G82=0),"INCONSISTENCIA - REVISAR MANUALMENTE: Para Programar sin saldo",IF(AND(L82="Terminada",G82>0),"INCONSISTENCIA - REVISAR MANUALMENTE: Terminada con saldo",""))) | U82: =IF(AND(L82="Para Programar",G82>0),COUNTIFS($L$5:L82,"Para Programar",$G$5:G82,">0"),"") | W82: =IF(OR(B82="",C82=""),"",B82&"|"&C82) -> N10 - N15|04 Inspecciones previas - Laboratorio base de asiento | X82: 0
A83: HI-02 | B83: N10 - N15 | C83: 04 Inspecciones previas - Zanja y materiales | D83: tramo | E83: 1 | F83: =IF(E83="","",MIN(E83,$X83+SUMIFS('05_Parte_Diario'!$H$5:$H$204,'05_Parte_Diario'!$D$5:$D$204,B83,'05_Parte_Diario'!$E$5:$E$204,C83))) -> 0 | G83: =IF(E83="","",MAX(E83-F83,0)) -> 1 | H83: =IFERROR(F83/E83,0) -> 0 | I83: =IF(OR(B83="",C83="",$V$1=""),"",MIN(E83,SUMIFS('03_Planificacion'!$G$99:$G$178,'03_Planificacion'!$E$99:$E$178,B83,'03_Planificacion'!$F$99:$F$178,C83,'03_Planificacion'!$D$99:$D$178,"<="&$V$1))) -> 0 | J83: =IFERROR(I83/E83,0) -> 0 | K83: =IF(OR(E83="",$V$1=""),"",H83-J83) -> 0 | L83: No iniciada | P83: =IF(A83="","",$V$1) -> 46287 | Q83: Pasaje N°2 | R83: 110 | S83: Red distribuidora | T83: =IF(A83="","",IF(AND(L83="Para Programar",G83=0),"INCONSISTENCIA - REVISAR MANUALMENTE: Para Programar sin saldo",IF(AND(L83="Terminada",G83>0),"INCONSISTENCIA - REVISAR MANUALMENTE: Terminada con saldo",""))) | U83: =IF(AND(L83="Para Programar",G83>0),COUNTIFS($L$5:L83,"Para Programar",$G$5:G83,">0"),"") | W83: =IF(OR(B83="",C83=""),"",B83&"|"&C83) -> N10 - N15|04 Inspecciones previas - Zanja y materiales | X83: 0
A84: AG-08 | B84: N10 - N15 | C84: 05 Tendido de cañería - Cañería principal | D84: m | E84: 81 | F84: =IF(E84="","",MIN(E84,$X84+SUMIFS('05_Parte_Diario'!$H$5:$H$204,'05_Parte_Diario'!$D$5:$D$204,B84,'05_Parte_Diario'!$E$5:$E$204,C84))) -> 0 | G84: =IF(E84="","",MAX(E84-F84,0)) -> 81 | H84: =IFERROR(F84/E84,0) -> 0 | I84: =IF(OR(B84="",C84="",$V$1=""),"",MIN(E84,SUMIFS('03_Planificacion'!$G$99:$G$178,'03_Planificacion'!$E$99:$E$178,B84,'03_Planificacion'!$F$99:$F$178,C84,'03_Planificacion'!$D$99:$D$178,"<="&$V$1))) -> 0 | J84: =IFERROR(I84/E84,0) -> 0 | K84: =IF(OR(E84="",$V$1=""),"",H84-J84) -> 0 | L84: No iniciada | P84: =IF(A84="","",$V$1) -> 46287 | Q84: Pasaje N°2 | R84: 110 | S84: Red distribuidora | T84: =IF(A84="","",IF(AND(L84="Para Programar",G84=0),"INCONSISTENCIA - REVISAR MANUALMENTE: Para Programar sin saldo",IF(AND(L84="Terminada",G84>0),"INCONSISTENCIA - REVISAR MANUALMENTE: Terminada con saldo",""))) | U84: =IF(AND(L84="Para Programar",G84>0),COUNTIFS($L$5:L84,"Para Programar",$G$5:G84,">0"),"") | W84: =IF(OR(B84="",C84=""),"",B84&"|"&C84) -> N10 - N15|05 Tendido de cañería - Cañería principal | X84: 0
A85: AG-09 | B85: N10 - N15 | C85: 05 Tendido de cañería - Relevamiento planialtimétrico | D85: m | E85: 81 | F85: =IF(E85="","",MIN(E85,$X85+SUMIFS('05_Parte_Diario'!$H$5:$H$204,'05_Parte_Diario'!$D$5:$D$204,B85,'05_Parte_Diario'!$E$5:$E$204,C85))) -> 0 | G85: =IF(E85="","",MAX(E85-F85,0)) -> 81 | H85: =IFERROR(F85/E85,0) -> 0 | I85: =IF(OR(B85="",C85="",$V$1=""),"",MIN(E85,SUMIFS('03_Planificacion'!$G$99:$G$178,'03_Planificacion'!$E$99:$E$178,B85,'03_Planificacion'!$F$99:$F$178,C85,'03_Planificacion'!$D$99:$D$178,"<="&$V$1))) -> 0 | J85: =IFERROR(I85/E85,0) -> 0 | K85: =IF(OR(E85="",$V$1=""),"",H85-J85) -> 0 | L85: No iniciada | P85: =IF(A85="","",$V$1) -> 46287 | Q85: Pasaje N°2 | R85: 110 | S85: Red distribuidora | T85: =IF(A85="","",IF(AND(L85="Para Programar",G85=0),"INCONSISTENCIA - REVISAR MANUALMENTE: Para Programar sin saldo",IF(AND(L85="Terminada",G85>0),"INCONSISTENCIA - REVISAR MANUALMENTE: Terminada con saldo",""))) | U85: =IF(AND(L85="Para Programar",G85>0),COUNTIFS($L$5:L85,"Para Programar",$G$5:G85,">0"),"") | W85: =IF(OR(B85="",C85=""),"",B85&"|"&C85) -> N10 - N15|05 Tendido de cañería - Relevamiento planialtimétrico | X85: 0
A86: AG-17 | B86: N10 - N15 | C86: 08 Prueba hidráulica - Preparación del sistema | D86: tramo | E86: 1 | F86: =IF(E86="","",MIN(E86,$X86+SUMIFS('05_Parte_Diario'!$H$5:$H$204,'05_Parte_Diario'!$D$5:$D$204,B86,'05_Parte_Diario'!$E$5:$E$204,C86))) -> 0 | G86: =IF(E86="","",MAX(E86-F86,0)) -> 1 | H86: =IFERROR(F86/E86,0) -> 0 | I86: =IF(OR(B86="",C86="",$V$1=""),"",MIN(E86,SUMIFS('03_Planificacion'!$G$99:$G$178,'03_Planificacion'!$E$99:$E$178,B86,'03_Planificacion'!$F$99:$F$178,C86,'03_Planificacion'!$D$99:$D$178,"<="&$V$1))) -> 0 | J86: =IFERROR(I86/E86,0) -> 0 | K86: =IF(OR(E86="",$V$1=""),"",H86-J86) -> 0 | L86: No iniciada | P86: =IF(A86="","",$V$1) -> 46287 | Q86: Pasaje N°2 | R86: 110 | S86: Red distribuidora | T86: =IF(A86="","",IF(AND(L86="Para Programar",G86=0),"INCONSISTENCIA - REVISAR MANUALMENTE: Para Programar sin saldo",IF(AND(L86="Terminada",G86>0),"INCONSISTENCIA - REVISAR MANUALMENTE: Terminada con saldo",""))) | U86: =IF(AND(L86="Para Programar",G86>0),COUNTIFS($L$5:L86,"Para Programar",$G$5:G86,">0"),"") | W86: =IF(OR(B86="",C86=""),"",B86&"|"&C86) -> N10 - N15|08 Prueba hidráulica - Preparación del sistema | X86: 0
A87: AG-18 | B87: N10 - N15 | C87: 08 Prueba hidráulica - Interna N° 1 | D87: tramo | E87: 1 | F87: =IF(E87="","",MIN(E87,$X87+SUMIFS('05_Parte_Diario'!$H$5:$H$204,'05_Parte_Diario'!$D$5:$D$204,B87,'05_Parte_Diario'!$E$5:$E$204,C87))) -> 0 | G87: =IF(E87="","",MAX(E87-F87,0)) -> 1 | H87: =IFERROR(F87/E87,0) -> 0 | I87: =IF(OR(B87="",C87="",$V$1=""),"",MIN(E87,SUMIFS('03_Planificacion'!$G$99:$G$178,'03_Planificacion'!$E$99:$E$178,B87,'03_Planificacion'!$F$99:$F$178,C87,'03_Planificacion'!$D$99:$D$178,"<="&$V$1))) -> 0 | J87: =IFERROR(I87/E87,0) -> 0 | K87: =IF(OR(E87="",$V$1=""),"",H87-J87) -> 0 | L87: No iniciada | P87: =IF(A87="","",$V$1) -> 46287 | Q87: Pasaje N°2 | R87: 110 | S87: Red distribuidora | T87: =IF(A87="","",IF(AND(L87="Para Programar",G87=0),"INCONSISTENCIA - REVISAR MANUALMENTE: Para Programar sin saldo",IF(AND(L87="Terminada",G87>0),"INCONSISTENCIA - REVISAR MANUALMENTE: Terminada con saldo",""))) | U87: =IF(AND(L87="Para Programar",G87>0),COUNTIFS($L$5:L87,"Para Programar",$G$5:G87,">0"),"") | W87: =IF(OR(B87="",C87=""),"",B87&"|"&C87) -> N10 - N15|08 Prueba hidráulica - Interna N° 1 | X87: 0
A88: AG-19 | B88: N10 - N15 | C88: 08 Prueba hidráulica - Interna N° 2 | D88: tramo | E88: 1 | F88: =IF(E88="","",MIN(E88,$X88+SUMIFS('05_Parte_Diario'!$H$5:$H$204,'05_Parte_Diario'!$D$5:$D$204,B88,'05_Parte_Diario'!$E$5:$E$204,C88))) -> 0 | G88: =IF(E88="","",MAX(E88-F88,0)) -> 1 | H88: =IFERROR(F88/E88,0) -> 0 | I88: =IF(OR(B88="",C88="",$V$1=""),"",MIN(E88,SUMIFS('03_Planificacion'!$G$99:$G$178,'03_Planificacion'!$E$99:$E$178,B88,'03_Planificacion'!$F$99:$F$178,C88,'03_Planificacion'!$D$99:$D$178,"<="&$V$1))) -> 0 | J88: =IFERROR(I88/E88,0) -> 0 | K88: =IF(OR(E88="",$V$1=""),"",H88-J88) -> 0 | L88: No iniciada | P88: =IF(A88="","",$V$1) -> 46287 | Q88: Pasaje N°2 | R88: 110 | S88: Red distribuidora | T88: =IF(A88="","",IF(AND(L88="Para Programar",G88=0),"INCONSISTENCIA - REVISAR MANUALMENTE: Para Programar sin saldo",IF(AND(L88="Terminada",G88>0),"INCONSISTENCIA - REVISAR MANUALMENTE: Terminada con saldo",""))) | U88: =IF(AND(L88="Para Programar",G88>0),COUNTIFS($L$5:L88,"Para Programar",$G$5:G88,">0"),"") | W88: =IF(OR(B88="",C88=""),"",B88&"|"&C88) -> N10 - N15|08 Prueba hidráulica - Interna N° 2 | X88: 0
A89: HI-03 | B89: N10 - N15 | C89: 08 Prueba hidráulica - Primera prueba oficial | D89: tramo | E89: 1 | F89: =IF(E89="","",MIN(E89,$X89+SUMIFS('05_Parte_Diario'!$H$5:$H$204,'05_Parte_Diario'!$D$5:$D$204,B89,'05_Parte_Diario'!$E$5:$E$204,C89))) -> 0 | G89: =IF(E89="","",MAX(E89-F89,0)) -> 1 | H89: =IFERROR(F89/E89,0) -> 0 | I89: =IF(OR(B89="",C89="",$V$1=""),"",MIN(E89,SUMIFS('03_Planificacion'!$G$99:$G$178,'03_Planificacion'!$E$99:$E$178,B89,'03_Planificacion'!$F$99:$F$178,C89,'03_Planificacion'!$D$99:$D$178,"<="&$V$1))) -> 0 | J89: =IFERROR(I89/E89,0) -> 0 | K89: =IF(OR(E89="",$V$1=""),"",H89-J89) -> 0 | L89: No iniciada | P89: =IF(A89="","",$V$1) -> 46287 | Q89: Pasaje N°2 | R89: 110 | S89: Red distribuidora | T89: =IF(A89="","",IF(AND(L89="Para Programar",G89=0),"INCONSISTENCIA - REVISAR MANUALMENTE: Para Programar sin saldo",IF(AND(L89="Terminada",G89>0),"INCONSISTENCIA - REVISAR MANUALMENTE: Terminada con saldo",""))) | U89: =IF(AND(L89="Para Programar",G89>0),COUNTIFS($L$5:L89,"Para Programar",$G$5:G89,">0"),"") | W89: =IF(OR(B89="",C89=""),"",B89&"|"&C89) -> N10 - N15|08 Prueba hidráulica - Primera prueba oficial | X89: 0
A90: AG-20 | B90: N10 - N15 | C90: 09 Paquete estructural - Aporte e=0,30 m | D90: m | E90: 81 | F90: =IF(E90="","",MIN(E90,$X90+SUMIFS('05_Parte_Diario'!$H$5:$H$204,'05_Parte_Diario'!$D$5:$D$204,B90,'05_Parte_Diario'!$E$5:$E$204,C90))) -> 0 | G90: =IF(E90="","",MAX(E90-F90,0)) -> 81 | H90: =IFERROR(F90/E90,0) -> 0 | I90: =IF(OR(B90="",C90="",$V$1=""),"",MIN(E90,SUMIFS('03_Planificacion'!$G$99:$G$178,'03_Planificacion'!$E$99:$E$178,B90,'03_Planificacion'!$F$99:$F$178,C90,'03_Planificacion'!$D$99:$D$178,"<="&$V$1))) -> 0 | J90: =IFERROR(I90/E90,0) -> 0 | K90: =IF(OR(E90="",$V$1=""),"",H90-J90) -> 0 | L90: No iniciada | P90: =IF(A90="","",$V$1) -> 46287 | Q90: Pasaje N°2 | R90: 110 | S90: Red distribuidora | T90: =IF(A90="","",IF(AND(L90="Para Programar",G90=0),"INCONSISTENCIA - REVISAR MANUALMENTE: Para Programar sin saldo",IF(AND(L90="Terminada",G90>0),"INCONSISTENCIA - REVISAR MANUALMENTE: Terminada con saldo",""))) | U90: =IF(AND(L90="Para Programar",G90>0),COUNTIFS($L$5:L90,"Para Programar",$G$5:G90,">0"),"") | W90: =IF(OR(B90="",C90=""),"",B90&"|"&C90) -> N10 - N15|09 Paquete estructural - Aporte e=0,30 m | X90: 0
A91: AG-21 | B91: N10 - N15 | C91: 09 Paquete estructural - Compactación | D91: m | E91: 81 | F91: =IF(E91="","",MIN(E91,$X91+SUMIFS('05_Parte_Diario'!$H$5:$H$204,'05_Parte_Diario'!$D$5:$D$204,B91,'05_Parte_Diario'!$E$5:$E$204,C91))) -> 0 | G91: =IF(E91="","",MAX(E91-F91,0)) -> 81 | H91: =IFERROR(F91/E91,0) -> 0 | I91: =IF(OR(B91="",C91="",$V$1=""),"",MIN(E91,SUMIFS('03_Planificacion'!$G$99:$G$178,'03_Planificacion'!$E$99:$E$178,B91,'03_Planificacion'!$F$99:$F$178,C91,'03_Planificacion'!$D$99:$D$178,"<="&$V$1))) -> 0 | J91: =IFERROR(I91/E91,0) -> 0 | K91: =IF(OR(E91="",$V$1=""),"",H91-J91) -> 0 | L91: No iniciada | P91: =IF(A91="","",$V$1) -> 46287 | Q91: Pasaje N°2 | R91: 110 | S91: Red distribuidora | T91: =IF(A91="","",IF(AND(L91="Para Programar",G91=0),"INCONSISTENCIA - REVISAR MANUALMENTE: Para Programar sin saldo",IF(AND(L91="Terminada",G91>0),"INCONSISTENCIA - REVISAR MANUALMENTE: Terminada con saldo",""))) | U91: =IF(AND(L91="Para Programar",G91>0),COUNTIFS($L$5:L91,"Para Programar",$G$5:G91,">0"),"") | W91: =IF(OR(B91="",C91=""),"",B91&"|"&C91) -> N10 - N15|09 Paquete estructural - Compactación | X91: 0
A92: HI-04 | B92: N10 - N15 | C92: 09 Paquete estructural - Inspección laboratorio | D92: tramo | E92: 1 | F92: =IF(E92="","",MIN(E92,$X92+SUMIFS('05_Parte_Diario'!$H$5:$H$204,'05_Parte_Diario'!$D$5:$D$204,B92,'05_Parte_Diario'!$E$5:$E$204,C92))) -> 0 | G92: =IF(E92="","",MAX(E92-F92,0)) -> 1 | H92: =IFERROR(F92/E92,0) -> 0 | I92: =IF(OR(B92="",C92="",$V$1=""),"",MIN(E92,SUMIFS('03_Planificacion'!$G$99:$G$178,'03_Planificacion'!$E$99:$E$178,B92,'03_Planificacion'!$F$99:$F$178,C92,'03_Planificacion'!$D$99:$D$178,"<="&$V$1))) -> 0 | J92: =IFERROR(I92/E92,0) -> 0 | K92: =IF(OR(E92="",$V$1=""),"",H92-J92) -> 0 | L92: No iniciada | P92: =IF(A92="","",$V$1) -> 46287 | Q92: Pasaje N°2 | R92: 110 | S92: Red distribuidora | T92: =IF(A92="","",IF(AND(L92="Para Programar",G92=0),"INCONSISTENCIA - REVISAR MANUALMENTE: Para Programar sin saldo",IF(AND(L92="Terminada",G92>0),"INCONSISTENCIA - REVISAR MANUALMENTE: Terminada con saldo",""))) | U92: =IF(AND(L92="Para Programar",G92>0),COUNTIFS($L$5:L92,"Para Programar",$G$5:G92,">0"),"") | W92: =IF(OR(B92="",C92=""),"",B92&"|"&C92) -> N10 - N15|09 Paquete estructural - Inspección laboratorio | X92: 0
A93: AG-22 | B93: N10 - N15 | C93: 10 Relleno -0,60 - Conformación de capa | D93: m | E93: 81 | F93: =IF(E93="","",MIN(E93,$X93+SUMIFS('05_Parte_Diario'!$H$5:$H$204,'05_Parte_Diario'!$D$5:$D$204,B93,'05_Parte_Diario'!$E$5:$E$204,C93))) -> 0 | G93: =IF(E93="","",MAX(E93-F93,0)) -> 81 | H93: =IFERROR(F93/E93,0) -> 0 | I93: =IF(OR(B93="",C93="",$V$1=""),"",MIN(E93,SUMIFS('03_Planificacion'!$G$99:$G$178,'03_Planificacion'!$E$99:$E$178,B93,'03_Planificacion'!$F$99:$F$178,C93,'03_Planificacion'!$D$99:$D$178,"<="&$V$1))) -> 0 | J93: =IFERROR(I93/E93,0) -> 0 | K93: =IF(OR(E93="",$V$1=""),"",H93-J93) -> 0 | L93: No iniciada | P93: =IF(A93="","",$V$1) -> 46287 | Q93: Pasaje N°2 | R93: 110 | S93: Red distribuidora | T93: =IF(A93="","",IF(AND(L93="Para Programar",G93=0),"INCONSISTENCIA - REVISAR MANUALMENTE: Para Programar sin saldo",IF(AND(L93="Terminada",G93>0),"INCONSISTENCIA - REVISAR MANUALMENTE: Terminada con saldo",""))) | U93: =IF(AND(L93="Para Programar",G93>0),COUNTIFS($L$5:L93,"Para Programar",$G$5:G93,">0"),"") | W93: =IF(OR(B93="",C93=""),"",B93&"|"&C93) -> N10 - N15|10 Relleno -0,60 - Conformación de capa | X93: 0
... A152: AG-06 | B152: N12 - N13 | C152: 03 Base de asiento - Aporte de material base e=0,10 m | D152: m | E152: 200 | F152: =IF(E152="","",MIN(E152,$X152+SUMIFS('05_Parte_Diario'!$H$5:$H$204,'05_Parte_Diario'!$D$5:$D$204,B152,'05_Parte_Diario'!$E$5:$E$204,C152))) -> 200 | G152: =IF(E152="","",MAX(E152-F152,0)) -> 0 | H152: =IFERROR(F152/E152,0) -> 1 | I152: =IF(OR(B152="",C152="",$V$1=""),"",MIN(E152,SUMIFS('03_Planificacion'!$G$99:$G$178,'03_Planificacion'!$E$99:$E$178,B152,'03_Planificacion'!$F$99:$F$178,C152,'03_Planificacion'!$D$99:$D$178,"<="&$V$1))) -> 0 | J152: =IFERROR(I152/E152,0) -> 0 | K152: =IF(OR(E152="",$V$1=""),"",H152-J152) -> 1 | L152: Terminada | P152: =IF(A152="","",$V$1) -> 46287 | Q152: Pasaje N°9 | R152: 75 | S152: Red distribuidora | T152: =IF(A152="","",IF(AND(L152="Para Programar",G152=0),"INCONSISTENCIA - REVISAR MANUALMENTE: Para Programar sin saldo",IF(AND(L152="Terminada",G152>0),"INCONSISTENCIA - REVISAR MANUALMENTE: Terminada con saldo",""))) | U152: =IF(AND(L152="Para Programar",G152>0),COUNTIFS($L$5:L152,"Para Programar",$G$5:G152,">0"),"") | W152: =IF(OR(B152="",C152=""),"",B152&"|"&C152) -> N12 - N13|03 Base de asiento - Aporte de material base e=0,10 m | X152: 200
A153: AG-07 | B153: N12 - N13 | C153: 03 Base de asiento - Compactación | D153: m | E153: 200 | F153: =IF(E153="","",MIN(E153,$X153+SUMIFS('05_Parte_Diario'!$H$5:$H$204,'05_Parte_Diario'!$D$5:$D$204,B153,'05_Parte_Diario'!$E$5:$E$204,C153))) -> 0 | G153: =IF(E153="","",MAX(E153-F153,0)) -> 200 | H153: =IFERROR(F153/E153,0) -> 0 | I153: =IF(OR(B153="",C153="",$V$1=""),"",MIN(E153,SUMIFS('03_Planificacion'!$G$99:$G$178,'03_Planificacion'!$E$99:$E$178,B153,'03_Planificacion'!$F$99:$F$178,C153,'03_Planificacion'!$D$99:$D$178,"<="&$V$1))) -> 0 | J153: =IFERROR(I153/E153,0) -> 0 | K153: =IF(OR(E153="",$V$1=""),"",H153-J153) -> 0 | L153: Terminada | N153: Alta | P153: =IF(A153="","",$V$1) -> 46287 | Q153: Pasaje N°9 | R153: 75 | S153: Red distribuidora | T153: =IF(A153="","",IF(AND(L153="Para Programar",G153=0),"INCONSISTENCIA - REVISAR MANUALMENTE: Para Programar sin saldo",IF(AND(L153="Terminada",G153>0),"INCONSISTENCIA - REVISAR MANUALMENTE: Terminada con saldo",""))) -> INCONSISTENCIA - REVISAR MANUALMENTE: Terminada con saldo | U153: =IF(AND(L153="Para Programar",G153>0),COUNTIFS($L$5:L153,"Para Programar",$G$5:G153,">0"),"") | W153: =IF(OR(B153="",C153=""),"",B153&"|"&C153) -> N12 - N13|03 Base de asiento - Compactación | X153: 0
A154: HI-01 | B154: N12 - N13 | C154: 04 Inspecciones previas - Laboratorio base de asiento | D154: tramo | E154: 1 | F154: =IF(E154="","",MIN(E154,$X154+SUMIFS('05_Parte_Diario'!$H$5:$H$204,'05_Parte_Diario'!$D$5:$D$204,B154,'05_Parte_Diario'!$E$5:$E$204,C154))) -> 0 | G154: =IF(E154="","",MAX(E154-F154,0)) -> 1 | H154: =IFERROR(F154/E154,0) -> 0 | I154: =IF(OR(B154="",C154="",$V$1=""),"",MIN(E154,SUMIFS('03_Planificacion'!$G$99:$G$178,'03_Planificacion'!$E$99:$E$178,B154,'03_Planificacion'!$F$99:$F$178,C154,'03_Planificacion'!$D$99:$D$178,"<="&$V$1))) -> 0 | J154: =IFERROR(I154/E154,0) -> 0 | K154: =IF(OR(E154="",$V$1=""),"",H154-J154) -> 0 | L154: Terminada | P154: =IF(A154="","",$V$1) -> 46287 | Q154: Pasaje N°9 | R154: 75 | S154: Red distribuidora | T154: =IF(A154="","",IF(AND(L154="Para Programar",G154=0),"INCONSISTENCIA - REVISAR MANUALMENTE: Para Programar sin saldo",IF(AND(L154="Terminada",G154>0),"INCONSISTENCIA - REVISAR MANUALMENTE: Terminada con saldo",""))) -> INCONSISTENCIA - REVISAR MANUALMENTE: Terminada con saldo | U154: =IF(AND(L154="Para Programar",G154>0),COUNTIFS($L$5:L154,"Para Programar",$G$5:G154,">0"),"") | W154: =IF(OR(B154="",C154=""),"",B154&"|"&C154) -> N12 - N13|04 Inspecciones previas - Laboratorio base de asiento | X154: 0
A155: HI-02 | B155: N12 - N13 | C155: 04 Inspecciones previas - Zanja y materiales | D155: tramo | E155: 1 | F155: =IF(E155="","",MIN(E155,$X155+SUMIFS('05_Parte_Diario'!$H$5:$H$204,'05_Parte_Diario'!$D$5:$D$204,B155,'05_Parte_Diario'!$E$5:$E$204,C155))) -> 0 | G155: =IF(E155="","",MAX(E155-F155,0)) -> 1 | H155: =IFERROR(F155/E155,0) -> 0 | I155: =IF(OR(B155="",C155="",$V$1=""),"",MIN(E155,SUMIFS('03_Planificacion'!$G$99:$G$178,'03_Planificacion'!$E$99:$E$178,B155,'03_Planificacion'!$F$99:$F$178,C155,'03_Planificacion'!$D$99:$D$178,"<="&$V$1))) -> 0 | J155: =IFERROR(I155/E155,0) -> 0 | K155: =IF(OR(E155="",$V$1=""),"",H155-J155) -> 0 | L155: Terminada | P155: =IF(A155="","",$V$1) -> 46287 | Q155: Pasaje N°9 | R155: 75 | S155: Red distribuidora | T155: =IF(A155="","",IF(AND(L155="Para Programar",G155=0),"INCONSISTENCIA - REVISAR MANUALMENTE: Para Programar sin saldo",IF(AND(L155="Terminada",G155>0),"INCONSISTENCIA - REVISAR MANUALMENTE: Terminada con saldo",""))) -> INCONSISTENCIA - REVISAR MANUALMENTE: Terminada con saldo | U155: =IF(AND(L155="Para Programar",G155>0),COUNTIFS($L$5:L155,"Para Programar",$G$5:G155,">0"),"") | W155: =IF(OR(B155="",C155=""),"",B155&"|"&C155) -> N12 - N13|04 Inspecciones previas - Zanja y materiales | X155: 0
A156: AG-08 | B156: N12 - N13 | C156: 05 Tendido de cañería - Cañería principal | D156: m | E156: 200 | F156: =IF(E156="","",MIN(E156,$X156+SUMIFS('05_Parte_Diario'!$H$5:$H$204,'05_Parte_Diario'!$D$5:$D$204,B156,'05_Parte_Diario'!$E$5:$E$204,C156))) -> 0 | G156: =IF(E156="","",MAX(E156-F156,0)) -> 200 | H156: =IFERROR(F156/E156,0) -> 0 | I156: =IF(OR(B156="",C156="",$V$1=""),"",MIN(E156,SUMIFS('03_Planificacion'!$G$99:$G$178,'03_Planificacion'!$E$99:$E$178,B156,'03_Planificacion'!$F$99:$F$178,C156,'03_Planificacion'!$D$99:$D$178,"<="&$V$1))) -> 0 | J156: =IFERROR(I156/E156,0) -> 0 | K156: =IF(OR(E156="",$V$1=""),"",H156-J156) -> 0 | L156: Para Programar | P156: =IF(A156="","",$V$1) -> 46287 | Q156: Pasaje N°9 | R156: 75 | S156: Red distribuidora | T156: =IF(A156="","",IF(AND(L156="Para Programar",G156=0),"INCONSISTENCIA - REVISAR MANUALMENTE: Para Programar sin saldo",IF(AND(L156="Terminada",G156>0),"INCONSISTENCIA - REVISAR MANUALMENTE: Terminada con saldo",""))) | U156: =IF(AND(L156="Para Programar",G156>0),COUNTIFS($L$5:L156,"Para Programar",$G$5:G156,">0"),"") -> 4 | W156: =IF(OR(B156="",C156=""),"",B156&"|"&C156) -> N12 - N13|05 Tendido de cañería - Cañería principal | X156: 0
A157: AG-09 | B157: N12 - N13 | C157: 05 Tendido de cañería - Relevamiento planialtimétrico | D157: m | E157: 200 | F157: =IF(E157="","",MIN(E157,$X157+SUMIFS('05_Parte_Diario'!$H$5:$H$204,'05_Parte_Diario'!$D$5:$D$204,B157,'05_Parte_Diario'!$E$5:$E$204,C157))) -> 0 | G157: =IF(E157="","",MAX(E157-F157,0)) -> 200 | H157: =IFERROR(F157/E157,0) -> 0 | I157: =IF(OR(B157="",C157="",$V$1=""),"",MIN(E157,SUMIFS('03_Planificacion'!$G$99:$G$178,'03_Planificacion'!$E$99:$E$178,B157,'03_Planificacion'!$F$99:$F$178,C157,'03_Planificacion'!$D$99:$D$178,"<="&$V$1))) -> 0 | J157: =IFERROR(I157/E157,0) -> 0 | K157: =IF(OR(E157="",$V$1=""),"",H157-J157) -> 0 | L157: No iniciada | P157: =IF(A157="","",$V$1) -> 46287 | Q157: Pasaje N°9 | R157: 75 | S157: Red distribuidora | T157: =IF(A157="","",IF(AND(L157="Para Programar",G157=0),"INCONSISTENCIA - REVISAR MANUALMENTE: Para Programar sin saldo",IF(AND(L157="Terminada",G157>0),"INCONSISTENCIA - REVISAR MANUALMENTE: Terminada con saldo",""))) | U157: =IF(AND(L157="Para Programar",G157>0),COUNTIFS($L$5:L157,"Para Programar",$G$5:G157,">0"),"") | W157: =IF(OR(B157="",C157=""),"",B157&"|"&C157) -> N12 - N13|05 Tendido de cañería - Relevamiento planialtimétrico | X157: 0
A158: AG-17 | B158: N12 - N13 | C158: 08 Prueba hidráulica - Preparación del sistema | D158: tramo | E158: 1 | F158: =IF(E158="","",MIN(E158,$X158+SUMIFS('05_Parte_Diario'!$H$5:$H$204,'05_Parte_Diario'!$D$5:$D$204,B158,'05_Parte_Diario'!$E$5:$E$204,C158))) -> 0 | G158: =IF(E158="","",MAX(E158-F158,0)) -> 1 | H158: =IFERROR(F158/E158,0) -> 0 | I158: =IF(OR(B158="",C158="",$V$1=""),"",MIN(E158,SUMIFS('03_Planificacion'!$G$99:$G$178,'03_Planificacion'!$E$99:$E$178,B158,'03_Planificacion'!$F$99:$F$178,C158,'03_Planificacion'!$D$99:$D$178,"<="&$V$1))) -> 0 | J158: =IFERROR(I158/E158,0) -> 0 | K158: =IF(OR(E158="",$V$1=""),"",H158-J158) -> 0 | L158: No iniciada | P158: =IF(A158="","",$V$1) -> 46287 | Q158: Pasaje N°9 | R158: 75 | S158: Red distribuidora | T158: =IF(A158="","",IF(AND(L158="Para Programar",G158=0),"INCONSISTENCIA - REVISAR MANUALMENTE: Para Programar sin saldo",IF(AND(L158="Terminada",G158>0),"INCONSISTENCIA - REVISAR MANUALMENTE: Terminada con saldo",""))) | U158: =IF(AND(L158="Para Programar",G158>0),COUNTIFS($L$5:L158,"Para Programar",$G$5:G158,">0"),"") | W158: =IF(OR(B158="",C158=""),"",B158&"|"&C158) -> N12 - N13|08 Prueba hidráulica - Preparación del sistema | X158: 0
...

Sheet 02_Para_Programar
A1: ECAR | OBRA ROQUE — PARA PROGRAMAR
A2: Bandeja automática: sólo actividades de 01_Estado_Actual con Estado = Para Programar y Saldo > 0.
A3: Cantidad válida Para Programar | B3: =COUNTIFS('01_Estado_Actual'!$L$5:$L$1204,"Para Programar",'01_Estado_Actual'!$G$5:$G$1204,">0") -> 144
A4: ID PP | B4: Sector / Tramo | C4: Código | D4: Actividad | E4: Unidad | F4: Saldo | G4: Pasaje / Calle | H4: Ø (mm) | I4: Prioridad | J4: Responsable | K4: En Plan Maestro? | L4: Restricción / Observación | N4: Clave PP
A5: {=IF(B5="","","PP-"&1)} -> PP-1 | B5: N10 - N15 | C5: AG-03 | D5: 02 Excavación - Zanja principal | E5: m | F5: 56 | G5: Pasaje N°2 | H5: 110 | I5: 0 | J5: 0 | K5: =IF(A5="","",IF(COUNTIFS('03_Planificacion'!$B$5:$B$84,B5,'03_Planificacion'!$C$5:$C$84,D5)>0,"SÍ","NO")) -> NO | L5: {=_xlfn._xlws.FILTER('01_Estado_Actual'!$M$5:$M$1204,('01_Estado_Actual'!$L$5:$L$1204="Para Programar")*('01_Estado_Actual'!$G$5:$G$1204>0),"")} -> 0 | N5: =IF(B5="","",B5&"|"&D5) -> N10 - N15|02 Excavación - Zanja principal
A6: PP-2 | B6: N10 - N15 | C6: AG-05 | D6: 03 Base de asiento - Nivelación de fondo de zanja | E6: m | F6: 81 | G6: Pasaje N°2 | H6: 110 | I6: 0 | J6: 0 | K6: =IF(A6="","",IF(COUNTIFS('03_Planificacion'!$B$5:$B$84,B6,'03_Planificacion'!$C$5:$C$84,D6)>0,"SÍ","NO")) -> NO | L6: 0 | N6: =IF(B6="","",B6&"|"&D6) -> N10 - N15|03 Base de asiento - Nivelación de fondo de zanja
A7: PP-3 | B7: N10 - N15 | C7: AG-06 | D7: 03 Base de asiento - Aporte de material base e=0,10 m | E7: m | F7: 81 | G7: Pasaje N°2 | H7: 110 | I7: 0 | J7: 0 | K7: =IF(A7="","",IF(COUNTIFS('03_Planificacion'!$B$5:$B$84,B7,'03_Planificacion'!$C$5:$C$84,D7)>0,"SÍ","NO")) -> NO | L7: 0 | N7: =IF(B7="","",B7&"|"&D7) -> N10 - N15|03 Base de asiento - Aporte de material base e=0,10 m
A8: PP-4 | B8: N10 - N15 | C8: AG-07 | D8: 03 Base de asiento - Compactación | E8: m | F8: 81 | G8: Pasaje N°2 | H8: 110 | I8: Alta | J8: 0 | K8: =IF(A8="","",IF(COUNTIFS('03_Planificacion'!$B$5:$B$84,B8,'03_Planificacion'!$C$5:$C$84,D8)>0,"SÍ","NO")) -> NO | L8: 0 | N8: =IF(B8="","",B8&"|"&D8) -> N10 - N15|03 Base de asiento - Compactación
A9: PP-5 | B9: N10 - N15 | C9: HI-01 | D9: 04 Inspecciones previas - Laboratorio base de asiento | E9: tramo | F9: 1 | G9: Pasaje N°2 | H9: 110 | I9: 0 | J9: 0 | K9: =IF(A9="","",IF(COUNTIFS('03_Planificacion'!$B$5:$B$84,B9,'03_Planificacion'!$C$5:$C$84,D9)>0,"SÍ","NO")) -> NO | L9: 0 | N9: =IF(B9="","",B9&"|"&D9) -> N10 - N15|04 Inspecciones previas - Laboratorio base de asiento
A10: PP-6 | B10: N10 - N15 | C10: HI-02 | D10: 04 Inspecciones previas - Zanja y materiales | E10: tramo | F10: 1 | G10: Pasaje N°2 | H10: 110 | I10: 0 | J10: 0 | K10: =IF(A10="","",IF(COUNTIFS('03_Planificacion'!$B$5:$B$84,B10,'03_Planificacion'!$C$5:$C$84,D10)>0,"SÍ","NO")) -> NO | L10: 0 | N10: =IF(B10="","",B10&"|"&D10) -> N10 - N15|04 Inspecciones previas - Zanja y materiales
A11: PP-7 | B11: N10 - N15 | C11: AG-08 | D11: 05 Tendido de cañería - Cañería principal | E11: m | F11: 81 | G11: Pasaje N°2 | H11: 110 | I11: 0 | J11: 0 | K11: =IF(A11="","",IF(COUNTIFS('03_Planificacion'!$B$5:$B$84,B11,'03_Planificacion'!$C$5:$C$84,D11)>0,"SÍ","NO")) -> NO | L11: 0 | N11: =IF(B11="","",B11&"|"&D11) -> N10 - N15|05 Tendido de cañería - Cañería principal
A12: PP-8 | B12: N10 - N15 | C12: AG-09 | D12: 05 Tendido de cañería - Relevamiento planialtimétrico | E12: m | F12: 81 | G12: Pasaje N°2 | H12: 110 | I12: 0 | J12: 0 | K12: =IF(A12="","",IF(COUNTIFS('03_Planificacion'!$B$5:$B$84,B12,'03_Planificacion'!$C$5:$C$84,D12)>0,"SÍ","NO")) -> NO | L12: 0 | N12: =IF(B12="","",B12&"|"&D12) -> N10 - N15|05 Tendido de cañería - Relevamiento planialtimétrico
A13: PP-9 | B13: N10 - N15 | C13: AG-17 | D13: 08 Prueba hidráulica - Preparación del sistema | E13: tramo | F13: 1 | G13: Pasaje N°2 | H13: 110 | I13: 0 | J13: 0 | K13: =IF(A13="","",IF(COUNTIFS('03_Planificacion'!$B$5:$B$84,B13,'03_Planificacion'!$C$5:$C$84,D13)>0,"SÍ","NO")) -> NO | L13: 0 | N13: =IF(B13="","",B13&"|"&D13) -> N10 - N15|08 Prueba hidráulica - Preparación del sistema
A14: PP-10 | B14: N10 - N15 | C14: AG-18 | D14: 08 Prueba hidráulica - Interna N° 1 | E14: tramo | F14: 1 | G14: Pasaje N°2 | H14: 110 | I14: 0 | J14: 0 | K14: =IF(A14="","",IF(COUNTIFS('03_Planificacion'!$B$5:$B$84,B14,'03_Planificacion'!$C$5:$C$84,D14)>0,"SÍ","NO")) -> NO | L14: 0 | N14: =IF(B14="","",B14&"|"&D14) -> N10 - N15|08 Prueba hidráulica - Interna N° 1
A15: PP-11 | B15: N10 - N15 | C15: AG-19 | D15: 08 Prueba hidráulica - Interna N° 2 | E15: tramo | F15: 1 | G15: Pasaje N°2 | H15: 110 | I15: 0 | J15: 0 | K15: =IF(A15="","",IF(COUNTIFS('03_Planificacion'!$B$5:$B$84,B15,'03_Planificacion'!$C$5:$C$84,D15)>0,"SÍ","NO")) -> NO | L15: 0 | N15: =IF(B15="","",B15&"|"&D15) -> N10 - N15|08 Prueba hidráulica - Interna N° 2
A16: PP-12 | B16: N10 - N15 | C16: HI-03 | D16: 08 Prueba hidráulica - Primera prueba oficial | E16: tramo | F16: 1 | G16: Pasaje N°2 | H16: 110 | I16: 0 | J16: 0 | K16: =IF(A16="","",IF(COUNTIFS('03_Planificacion'!$B$5:$B$84,B16,'03_Planificacion'!$C$5:$C$84,D16)>0,"SÍ","NO")) -> NO | L16: 0 | N16: =IF(B16="","",B16&"|"&D16) -> N10 - N15|08 Prueba hidráulica - Primera prueba oficial
A17: PP-13 | B17: N10 - N15 | C17: AG-20 | D17: 09 Paquete estructural - Aporte e=0,30 m | E17: m | F17: 81 | G17: Pasaje N°2 | H17: 110 | I17: 0 | J17: 0 | K17: =IF(A17="","",IF(COUNTIFS('03_Planificacion'!$B$5:$B$84,B17,'03_Planificacion'!$C$5:$C$84,D17)>0,"SÍ","NO")) -> NO | L17: 0 | N17: =IF(B17="","",B17&"|"&D17) -> N10 - N15|09 Paquete estructural - Aporte e=0,30 m
A18: PP-14 | B18: N10 - N15 | C18: AG-21 | D18: 09 Paquete estructural - Compactación | E18: m | F18: 81 | G18: Pasaje N°2 | H18: 110 | I18: 0 | J18: 0 | K18: =IF(A18="","",IF(COUNTIFS('03_Planificacion'!$B$5:$B$84,B18,'03_Planificacion'!$C$5:$C$84,D18)>0,"SÍ","NO")) -> NO | L18: 0 | N18: =IF(B18="","",B18&"|"&D18) -> N10 - N15|09 Paquete estructural - Compactación
A19: PP-15 | B19: N10 - N15 | C19: HI-04 | D19: 09 Paquete estructural - Inspección laboratorio | E19: tramo | F19: 1 | G19: Pasaje N°2 | H19: 110 | I19: 0 | J19: 0 | K19: =IF(A19="","",IF(COUNTIFS('03_Planificacion'!$B$5:$B$84,B19,'03_Planificacion'!$C$5:$C$84,D19)>0,"SÍ","NO")) -> NO | L19: 0 | N19: =IF(B19="","",B19&"|"&D19) -> N10 - N15|09 Paquete estructural - Inspección laboratorio
A20: PP-16 | B20: N10 - N15 | C20: AG-22 | D20: 10 Relleno -0,60 - Conformación de capa | E20: m | F20: 81 | G20: Pasaje N°2 | H20: 110 | I20: 0 | J20: 0 | K20: =IF(A20="","",IF(COUNTIFS('03_Planificacion'!$B$5:$B$84,B20,'03_Planificacion'!$C$5:$C$84,D20)>0,"SÍ","NO")) -> NO | L20: 0 | N20: =IF(B20="","",B20&"|"&D20) -> N10 - N15|10 Relleno -0,60 - Conformación de capa
... A27: PP-23 | B27: N10 - N15 | C27: HI-06 | D27: 11 Relleno -0,30 - Inspección laboratorio | E27: tramo | F27: 1 | G27: Pasaje N°2 | H27: 110 | I27: 0 | J27: 0 | K27: =IF(A27="","",IF(COUNTIFS('03_Planificacion'!$B$5:$B$84,B27,'03_Planificacion'!$C$5:$C$84,D27)>0,"SÍ","NO")) -> NO | L27: 0 | N27: =IF(B27="","",B27&"|"&D27) -> N10 - N15|11 Relleno -0,30 - Inspección laboratorio
A28: PP-24 | B28: N12 - N13 | C28: AG-07 | D28: 03 Base de asiento - Compactación | E28: m | F28: 200 | G28: Pasaje N°9 | H28: 75 | I28: Alta | J28: 0 | K28: =IF(A28="","",IF(COUNTIFS('03_Planificacion'!$B$5:$B$84,B28,'03_Planificacion'!$C$5:$C$84,D28)>0,"SÍ","NO")) -> NO | L28: 0 | N28: =IF(B28="","",B28&"|"&D28) -> N12 - N13|03 Base de asiento - Compactación
A29: PP-25 | B29: N12 - N13 | C29: HI-01 | D29: 04 Inspecciones previas - Laboratorio base de asiento | E29: tramo | F29: 1 | G29: Pasaje N°9 | H29: 75 | I29: 0 | J29: 0 | K29: =IF(A29="","",IF(COUNTIFS('03_Planificacion'!$B$5:$B$84,B29,'03_Planificacion'!$C$5:$C$84,D29)>0,"SÍ","NO")) -> NO | L29: 0 | N29: =IF(B29="","",B29&"|"&D29) -> N12 - N13|04 Inspecciones previas - Laboratorio base de asiento
A30: PP-26 | B30: N12 - N13 | C30: HI-02 | D30: 04 Inspecciones previas - Zanja y materiales | E30: tramo | F30: 1 | G30: Pasaje N°9 | H30: 75 | I30: 0 | J30: 0 | K30: =IF(A30="","",IF(COUNTIFS('03_Planificacion'!$B$5:$B$84,B30,'03_Planificacion'!$C$5:$C$84,D30)>0,"SÍ","NO")) -> NO | L30: 0 | N30: =IF(B30="","",B30&"|"&D30) -> N12 - N13|04 Inspecciones previas - Zanja y materiales
A31: PP-27 | B31: N12 - N13 | C31: AG-08 | D31: 05 Tendido de cañería - Cañería principal | E31: m | F31: 200 | G31: Pasaje N°9 | H31: 75 | I31: 0 | J31: 0 | K31: =IF(A31="","",IF(COUNTIFS('03_Planificacion'!$B$5:$B$84,B31,'03_Planificacion'!$C$5:$C$84,D31)>0,"SÍ","NO")) -> NO | L31: 0 | N31: =IF(B31="","",B31&"|"&D31) -> N12 - N13|05 Tendido de cañería - Cañería principal
A32: PP-28 | B32: N12 - N13 | C32: AG-09 | D32: 05 Tendido de cañería - Relevamiento planialtimétrico | E32: m | F32: 200 | G32: Pasaje N°9 | H32: 75 | I32: 0 | J32: 0 | K32: =IF(A32="","",IF(COUNTIFS('03_Planificacion'!$B$5:$B$84,B32,'03_Planificacion'!$C$5:$C$84,D32)>0,"SÍ","NO")) -> NO | L32: 0 | N32: =IF(B32="","",B32&"|"&D32) -> N12 - N13|05 Tendido de cañería - Relevamiento planialtimétrico
A33: PP-29 | B33: N12 - N13 | C33: AG-17 | D33: 08 Prueba hidráulica - Preparación del sistema | E33: tramo | F33: 1 | G33: Pasaje N°9 | H33: 75 | I33: 0 | J33: 0 | K33: =IF(A33="","",IF(COUNTIFS('03_Planificacion'!$B$5:$B$84,B33,'03_Planificacion'!$C$5:$C$84,D33)>0,"SÍ","NO")) -> NO | L33: 0 | N33: =IF(B33="","",B33&"|"&D33) -> N12 - N13|08 Prueba hidráulica - Preparación del sistema
A34: PP-30 | B34: N12 - N13 | C34: AG-18 | D34: 08 Prueba hidráulica - Interna N° 1 | E34: tramo | F34: 1 | G34: Pasaje N°9 | H34: 75 | I34: 0 | J34: 0 | K34: =IF(A34="","",IF(COUNTIFS('03_Planificacion'!$B$5:$B$84,B34,'03_Planificacion'!$C$5:$C$84,D34)>0,"SÍ","NO")) -> NO | L34: 0 | N34: =IF(B34="","",B34&"|"&D34) -> N12 - N13|08 Prueba hidráulica - Interna N° 1
A35: PP-31 | B35: N12 - N20 | C35: AG-07 | D35: 03 Base de asiento - Compactación | E35: m | F35: 98 | G35: Pasaje N°5 | H35: 75 | I35: 0 | J35: 0 | K35: =IF(A35="","",IF(COUNTIFS('03_Planificacion'!$B$5:$B$84,B35,'03_Planificacion'!$C$5:$C$84,D35)>0,"SÍ","NO")) -> NO | L35: 0 | N35: =IF(B35="","",B35&"|"&D35) -> N12 - N20|03 Base de asiento - Compactación
A36: PP-32 | B36: N12 - N20 | C36: HI-01 | D36: 04 Inspecciones previas - Laboratorio base de asiento | E36: tramo | F36: 1 | G36: Pasaje N°5 | H36: 75 | I36: 0 | J36: 0 | K36: =IF(A36="","",IF(COUNTIFS('03_Planificacion'!$B$5:$B$84,B36,'03_Planificacion'!$C$5:$C$84,D36)>0,"SÍ","NO")) -> NO | L36: 0 | N36: =IF(B36="","",B36&"|"&D36) -> N12 - N20|04 Inspecciones previas - Laboratorio base de asiento
A37: PP-33 | B37: N12 - N20 | C37: HI-02 | D37: 04 Inspecciones previas - Zanja y materiales | E37: tramo | F37: 1 | G37: Pasaje N°5 | H37: 75 | I37: 0 | J37: 0 | K37: =IF(A37="","",IF(COUNTIFS('03_Planificacion'!$B$5:$B$84,B37,'03_Planificacion'!$C$5:$C$84,D37)>0,"SÍ","NO")) -> NO | L37: 0 | N37: =IF(B37="","",B37&"|"&D37) -> N12 - N20|04 Inspecciones previas - Zanja y materiales
A38: PP-34 | B38: N12 - N20 | C38: AG-08 | D38: 05 Tendido de cañería - Cañería principal | E38: m | F38: 98 | G38: Pasaje N°5 | H38: 75 | I38: 0 | J38: 0 | K38: =IF(A38="","",IF(COUNTIFS('03_Planificacion'!$B$5:$B$84,B38,'03_Planificacion'!$C$5:$C$84,D38)>0,"SÍ","NO")) -> NO | L38: 0 | N38: =IF(B38="","",B38&"|"&D38) -> N12 - N20|05 Tendido de cañería - Cañería principal
A39: PP-35 | B39: N12 - N20 | C39: AG-09 | D39: 05 Tendido de cañería - Relevamiento planialtimétrico | E39: m | F39: 98 | G39: Pasaje N°5 | H39: 75 | I39: 0 | J39: 0 | K39: =IF(A39="","",IF(COUNTIFS('03_Planificacion'!$B$5:$B$84,B39,'03_Planificacion'!$C$5:$C$84,D39)>0,"SÍ","NO")) -> NO | L39: 0 | N39: =IF(B39="","",B39&"|"&D39) -> N12 - N20|05 Tendido de cañería - Relevamiento planialtimétrico
A40: PP-36 | B40: N12 - N20 | C40: AG-17 | D40: 08 Prueba hidráulica - Preparación del sistema | E40: tramo | F40: 1 | G40: Pasaje N°5 | H40: 75 | I40: 0 | J40: 0 | K40: =IF(A40="","",IF(COUNTIFS('03_Planificacion'!$B$5:$B$84,B40,'03_Planificacion'!$C$5:$C$84,D40)>0,"SÍ","NO")) -> NO | L40: 0 | N40: =IF(B40="","",B40&"|"&D40) -> N12 - N20|08 Prueba hidráulica - Preparación del sistema
... A47: PP-43 | B47: N13 - N23 | C47: AG-17 | D47: 08 Prueba hidráulica - Preparación del sistema | E47: tramo | F47: 1 | G47: Pasaje N°3 | H47: 75 | I47: 0 | J47: 0 | K47: =IF(A47="","",IF(COUNTIFS('03_Planificacion'!$B$5:$B$84,B47,'03_Planificacion'!$C$5:$C$84,D47)>0,"SÍ","NO")) -> NO | L47: 0 | N47: =IF(B47="","",B47&"|"&D47) -> N13 - N23|08 Prueba hidráulica - Preparación del sistema
A48: PP-44 | B48: N13 - N23 | C48: AG-18 | D48: 08 Prueba hidráulica - Interna N° 1 | E48: tramo | F48: 1 | G48: Pasaje N°3 | H48: 75 | I48: 0 | J48: 0 | K48: =IF(A48="","",IF(COUNTIFS('03_Planificacion'!$B$5:$B$84,B48,'03_Planificacion'!$C$5:$C$84,D48)>0,"SÍ","NO")) -> NO | L48: Preguntar si esta listo | N48: =IF(B48="","",B48&"|"&D48) -> N13 - N23|08 Prueba hidráulica - Interna N° 1
A49: PP-45 | B49: N13 - N23 | C49: AG-19 | D49: 08 Prueba hidráulica - Interna N° 2 | E49: tramo | F49: 1 | G49: Pasaje N°3 | H49: 75 | I49: 0 | J49: 0 | K49: =IF(A49="","",IF(COUNTIFS('03_Planificacion'!$B$5:$B$84,B49,'03_Planificacion'!$C$5:$C$84,D49)>0,"SÍ","NO")) -> NO | L49: 0 | N49: =IF(B49="","",B49&"|"&D49) -> N13 - N23|08 Prueba hidráulica - Interna N° 2
A50: PP-46 | B50: N13 - N23 | C50: HI-03 | D50: 08 Prueba hidráulica - Primera prueba oficial | E50: tramo | F50: 1 | G50: Pasaje N°3 | H50: 75 | I50: 0 | J50: 0 | K50: =IF(A50="","",IF(COUNTIFS('03_Planificacion'!$B$5:$B$84,B50,'03_Planificacion'!$C$5:$C$84,D50)>0,"SÍ","NO")) -> NO | L50: 0 | N50: =IF(B50="","",B50&"|"&D50) -> N13 - N23|08 Prueba hidráulica - Primera prueba oficial
