Workbook

Sheet Distribucion Contrato
A1: DISTRIBUCIÓN DEL SALDO CONTRACTUAL CERTIFICABLE – AGUA Y CLOACA
A3: Criterio: mantener la misma proporción económica de la oferta aceptada ($400 M Agua / $680 M Cloaca) para distribuir el saldo contractual de $374,4 M IVA incluido.
A5: Concepto | B5: Oferta original s/IVA | C5: Participación | D5: Saldo certificable s/IVA | E5: IVA | F5: Saldo certificable c/IVA
A6: Red de Agua | B6: =Configuracion!B10 -> 400000000 | C6: =Configuracion!B13 -> 0.37037037 | D6: =Configuracion!B18 -> 1.1460055e+08 | E6: =D6*Configuracion!B16 -> 24066116 | F6: =Configuracion!B19 -> 1.3866667e+08
A7: Red Cloacal | B7: =Configuracion!B11 -> 680000000 | C7: =Configuracion!B14 -> 0.62962963 | D7: =Configuracion!B20 -> 1.9482094e+08 | E7: =D7*Configuracion!B16 -> 40912397 | F7: =Configuracion!B21 -> 2.3573333e+08
A8: TOTAL | B8: =SUM(B6:B7) -> 1080000000 | C8: =SUM(C6:C7) -> 1 | D8: =SUM(D6:D7) -> 3.0942149e+08 | E8: =SUM(E6:E7) -> 64978512 | F8: =SUM(F6:F7) -> 3.744e+08
A10: Referencia contractual
A11: Cláusula c) | B11: $374.400.000 IVA incluido mediante certificaciones mensuales según avance de obra.
A12: Actualización | B12: Índice UOCRA – mes base JULIO 2026.
A13: Aclaración | B13: La distribución Agua/Cloaca es un criterio interno basado en la proporción de la oferta aceptada.

Sheet Resumen
A1: ECAR – CONTROL ECONÓMICO Y CERTIFICACIÓN | RED DE AGUA – LOTEO ROQUE
A3: Panel ejecutivo vinculado al Presupuesto Base, Medición y Certificado.
A5: INDICADOR | B5: VALOR | D5: CONTROL | E5: ESTADO
A6: Valor original Red de Agua s/IVA | B6: =Configuracion!B10 -> 400000000 | D6: Distribución contrato Agua | E6: =IF(ABS('Distribucion Contrato'!F8-Configuracion!B15)<0.01,"OK","REVISAR") -> OK
A7: Saldo certificable Agua s/IVA | B7: =Configuracion!B18 -> 1.1460055e+08 | D7: Incidencias = 100% | E7: =IF(ABS('Presupuesto Base'!G25-1)<0.000001,"OK","REVISAR") -> OK
A8: Saldo certificable Agua c/IVA | B8: =Configuracion!B19 -> 1.3866667e+08 | D8: Excesos en certificado | E8: =IF(Certificado!M28<=Configuracion!B18+0.01,"OK","REVISAR") -> OK
A9: Certificado seleccionado N° | B9: =Certificado!B4 -> 1 | D9: Mes base UOCRA | E9: =Configuracion!B22 -> Julio 2026
A10: Último certificado con movimiento | B10: =MAX(Medicion!$A$6:$A$511) -> 1
A11: Certificados cerrados | B11: =COUNTIF('Historial Certificados'!$E$6:$E$29,"CERRADO") -> 0
A12: Certificación presente seleccionado s/IVA | B12: =IFERROR(VLOOKUP(Certificado!B4,'Historial Certificados'!$A$6:$O$29,8,FALSE),0) -> 14722545
A13: Acumulado certificado seleccionado | B13: =IFERROR(VLOOKUP(Certificado!B4,'Historial Certificados'!$A$6:$O$29,9,FALSE),0) -> 14722545
A14: Saldo luego del certificado | B14: =IFERROR(VLOOKUP(Certificado!B4,'Historial Certificados'!$A$6:$O$29,10,FALSE),Configuracion!B18) -> 99878006
A15: Avance económico acumulado | B15: =IFERROR(VLOOKUP(Certificado!B4,'Historial Certificados'!$A$6:$O$29,11,FALSE),0) -> 0.12846836
A16: Composición saldo certificable Agua | B16: Monto s/IVA
A17: Obra civil lineal | B17: =Configuracion!B18*0.5625 -> 64462810
A18: Cañerías | B18: =Configuracion!B18*0.27 -> 30942149
A19: Conexiones | B19: =Configuracion!B18*0.1 -> 11460055
A20: Válvulas e hidrantes | B20: =Configuracion!B18*0.035 -> 4011019.3
A21: Pruebas / terminaciones / documentación | B21: =Configuracion!B18*0.0325 -> 3724517.9
A22: Conexiones terminadas | B22: =COUNTIF(Conexiones!$J$6:$J$232,"Terminada") -> 0
A23: Conexiones totales | B23: =Configuracion!B30 -> 227
A24: Flujo recomendado: 1) completar período y estado en Historial Certificados; 2) cargar avances en Medicion; 3) seleccionar el Certificado N° en Certificado; 4) revisar ANTERIOR / PRESENTE / ACUMULADO; 5) verificar controles; 6) una vez emitido definitivamente, cambiar Estado a CERRADO y no modificar esas mediciones.

Sheet Configuracion
A1: CONFIGURACIÓN GENERAL – CERTIFICACIÓN RED DE AGUA
A4: Dato | B4: Valor | D4: Código de color | E4: Uso | F4: Descripción
A5: Obra | B5: Red Distribuidora de Agua Potable – Loteo Roque | D5: AMARILLO | E5: Carga manual | F5: Celdas que el usuario puede completar o modificar.
A6: Ubicación | B6: Santa Lucía, San Juan | D6: CELESTE | E6: Cálculo | F6: Celdas con fórmulas o datos vinculados.
A7: Comitente | B7: VALDIVIESO GROUP S.R.L. | D7: VERDE | E7: OK | F7: Control correcto / dentro de límites.
A8: Contratista | B8: ECAR SAS | D8: ROJO | E8: Alerta | F8: Dato excedido, incompleto o inconsistente.
A9: Ente de inspección | B9: O.S.S.E.
A10: Monto original oferta Agua s/IVA | B10: 400000000
A11: Monto original oferta Cloaca s/IVA | B11: 680000000
A12: Monto original oferta Total s/IVA | B12: =B10+B11 -> 1080000000
A13: Participación Agua | B13: =B10/B12 -> 0.37037037
A14: Participación Cloaca | B14: =B11/B12 -> 0.62962963
A15: Saldo contractual certificable TOTAL c/IVA | B15: 374400000
A16: IVA | B16: 0.21
A17: Saldo contractual certificable TOTAL s/IVA | B17: =B15/(1+B16) -> 3.0942149e+08
A18: Saldo certificable Agua s/IVA | B18: =B17*B13 -> 1.1460055e+08
A19: Saldo certificable Agua c/IVA | B19: =B18*(1+B16) -> 1.3866667e+08
A20: Saldo certificable Cloaca s/IVA | B20: =B17*B14 -> 1.9482094e+08
A21: Saldo certificable Cloaca c/IVA | B21: =B20*(1+B16) -> 2.3573333e+08
A22: Mes base actualización | B22: Julio 2026
A23: Índice actualización | B23: UOCRA
A24: NOTA DE USO | D24: NOTA CONTRACTUAL
A25: Longitud PEAD Ø75 mm (ml) | B25: 3170 | D25: El contrato establece un saldo de $374.400.000 IVA incluido a abonar mediante certificaciones mensuales según avance de obra, actualizable por índice UOCRA con mes base JULIO 2026. Para separar Agua y Cloaca se mantiene la proporción económica de la oferta aceptada: Agua $400.000.000 s/IVA y Cloaca $680.000.000 s/IVA. Esta distribución es un criterio interno de certificación y no modifica el valor original de cada red.
A26: Longitud PEAD Ø110 mm (ml) | B26: 1030
A27: Longitud total red (ml) | B27: 4200
A28: Conexiones sobre Ø75 (un) | B28: 165
A29: Conexiones sobre Ø110 (un) | B29: 62
A30: Total conexiones (un) | B30: 227 | D30: FUENTES DE REFERENCIA
A31: Válvulas Ø75 (un) | B31: 2 | D31: Documento | E31: Cotización ECAR SAS Loteo Roque.pdf
A32: Válvulas Ø100 (un) | B32: 4 | D32: Contrato | E32: Cláusula c) – saldo $374.400.000 IVA incluido / certificaciones mensuales
A33: Hidrantes (un) | B33: 15 | D33: Criterio ECAR | E33: Distribución proporcional Agua 37,037% / Cloaca 62,963%

Sheet Sectores
D3: Código | H3: Longitudes
B4: Pasaje 3 | C4: MzaA | D4: 1 | E4: N25 | F4: N30 | G4: =+CONCATENATE(E4,"-",F4) -> N25-N30 | H4: 76
B5: Pasaje 8 | C5: MzaA | D5: =+D4+1 -> 2 | E5: N30 | F5: N29 | G5: =+CONCATENATE(E5,"-",F5) -> N30-N29 | H5: 106
B6: Pasaje 4 | D6: =+D5+1 -> 3 | E6: N29 | F6: N22 | G6: =+CONCATENATE(E6,"-",F6) -> N29-N22 | H6: 92
B7: Pasaje 2 | C7: MzaA | D7: =+D6+1 -> 4 | E7: N22 | F7: N24 | G7: =+CONCATENATE(E7,"-",F7) -> N22-N24 | H7: 96
B8: Pasaje 2 | C8: MzaA | D8: =+D7+1 -> 5 | E8: N24 | F8: N25 | G8: =+CONCATENATE(E8,"-",F8) -> N24-N25 | H8: 15
B10: Pasaje 8 | C10: MzaB | D10: =+D8+1 -> 6 | E10: N29 | F10: N28 | G10: =+CONCATENATE(E10,"-",F10) -> N29-N28 | H10: 100
B11: Pasaje 5 | D11: =+D10+1 -> 7 | E11: N28 | F11: N21 | G11: =+CONCATENATE(E11,"-",F11) -> N28-N21 | H11: 102
B12: Pasaje 2 | C12: MzaB | D12: =+D11+1 -> 8 | E12: N20 | F12: N21 | G12: =+CONCATENATE(E12,"-",F12) -> N20-N21 | H12: 97
B13: Pasaje 2 | D13: =+D12+1 -> 9 | E13: N21 | F13: N22 | G13: =+CONCATENATE(E13,"-",F13) -> N21-N22 | H13: 2
B15: Pasaje 8 | C15: MzaC | D15: =+D13+1 -> 10 | E15: N28 | F15: N27 | G15: =+CONCATENATE(E15,"-",F15) -> N28-N27 | H15: 82
B16: Pasaje 6 | D16: =+D15+1 -> 11 | E16: N27 | F16: N19 | G16: =+CONCATENATE(E16,"-",F16) -> N27-N19 | H16: 117
B17: Pasaje 2 | C17: MzaC | D17: =+D16+1 -> 12 | E17: N19 | F17: N20 | G17: =+CONCATENATE(E17,"-",F17) -> N19-N20 | H17: 77
B19: Pasaje 8 | C19: MzaD | D19: 13 | E19: N27 | F19: N26 | G19: =+CONCATENATE(E19,"-",F19) -> N27-N26 | H19: 81
B20: Pasaje 7 | C20: MzaD | D20: 14 | E20: N26 | F20: N18 | G20: =+CONCATENATE(E20,"-",F20) -> N26-N18 | H20: 113
B21: Pasaje 2 | C21: MzaD | D21: 15 | E21: N18 | F21: N19 | G21: =+CONCATENATE(E21,"-",F21) -> N18-N19 | H21: 88
B23: Pasaje 3 | C23: Mza E | D23: 16 | E23: N13 | F23: N23 | G23: =+CONCATENATE(E23,"-",F23) -> N13-N23 | H23: 78
B24: Pasaje 3 | C24: Mza E | D24: 17 | E24: N23 | F24: N24 | G24: =+CONCATENATE(E24,"-",F24) -> N23-N24 | H24: 8
B25: Pasaje 5 | C25: Mza E | D25: 18 | E25: N20 | F25: N12 | G25: =+CONCATENATE(E25,"-",F25) -> N20-N12 | H25: 98
B26: Pasaje 9 | C26: Mza E | D26: 19 | E26: N12 | F26: N13 | G26: =+CONCATENATE(E26,"-",F26) -> N12-N13 | H26: 200
B28: Pasaje 14 | C28: F | D28: =+D26+1 -> 20 | E28: N18 | F28: N17 | G28: =+CONCATENATE(E28,"-",F28) -> N18-N17 | H28: 24
B29: Pasaje 9 | C29: F | D29: =+D28+1 -> 21 | E29: N17 | F29: N11 | G29: =+CONCATENATE(E29,"-",F29) -> N17-N11 | H29: 92
B30: Pasaje 9 | C30: F | D30: =+D29+1 -> 22 | E30: N11 | F30: N12 | G30: =+CONCATENATE(E30,"-",F30) -> N11-N12 | H30: 182
B32: Pasaje 2 | C32: G | D32: =+D30+1 -> 23 | E32: N17 | F32: N15 | G32: =+CONCATENATE(E32,"-",F32) -> N17-N15 | H32: 245
B33: Pasaje 2 | C33: G | D33: =+D32+1 -> 24 | E33: N16 | F33: N15 | G33: =+CONCATENATE(E33,"-",F33) -> N16-N15 | H33: 7
B34: Pasaje 2 | C34: G | D34: =+D33+1 -> 25 | E34: N15 | F34: N10 | G34: =+CONCATENATE(E34,"-",F34) -> N15-N10 | H34: 81
B35: Pasaje 2 | C35: G | D35: =+D34+1 -> 26 | E35: N10 | F35: N9 | G35: =+CONCATENATE(E35,"-",F35) -> N10-N9 | H35: 10
B36: Pasaje 2 | C36: G | D36: =+D35+1 -> 27 | E36: N9 | F36: N11 | G36: =+CONCATENATE(E36,"-",F36) -> N9-N11 | H36: 210
C38: H | D38: 27 | E38: N16 | F38: N14 | G38: =+CONCATENATE(E38,"-",F38) -> N16-N14 | H38: 136
C39: H | D39: =+D38+1 -> 28 | E39: N14 | F39: N8 | G39: =+CONCATENATE(E39,"-",F39) -> N14-N8 | H39: 110
C40: H | D40: =+D39+1 -> 29 | E40: N8 | F40: N10 | G40: =+CONCATENATE(E40,"-",F40) -> N8-N10 | H40: 140
C42: I | D42: =+D40+1 -> 30 | E42: N7 | F42: N11 | G42: =+CONCATENATE(E42,"-",F42) -> N7-N11 | H42: 80
C43: I | D43: =+D42+1 -> 31 | E43: N9 | F43: N6 | G43: =+CONCATENATE(E43,"-",F43) -> N9-N6 | H43: 91
C44: I | D44: =+D43+1 -> 32 | E44: N6 | F44: N5 | G44: =+CONCATENATE(E44,"-",F44) -> N6-N5 | H44: 10
C45: I | D45: =+D44+1 -> 33 | E45: N5 | F45: N7 | G45: =+CONCATENATE(E45,"-",F45) -> N5-N7 | H45: 188
C47: J | D47: =+D45+1 -> 34 | E47: N8 | F47: N4 | G47: =+CONCATENATE(E47,"-",F47) -> N8-N4 | H47: 118
C48: J | D48: =+D47+1 -> 35 | E48: N4 | F48: N6 | G48: =+CONCATENATE(E48,"-",F48) -> N4-N6 | H48: 167
C50: K | D50: =+D48+1 -> 36 | E50: N3 | F50: N7 | G50: =+CONCATENATE(E50,"-",F50) -> N3-N7 | H50: 64
C51: K | D51: =+D50+1 -> 37 | E51: N5 | F51: N2 | G51: =+CONCATENATE(E51,"-",F51) -> N5-N2 | H51: 55
C52: K | D52: =+D51+1 -> 38 | E52: N2 | F52: N3 | G52: =+CONCATENATE(E52,"-",F52) -> N2-N3 | H52: 190
...

Sheet Presupuesto Base
A1: PRESUPUESTO BASE DE CERTIFICACIÓN – RED DE AGUA – VERSIÓN 2 AJUSTADA A CONTRATO
A4: Apertura interna del SALDO CERTIFICABLE de la Red de Agua. Las incidencias de la Versión 2 se mantienen y los P.U. se recalculan sobre el saldo de Agua asignado proporcionalmente al contrato.
A6: Ítem | B6: Descripción | C6: Unidad | D6: Cantidad contractual | E6: P.U. interno s/IVA | F6: Importe asignado s/IVA | G6: Incidencia
A7: 1 | B7: Replanteo y marcación de traza | C7: ml | D7: 4200 | E7: =IFERROR(F7/D7,0) -> 204.64384 | F7: =Configuracion!$B$18*G7 -> 859504.13 | G7: 0.0075
A8: 2 | B8: Excavación de zanja | C8: ml | D8: 4200 | E8: =IFERROR(F8/D8,0) -> 3683.5891 | F8: =Configuracion!$B$18*G8 -> 15471074 | G8: 0.135
A9: 3 | B9: Nivelación y conformación del fondo de zanja | C9: ml | D9: 4200 | E9: =IFERROR(F9/D9,0) -> 477.5023 | F9: =Configuracion!$B$18*G9 -> 2005509.6 | G9: 0.0175
A10: 4 | B10: Cama de asiento compactada | C10: ml | D10: 4200 | E10: =IFERROR(F10/D10,0) -> 1705.3653 | F10: =Configuracion!$B$18*G10 -> 7162534.4 | G10: 0.0625
A11: 5.1 | B11: PEAD PN10 Ø75 – provisión e instalación | C11: ml | D11: 3170 | E11: =IFERROR(F11/D11,0) -> 5784.2549 | F11: =Configuracion!$B$18*G11 -> 18336088 | G11: 0.16
A12: 5.2 | B12: PEAD PN10 Ø110 – provisión e instalación | C12: ml | D12: 1030 | E12: =IFERROR(F12/D12,0) -> 12238.894 | F12: =Configuracion!$B$18*G12 -> 12606061 | G12: 0.11
A13: 6 | B13: Ejecución de paquete estructural de 30 cm | C13: ml | D13: 4200 | E13: =IFERROR(F13/D13,0) -> 3274.3015 | F13: =Configuracion!$B$18*G13 -> 13752066 | G13: 0.12
A14: 7 | B14: Compactación del paquete estructural de 30 cm | C14: ml | D14: 4200 | E14: =IFERROR(F14/D14,0) -> 1227.863 | F14: =Configuracion!$B$18*G14 -> 5157024.8 | G14: 0.045
A15: 8 | B15: Ejecución y compactación de capa cota -0,60 | C15: ml | D15: 4200 | E15: =IFERROR(F15/D15,0) -> 2592.1553 | F15: =Configuracion!$B$18*G15 -> 10887052 | G15: 0.095
A16: 9 | B16: Ejecución y compactación de capa cota -0,30 | C16: ml | D16: 4200 | E16: =IFERROR(F16/D16,0) -> 2182.8676 | F16: =Configuracion!$B$18*G16 -> 9168044.1 | G16: 0.08
A17: 10.1 | B17: Conexión domiciliaria sobre red Ø75 | C17: un | D17: 165 | E17: =IFERROR(F17/D17,0) -> 48618.416 | F17: =Configuracion!$B$18*G17 -> 8022038.6 | G17: 0.07
A18: 10.2 | B18: Conexión domiciliaria sobre red Ø110 | C18: un | D18: 62 | E18: =IFERROR(F18/D18,0) -> 55451.879 | F18: =Configuracion!$B$18*G18 -> 3438016.5 | G18: 0.03
... A24: 13.3 | B24: Documentación conforme a obra y cierre | C24: gl | D24: 1 | E24: =IFERROR(F24/D24,0) -> 859504.13 | F24: =Configuracion!$B$18*G24 -> 859504.13 | G24: 0.0075
B25: TOTAL RED DE AGUA | F25: =SUM(F7:F24) -> 1.1460055e+08 | G25: =SUM(G7:G24) -> 1
A27: Control | B27: Resultado | C27: Estado
A28: Saldo certificable Agua s/IVA | B28: =Configuracion!B18 -> 1.1460055e+08 | C28: =IF(ABS(F25-B28)<1,"OK","REVISAR") -> OK
A29: Suma incidencias | B29: =SUM(G7:G24) -> 1 | C29: =IF(ABS(B29-1)<0.000001,"OK","REVISAR") -> OK

Sheet Medicion
A1: MEDICIÓN DE AVANCE – CARGA POR TRAMO Y ACTIVIDAD
A3: Cargar una fila por actividad medida. En la columna Ítem seleccionar el código del desplegable (por ejemplo 2, 5.1 o 10.2). La DESCRIPCIÓN, UNIDAD y P.U. se completan automáticamente. Para ítems globales 13.1 a 13.3 cargar una fracción entre 0 y 1.
A5: Cert. N° | B5: Fecha | C5: Código tramo | D5: Nodo inicial | E5: Nodo final | F5: Calle / sector | G5: Ítem | H5: Descripción | I5: Unidad | J5: Diámetro / tipo | K5: Cantidad medida | L5: P.U. s/IVA | M5: Importe s/IVA | N5: Estado OSSE | O5: Acta / inspección | P5: Observaciones | Q5: Estado Cert. | R5: Control histórico
A6: 1 | B6: 46262 | C6: =+CONCATENATE(D6,"-",E6) -> N30-N29 | D6: N30 | E6: N29 | F6: Pasaje 8 | G6: 1 | H6: =IF(G6="","",IFERROR(VLOOKUP(G6&"",'Presupuesto Base'!$A$7:$G$24,2,FALSE),"Ítem no encontrado")) -> Replanteo y marcación de traza | I6: =IF(G6="","",IFERROR(VLOOKUP(G6&"",'Presupuesto Base'!$A$7:$G$24,3,FALSE),"")) -> ml | K6: 106 | L6: =IF(G6="",0,IFERROR(VLOOKUP(G6&"",'Presupuesto Base'!$A$7:$G$24,5,FALSE),0)) -> 204.64384 | M6: =IFERROR(K6*L6,0) -> 21692.247 | Q6: =IFERROR(VLOOKUP(A6,'Historial Certificados'!$A$6:$E$29,5,FALSE),"") -> 0 | R6: =IF(A6="","",IF(Q6="CERRADO","CERTIFICADO CERRADO - NO MODIFICAR","ABIERTO")) -> ABIERTO
A7: 1 | B7: 46262 | C7: =+CONCATENATE(D7,"-",E7) -> N30-N25 | D7: N30 | E7: N25 | F7: Pasaje 3 | G7: 1 | H7: =IF(G7="","",IFERROR(VLOOKUP(G7&"",'Presupuesto Base'!$A$7:$G$24,2,FALSE),"Ítem no encontrado")) -> Replanteo y marcación de traza | I7: =IF(G7="","",IFERROR(VLOOKUP(G7&"",'Presupuesto Base'!$A$7:$G$24,3,FALSE),"")) -> ml | K7: 76 | L7: =IF(G7="",0,IFERROR(VLOOKUP(G7&"",'Presupuesto Base'!$A$7:$G$24,5,FALSE),0)) -> 204.64384 | M7: =IFERROR(K7*L7,0) -> 15552.932 | Q7: =IFERROR(VLOOKUP(A7,'Historial Certificados'!$A$6:$E$29,5,FALSE),"") -> 0 | R7: =IF(A7="","",IF(Q7="CERRADO","CERTIFICADO CERRADO - NO MODIFICAR","ABIERTO")) -> ABIERTO
A8: 1 | B8: 46262 | C8: =+CONCATENATE(D8,"-",E8) -> N25-N24 | D8: N25 | E8: N24 | F8: Pasaje 2 | G8: 1 | H8: =IF(G8="","",IFERROR(VLOOKUP(G8&"",'Presupuesto Base'!$A$7:$G$24,2,FALSE),"Ítem no encontrado")) -> Replanteo y marcación de traza | I8: =IF(G8="","",IFERROR(VLOOKUP(G8&"",'Presupuesto Base'!$A$7:$G$24,3,FALSE),"")) -> ml | K8: 15 | L8: =IF(G8="",0,IFERROR(VLOOKUP(G8&"",'Presupuesto Base'!$A$7:$G$24,5,FALSE),0)) -> 204.64384 | M8: =IFERROR(K8*L8,0) -> 3069.6576 | Q8: =IFERROR(VLOOKUP(A8,'Historial Certificados'!$A$6:$E$29,5,FALSE),"") -> 0 | R8: =IF(A8="","",IF(Q8="CERRADO","CERTIFICADO CERRADO - NO MODIFICAR","ABIERTO")) -> ABIERTO
A9: 1 | B9: 46262 | C9: =+CONCATENATE(D9,"-",E9) -> N24-N22 | D9: N24 | E9: N22 | F9: Pasaje 2 | G9: 1 | H9: =IF(G9="","",IFERROR(VLOOKUP(G9&"",'Presupuesto Base'!$A$7:$G$24,2,FALSE),"Ítem no encontrado")) -> Replanteo y marcación de traza | I9: =IF(G9="","",IFERROR(VLOOKUP(G9&"",'Presupuesto Base'!$A$7:$G$24,3,FALSE),"")) -> ml | K9: 96 | L9: =IF(G9="",0,IFERROR(VLOOKUP(G9&"",'Presupuesto Base'!$A$7:$G$24,5,FALSE),0)) -> 204.64384 | M9: =IFERROR(K9*L9,0) -> 19645.809 | Q9: =IFERROR(VLOOKUP(A9,'Historial Certificados'!$A$6:$E$29,5,FALSE),"") -> 0 | R9: =IF(A9="","",IF(Q9="CERRADO","CERTIFICADO CERRADO - NO MODIFICAR","ABIERTO")) -> ABIERTO
A10: 1 | B10: 46262 | C10: =+CONCATENATE(D10,"-",E10) -> N22-N29 | D10: N22 | E10: N29 | F10: Pasaje 4 | G10: 1 | H10: =IF(G10="","",IFERROR(VLOOKUP(G10&"",'Presupuesto Base'!$A$7:$G$24,2,FALSE),"Ítem no encontrado")) -> Replanteo y marcación de traza | I10: =IF(G10="","",IFERROR(VLOOKUP(G10&"",'Presupuesto Base'!$A$7:$G$24,3,FALSE),"")) -> ml | K10: 92 | L10: =IF(G10="",0,IFERROR(VLOOKUP(G10&"",'Presupuesto Base'!$A$7:$G$24,5,FALSE),0)) -> 204.64384 | M10: =IFERROR(K10*L10,0) -> 18827.233 | Q10: =IFERROR(VLOOKUP(A10,'Historial Certificados'!$A$6:$E$29,5,FALSE),"") -> 0 | R10: =IF(A10="","",IF(Q10="CERRADO","CERTIFICADO CERRADO - NO MODIFICAR","ABIERTO")) -> ABIERTO
A11: 1 | B11: 46262 | C11: =+CONCATENATE(D11,"-",E11) -> N22-N21 | D11: N22 | E11: N21 | F11: Pasaje 2 | G11: 1 | H11: =IF(G11="","",IFERROR(VLOOKUP(G11&"",'Presupuesto Base'!$A$7:$G$24,2,FALSE),"Ítem no encontrado")) -> Replanteo y marcación de traza | I11: =IF(G11="","",IFERROR(VLOOKUP(G11&"",'Presupuesto Base'!$A$7:$G$24,3,FALSE),"")) -> ml | K11: 97 | L11: =IF(G11="",0,IFERROR(VLOOKUP(G11&"",'Presupuesto Base'!$A$7:$G$24,5,FALSE),0)) -> 204.64384 | M11: =IFERROR(K11*L11,0) -> 19850.453 | Q11: =IFERROR(VLOOKUP(A11,'Historial Certificados'!$A$6:$E$29,5,FALSE),"") -> 0 | R11: =IF(A11="","",IF(Q11="CERRADO","CERTIFICADO CERRADO - NO MODIFICAR","ABIERTO")) -> ABIERTO
A12: 1 | B12: 46262 | C12: =+CONCATENATE(D12,"-",E12) -> N21-N20 | D12: N21 | E12: N20 | F12: Pasaje 2 | G12: 1 | H12: =IF(G12="","",IFERROR(VLOOKUP(G12&"",'Presupuesto Base'!$A$7:$G$24,2,FALSE),"Ítem no encontrado")) -> Replanteo y marcación de traza | I12: =IF(G12="","",IFERROR(VLOOKUP(G12&"",'Presupuesto Base'!$A$7:$G$24,3,FALSE),"")) -> ml | K12: 2 | L12: =IF(G12="",0,IFERROR(VLOOKUP(G12&"",'Presupuesto Base'!$A$7:$G$24,5,FALSE),0)) -> 204.64384 | M12: =IFERROR(K12*L12,0) -> 409.28768 | Q12: =IFERROR(VLOOKUP(A12,'Historial Certificados'!$A$6:$E$29,5,FALSE),"") -> 0 | R12: =IF(A12="","",IF(Q12="CERRADO","CERTIFICADO CERRADO - NO MODIFICAR","ABIERTO")) -> ABIERTO
A13: 1 | B13: 46262 | C13: =+CONCATENATE(D13,"-",E13) -> N20-N19 | D13: N20 | E13: N19 | F13: Pasaje 2 | G13: 1 | H13: =IF(G13="","",IFERROR(VLOOKUP(G13&"",'Presupuesto Base'!$A$7:$G$24,2,FALSE),"Ítem no encontrado")) -> Replanteo y marcación de traza | I13: =IF(G13="","",IFERROR(VLOOKUP(G13&"",'Presupuesto Base'!$A$7:$G$24,3,FALSE),"")) -> ml | K13: 77 | L13: =IF(G13="",0,IFERROR(VLOOKUP(G13&"",'Presupuesto Base'!$A$7:$G$24,5,FALSE),0)) -> 204.64384 | M13: =IFERROR(K13*L13,0) -> 15757.576 | Q13: =IFERROR(VLOOKUP(A13,'Historial Certificados'!$A$6:$E$29,5,FALSE),"") -> 0 | R13: =IF(A13="","",IF(Q13="CERRADO","CERTIFICADO CERRADO - NO MODIFICAR","ABIERTO")) -> ABIERTO
A14: 1 | B14: 46262 | C14: =+CONCATENATE(D14,"-",E14) -> N21-N28 | D14: N21 | E14: N28 | F14: Pasaje 5 | G14: 1 | H14: =IF(G14="","",IFERROR(VLOOKUP(G14&"",'Presupuesto Base'!$A$7:$G$24,2,FALSE),"Ítem no encontrado")) -> Replanteo y marcación de traza | I14: =IF(G14="","",IFERROR(VLOOKUP(G14&"",'Presupuesto Base'!$A$7:$G$24,3,FALSE),"")) -> ml | K14: 102 | L14: =IF(G14="",0,IFERROR(VLOOKUP(G14&"",'Presupuesto Base'!$A$7:$G$24,5,FALSE),0)) -> 204.64384 | M14: =IFERROR(K14*L14,0) -> 20873.672 | Q14: =IFERROR(VLOOKUP(A14,'Historial Certificados'!$A$6:$E$29,5,FALSE),"") -> 0 | R14: =IF(A14="","",IF(Q14="CERRADO","CERTIFICADO CERRADO - NO MODIFICAR","ABIERTO")) -> ABIERTO
A15: 1 | B15: 46262 | C15: =+CONCATENATE(D15,"-",E15) -> N29-N28 | D15: N29 | E15: N28 | F15: Pasaje 8 | G15: 1 | H15: =IF(G15="","",IFERROR(VLOOKUP(G15&"",'Presupuesto Base'!$A$7:$G$24,2,FALSE),"Ítem no encontrado")) -> Replanteo y marcación de traza | I15: =IF(G15="","",IFERROR(VLOOKUP(G15&"",'Presupuesto Base'!$A$7:$G$24,3,FALSE),"")) -> ml | K15: 100 | L15: =IF(G15="",0,IFERROR(VLOOKUP(G15&"",'Presupuesto Base'!$A$7:$G$24,5,FALSE),0)) -> 204.64384 | M15: =IFERROR(K15*L15,0) -> 20464.384
A16: 1 | B16: 46262 | C16: =+CONCATENATE(D16,"-",E16) -> N28-N27 | D16: N28 | E16: N27 | F16: Pasaje 8 | G16: 1 | H16: =IF(G16="","",IFERROR(VLOOKUP(G16&"",'Presupuesto Base'!$A$7:$G$24,2,FALSE),"Ítem no encontrado")) -> Replanteo y marcación de traza | I16: =IF(G16="","",IFERROR(VLOOKUP(G16&"",'Presupuesto Base'!$A$7:$G$24,3,FALSE),"")) -> ml | K16: 82 | L16: =IF(G16="",0,IFERROR(VLOOKUP(G16&"",'Presupuesto Base'!$A$7:$G$24,5,FALSE),0)) -> 204.64384 | M16: =IFERROR(K16*L16,0) -> 16780.795 | Q16: =IFERROR(VLOOKUP(A16,'Historial Certificados'!$A$6:$E$29,5,FALSE),"") -> 0 | R16: =IF(A16="","",IF(Q16="CERRADO","CERTIFICADO CERRADO - NO MODIFICAR","ABIERTO")) -> ABIERTO
A17: 1 | B17: 46262 | C17: =+CONCATENATE(D17,"-",E17) -> N30-N29 | D17: N30 | E17: N29 | F17: Pasaje 8 | G17: 2 | H17: =IF(G17="","",IFERROR(VLOOKUP(G17&"",'Presupuesto Base'!$A$7:$G$24,2,FALSE),"Ítem no encontrado")) -> Excavación de zanja | I17: =IF(G17="","",IFERROR(VLOOKUP(G17&"",'Presupuesto Base'!$A$7:$G$24,3,FALSE),"")) -> ml | K17: 106 | L17: =IF(G17="",0,IFERROR(VLOOKUP(G17&"",'Presupuesto Base'!$A$7:$G$24,5,FALSE),0)) -> 3683.5891 | M17: =IFERROR(K17*L17,0) -> 390460.45 | Q17: =IFERROR(VLOOKUP(A17,'Historial Certificados'!$A$6:$E$29,5,FALSE),"") -> 0 | R17: =IF(A17="","",IF(Q17="CERRADO","CERTIFICADO CERRADO - NO MODIFICAR","ABIERTO")) -> ABIERTO
A18: 1 | B18: 46262 | C18: =+CONCATENATE(D18,"-",E18) -> N30-N25 | D18: N30 | E18: N25 | F18: Pasaje 3 | G18: 2 | H18: =IF(G18="","",IFERROR(VLOOKUP(G18&"",'Presupuesto Base'!$A$7:$G$24,2,FALSE),"Ítem no encontrado")) -> Excavación de zanja | I18: =IF(G18="","",IFERROR(VLOOKUP(G18&"",'Presupuesto Base'!$A$7:$G$24,3,FALSE),"")) -> ml | K18: 76 | L18: =IF(G18="",0,IFERROR(VLOOKUP(G18&"",'Presupuesto Base'!$A$7:$G$24,5,FALSE),0)) -> 3683.5891 | M18: =IFERROR(K18*L18,0) -> 279952.77 | Q18: =IFERROR(VLOOKUP(A18,'Historial Certificados'!$A$6:$E$29,5,FALSE),"") -> 0 | R18: =IF(A18="","",IF(Q18="CERRADO","CERTIFICADO CERRADO - NO MODIFICAR","ABIERTO")) -> ABIERTO
A19: 1 | B19: 46262 | C19: =+CONCATENATE(D19,"-",E19) -> N25-N24 | D19: N25 | E19: N24 | F19: Pasaje 2 | G19: 2 | H19: =IF(G19="","",IFERROR(VLOOKUP(G19&"",'Presupuesto Base'!$A$7:$G$24,2,FALSE),"Ítem no encontrado")) -> Excavación de zanja | I19: =IF(G19="","",IFERROR(VLOOKUP(G19&"",'Presupuesto Base'!$A$7:$G$24,3,FALSE),"")) -> ml | K19: 15 | L19: =IF(G19="",0,IFERROR(VLOOKUP(G19&"",'Presupuesto Base'!$A$7:$G$24,5,FALSE),0)) -> 3683.5891 | M19: =IFERROR(K19*L19,0) -> 55253.837 | Q19: =IFERROR(VLOOKUP(A19,'Historial Certificados'!$A$6:$E$29,5,FALSE),"") -> 0 | R19: =IF(A19="","",IF(Q19="CERRADO","CERTIFICADO CERRADO - NO MODIFICAR","ABIERTO")) -> ABIERTO
A20: 1 | B20: 46262 | C20: =+CONCATENATE(D20,"-",E20) -> N24-N22 | D20: N24 | E20: N22 | F20: Pasaje 2 | G20: 2 | H20: =IF(G20="","",IFERROR(VLOOKUP(G20&"",'Presupuesto Base'!$A$7:$G$24,2,FALSE),"Ítem no encontrado")) -> Excavación de zanja | I20: =IF(G20="","",IFERROR(VLOOKUP(G20&"",'Presupuesto Base'!$A$7:$G$24,3,FALSE),"")) -> ml | K20: 96 | L20: =IF(G20="",0,IFERROR(VLOOKUP(G20&"",'Presupuesto Base'!$A$7:$G$24,5,FALSE),0)) -> 3683.5891 | M20: =IFERROR(K20*L20,0) -> 353624.56 | Q20: =IFERROR(VLOOKUP(A20,'Historial Certificados'!$A$6:$E$29,5,FALSE),"") -> 0 | R20: =IF(A20="","",IF(Q20="CERRADO","CERTIFICADO CERRADO - NO MODIFICAR","ABIERTO")) -> ABIERTO
A21: 1 | B21: 46262 | C21: =+CONCATENATE(D21,"-",E21) -> N22-N29 | D21: N22 | E21: N29 | F21: Pasaje 4 | G21: 2 | H21: =IF(G21="","",IFERROR(VLOOKUP(G21&"",'Presupuesto Base'!$A$7:$G$24,2,FALSE),"Ítem no encontrado")) -> Excavación de zanja | I21: =IF(G21="","",IFERROR(VLOOKUP(G21&"",'Presupuesto Base'!$A$7:$G$24,3,FALSE),"")) -> ml | K21: 92 | L21: =IF(G21="",0,IFERROR(VLOOKUP(G21&"",'Presupuesto Base'!$A$7:$G$24,5,FALSE),0)) -> 3683.5891 | M21: =IFERROR(K21*L21,0) -> 338890.2 | Q21: =IFERROR(VLOOKUP(A21,'Historial Certificados'!$A$6:$E$29,5,FALSE),"") -> 0 | R21: =IF(A21="","",IF(Q21="CERRADO","CERTIFICADO CERRADO - NO MODIFICAR","ABIERTO")) -> ABIERTO
A22: 1 | B22: 46262 | C22: =+CONCATENATE(D22,"-",E22) -> N22-N21 | D22: N22 | E22: N21 | F22: Pasaje 2 | G22: 2 | H22: =IF(G22="","",IFERROR(VLOOKUP(G22&"",'Presupuesto Base'!$A$7:$G$24,2,FALSE),"Ítem no encontrado")) -> Excavación de zanja | I22: =IF(G22="","",IFERROR(VLOOKUP(G22&"",'Presupuesto Base'!$A$7:$G$24,3,FALSE),"")) -> ml | K22: 97 | L22: =IF(G22="",0,IFERROR(VLOOKUP(G22&"",'Presupuesto Base'!$A$7:$G$24,5,FALSE),0)) -> 3683.5891 | M22: =IFERROR(K22*L22,0) -> 357308.15 | Q22: =IFERROR(VLOOKUP(A22,'Historial Certificados'!$A$6:$E$29,5,FALSE),"") -> 0 | R22: =IF(A22="","",IF(Q22="CERRADO","CERTIFICADO CERRADO - NO MODIFICAR","ABIERTO")) -> ABIERTO
A23: 1 | B23: 46262 | C23: =+CONCATENATE(D23,"-",E23) -> N21-N20 | D23: N21 | E23: N20 | F23: Pasaje 2 | G23: 2 | H23: =IF(G23="","",IFERROR(VLOOKUP(G23&"",'Presupuesto Base'!$A$7:$G$24,2,FALSE),"Ítem no encontrado")) -> Excavación de zanja | I23: =IF(G23="","",IFERROR(VLOOKUP(G23&"",'Presupuesto Base'!$A$7:$G$24,3,FALSE),"")) -> ml | K23: 2 | L23: =IF(G23="",0,IFERROR(VLOOKUP(G23&"",'Presupuesto Base'!$A$7:$G$24,5,FALSE),0)) -> 3683.5891 | M23: =IFERROR(K23*L23,0) -> 7367.1783 | Q23: =IFERROR(VLOOKUP(A23,'Historial Certificados'!$A$6:$E$29,5,FALSE),"") -> 0 | R23: =IF(A23="","",IF(Q23="CERRADO","CERTIFICADO CERRADO - NO MODIFICAR","ABIERTO")) -> ABIERTO
A24: 1 | B24: 46262 | C24: =+CONCATENATE(D24,"-",E24) -> N20-N19 | D24: N20 | E24: N19 | F24: Pasaje 2 | G24: 2 | H24: =IF(G24="","",IFERROR(VLOOKUP(G24&"",'Presupuesto Base'!$A$7:$G$24,2,FALSE),"Ítem no encontrado")) -> Excavación de zanja | I24: =IF(G24="","",IFERROR(VLOOKUP(G24&"",'Presupuesto Base'!$A$7:$G$24,3,FALSE),"")) -> ml | K24: 77 | L24: =IF(G24="",0,IFERROR(VLOOKUP(G24&"",'Presupuesto Base'!$A$7:$G$24,5,FALSE),0)) -> 3683.5891 | M24: =IFERROR(K24*L24,0) -> 283636.36 | Q24: =IFERROR(VLOOKUP(A24,'Historial Certificados'!$A$6:$E$29,5,FALSE),"") -> 0 | R24: =IF(A24="","",IF(Q24="CERRADO","CERTIFICADO CERRADO - NO MODIFICAR","ABIERTO")) -> ABIERTO
A25: 1 | B25: 46262 | C25: =+CONCATENATE(D25,"-",E25) -> N21-N28 | D25: N21 | E25: N28 | F25: Pasaje 5 | G25: 2 | H25: =IF(G25="","",IFERROR(VLOOKUP(G25&"",'Presupuesto Base'!$A$7:$G$24,2,FALSE),"Ítem no encontrado")) -> Excavación de zanja | I25: =IF(G25="","",IFERROR(VLOOKUP(G25&"",'Presupuesto Base'!$A$7:$G$24,3,FALSE),"")) -> ml | K25: 102 | L25: =IF(G25="",0,IFERROR(VLOOKUP(G25&"",'Presupuesto Base'!$A$7:$G$24,5,FALSE),0)) -> 3683.5891 | M25: =IFERROR(K25*L25,0) -> 375726.09 | Q25: =IFERROR(VLOOKUP(A25,'Historial Certificados'!$A$6:$E$29,5,FALSE),"") -> 0 | R25: =IF(A25="","",IF(Q25="CERRADO","CERTIFICADO CERRADO - NO MODIFICAR","ABIERTO")) -> ABIERTO
A26: 1 | B26: 46262 | C26: =+CONCATENATE(D26,"-",E26) -> N29-N28 | D26: N29 | E26: N28 | F26: Pasaje 8 | G26: 2 | H26: =IF(G26="","",IFERROR(VLOOKUP(G26&"",'Presupuesto Base'!$A$7:$G$24,2,FALSE),"Ítem no encontrado")) -> Excavación de zanja | I26: =IF(G26="","",IFERROR(VLOOKUP(G26&"",'Presupuesto Base'!$A$7:$G$24,3,FALSE),"")) -> ml | K26: 100 | L26: =IF(G26="",0,IFERROR(VLOOKUP(G26&"",'Presupuesto Base'!$A$7:$G$24,5,FALSE),0)) -> 3683.5891 | M26: =IFERROR(K26*L26,0) -> 368358.91
A27: 1 | B27: 46262 | C27: =+CONCATENATE(D27,"-",E27) -> N28-N27 | D27: N28 | E27: N27 | F27: Pasaje 8 | G27: 2 | H27: =IF(G27="","",IFERROR(VLOOKUP(G27&"",'Presupuesto Base'!$A$7:$G$24,2,FALSE),"Ítem no encontrado")) -> Excavación de zanja | I27: =IF(G27="","",IFERROR(VLOOKUP(G27&"",'Presupuesto Base'!$A$7:$G$24,3,FALSE),"")) -> ml | K27: 82 | L27: =IF(G27="",0,IFERROR(VLOOKUP(G27&"",'Presupuesto Base'!$A$7:$G$24,5,FALSE),0)) -> 3683.5891 | M27: =IFERROR(K27*L27,0) -> 302054.31 | Q27: =IFERROR(VLOOKUP(A27,'Historial Certificados'!$A$6:$E$29,5,FALSE),"") -> 0 | R27: =IF(A27="","",IF(Q27="CERRADO","CERTIFICADO CERRADO - NO MODIFICAR","ABIERTO")) -> ABIERTO
A28: 1 | B28: 46262 | C28: =+CONCATENATE(D28,"-",E28) -> N30-N29 | D28: N30 | E28: N29 | F28: Pasaje 8 | G28: 3 | H28: =IF(G28="","",IFERROR(VLOOKUP(G28&"",'Presupuesto Base'!$A$7:$G$24,2,FALSE),"Ítem no encontrado")) -> Nivelación y conformación del fondo de zanja | I28: =IF(G28="","",IFERROR(VLOOKUP(G28&"",'Presupuesto Base'!$A$7:$G$24,3,FALSE),"")) -> ml | K28: 106 | L28: =IF(G28="",0,IFERROR(VLOOKUP(G28&"",'Presupuesto Base'!$A$7:$G$24,5,FALSE),0)) -> 477.5023 | M28: =IFERROR(K28*L28,0) -> 50615.243 | Q28: =IFERROR(VLOOKUP(A28,'Historial Certificados'!$A$6:$E$29,5,FALSE),"") -> 0 | R28: =IF(A28="","",IF(Q28="CERRADO","CERTIFICADO CERRADO - NO MODIFICAR","ABIERTO")) -> ABIERTO
A29: 1 | B29: 46262 | C29: =+CONCATENATE(D29,"-",E29) -> N30-N25 | D29: N30 | E29: N25 | F29: Pasaje 3 | G29: 3 | H29: =IF(G29="","",IFERROR(VLOOKUP(G29&"",'Presupuesto Base'!$A$7:$G$24,2,FALSE),"Ítem no encontrado")) -> Nivelación y conformación del fondo de zanja | I29: =IF(G29="","",IFERROR(VLOOKUP(G29&"",'Presupuesto Base'!$A$7:$G$24,3,FALSE),"")) -> ml | K29: 76 | L29: =IF(G29="",0,IFERROR(VLOOKUP(G29&"",'Presupuesto Base'!$A$7:$G$24,5,FALSE),0)) -> 477.5023 | M29: =IFERROR(K29*L29,0) -> 36290.174 | Q29: =IFERROR(VLOOKUP(A29,'Historial Certificados'!$A$6:$E$29,5,FALSE),"") -> 0 | R29: =IF(A29="","",IF(Q29="CERRADO","CERTIFICADO CERRADO - NO MODIFICAR","ABIERTO")) -> ABIERTO
A30: 1 | B30: 46262 | C30: =+CONCATENATE(D30,"-",E30) -> N25-N24 | D30: N25 | E30: N24 | F30: Pasaje 2 | G30: 3 | H30: =IF(G30="","",IFERROR(VLOOKUP(G30&"",'Presupuesto Base'!$A$7:$G$24,2,FALSE),"Ítem no encontrado")) -> Nivelación y conformación del fondo de zanja | I30: =IF(G30="","",IFERROR(VLOOKUP(G30&"",'Presupuesto Base'!$A$7:$G$24,3,FALSE),"")) -> ml | K30: 15 | L30: =IF(G30="",0,IFERROR(VLOOKUP(G30&"",'Presupuesto Base'!$A$7:$G$24,5,FALSE),0)) -> 477.5023 | M30: =IFERROR(K30*L30,0) -> 7162.5344 | Q30: =IFERROR(VLOOKUP(A30,'Historial Certificados'!$A$6:$E$29,5,FALSE),"") -> 0 | R30: =IF(A30="","",IF(Q30="CERRADO","CERTIFICADO CERRADO - NO MODIFICAR","ABIERTO")) -> ABIERTO
A31: 1 | B31: 46262 | C31: =+CONCATENATE(D31,"-",E31) -> N24-N22 | D31: N24 | E31: N22 | F31: Pasaje 2 | G31: 3 | H31: =IF(G31="","",IFERROR(VLOOKUP(G31&"",'Presupuesto Base'!$A$7:$G$24,2,FALSE),"Ítem no encontrado")) -> Nivelación y conformación del fondo de zanja | I31: =IF(G31="","",IFERROR(VLOOKUP(G31&"",'Presupuesto Base'!$A$7:$G$24,3,FALSE),"")) -> ml | K31: 96 | L31: =IF(G31="",0,IFERROR(VLOOKUP(G31&"",'Presupuesto Base'!$A$7:$G$24,5,FALSE),0)) -> 477.5023 | M31: =IFERROR(K31*L31,0) -> 45840.22 | Q31: =IFERROR(VLOOKUP(A31,'Historial Certificados'!$A$6:$E$29,5,FALSE),"") -> 0 | R31: =IF(A31="","",IF(Q31="CERRADO","CERTIFICADO CERRADO - NO MODIFICAR","ABIERTO")) -> ABIERTO
A32: 1 | B32: 46262 | C32: =+CONCATENATE(D32,"-",E32) -> N22-N29 | D32: N22 | E32: N29 | F32: Pasaje 4 | G32: 3 | H32: =IF(G32="","",IFERROR(VLOOKUP(G32&"",'Presupuesto Base'!$A$7:$G$24,2,FALSE),"Ítem no encontrado")) -> Nivelación y conformación del fondo de zanja | I32: =IF(G32="","",IFERROR(VLOOKUP(G32&"",'Presupuesto Base'!$A$7:$G$24,3,FALSE),"")) -> ml | K32: 92 | L32: =IF(G32="",0,IFERROR(VLOOKUP(G32&"",'Presupuesto Base'!$A$7:$G$24,5,FALSE),0)) -> 477.5023 | M32: =IFERROR(K32*L32,0) -> 43930.211 | Q32: =IFERROR(VLOOKUP(A32,'Historial Certificados'!$A$6:$E$29,5,FALSE),"") -> 0 | R32: =IF(A32="","",IF(Q32="CERRADO","CERTIFICADO CERRADO - NO MODIFICAR","ABIERTO")) -> ABIERTO
A33: 1 | B33: 46262 | C33: =+CONCATENATE(D33,"-",E33) -> N22-N21 | D33: N22 | E33: N21 | F33: Pasaje 2 | G33: 3 | H33: =IF(G33="","",IFERROR(VLOOKUP(G33&"",'Presupuesto Base'!$A$7:$G$24,2,FALSE),"Ítem no encontrado")) -> Nivelación y conformación del fondo de zanja | I33: =IF(G33="","",IFERROR(VLOOKUP(G33&"",'Presupuesto Base'!$A$7:$G$24,3,FALSE),"")) -> ml | K33: 97 | L33: =IF(G33="",0,IFERROR(VLOOKUP(G33&"",'Presupuesto Base'!$A$7:$G$24,5,FALSE),0)) -> 477.5023 | M33: =IFERROR(K33*L33,0) -> 46317.723 | Q33: =IFERROR(VLOOKUP(A33,'Historial Certificados'!$A$6:$E$29,5,FALSE),"") -> 0 | R33: =IF(A33="","",IF(Q33="CERRADO","CERTIFICADO CERRADO - NO MODIFICAR","ABIERTO")) -> ABIERTO
A34: 1 | B34: 46262 | C34: =+CONCATENATE(D34,"-",E34) -> N21-N20 | D34: N21 | E34: N20 | F34: Pasaje 2 | G34: 3 | H34: =IF(G34="","",IFERROR(VLOOKUP(G34&"",'Presupuesto Base'!$A$7:$G$24,2,FALSE),"Ítem no encontrado")) -> Nivelación y conformación del fondo de zanja | I34: =IF(G34="","",IFERROR(VLOOKUP(G34&"",'Presupuesto Base'!$A$7:$G$24,3,FALSE),"")) -> ml | K34: 2 | L34: =IF(G34="",0,IFERROR(VLOOKUP(G34&"",'Presupuesto Base'!$A$7:$G$24,5,FALSE),0)) -> 477.5023 | M34: =IFERROR(K34*L34,0) -> 955.00459 | Q34: =IFERROR(VLOOKUP(A34,'Historial Certificados'!$A$6:$E$29,5,FALSE),"") -> 0 | R34: =IF(A34="","",IF(Q34="CERRADO","CERTIFICADO CERRADO - NO MODIFICAR","ABIERTO")) -> ABIERTO
A35: 1 | B35: 46262 | C35: =+CONCATENATE(D35,"-",E35) -> N20-N19 | D35: N20 | E35: N19 | F35: Pasaje 2 | G35: 3 | H35: =IF(G35="","",IFERROR(VLOOKUP(G35&"",'Presupuesto Base'!$A$7:$G$24,2,FALSE),"Ítem no encontrado")) -> Nivelación y conformación del fondo de zanja | I35: =IF(G35="","",IFERROR(VLOOKUP(G35&"",'Presupuesto Base'!$A$7:$G$24,3,FALSE),"")) -> ml | K35: 77 | L35: =IF(G35="",0,IFERROR(VLOOKUP(G35&"",'Presupuesto Base'!$A$7:$G$24,5,FALSE),0)) -> 477.5023 | M35: =IFERROR(K35*L35,0) -> 36767.677 | Q35: =IFERROR(VLOOKUP(A35,'Historial Certificados'!$A$6:$E$29,5,FALSE),"") -> 0 | R35: =IF(A35="","",IF(Q35="CERRADO","CERTIFICADO CERRADO - NO MODIFICAR","ABIERTO")) -> ABIERTO
A36: 1 | B36: 46262 | C36: =+CONCATENATE(D36,"-",E36) -> N21-N28 | D36: N21 | E36: N28 | F36: Pasaje 5 | G36: 3 | H36: =IF(G36="","",IFERROR(VLOOKUP(G36&"",'Presupuesto Base'!$A$7:$G$24,2,FALSE),"Ítem no encontrado")) -> Nivelación y conformación del fondo de zanja | I36: =IF(G36="","",IFERROR(VLOOKUP(G36&"",'Presupuesto Base'!$A$7:$G$24,3,FALSE),"")) -> ml | K36: 102 | L36: =IF(G36="",0,IFERROR(VLOOKUP(G36&"",'Presupuesto Base'!$A$7:$G$24,5,FALSE),0)) -> 477.5023 | M36: =IFERROR(K36*L36,0) -> 48705.234 | Q36: =IFERROR(VLOOKUP(A36,'Historial Certificados'!$A$6:$E$29,5,FALSE),"") -> 0 | R36: =IF(A36="","",IF(Q36="CERRADO","CERTIFICADO CERRADO - NO MODIFICAR","ABIERTO")) -> ABIERTO
A37: 1 | B37: 46262 | C37: =+CONCATENATE(D37,"-",E37) -> N29-N28 | D37: N29 | E37: N28 | F37: Pasaje 8 | G37: 3 | H37: =IF(G37="","",IFERROR(VLOOKUP(G37&"",'Presupuesto Base'!$A$7:$G$24,2,FALSE),"Ítem no encontrado")) -> Nivelación y conformación del fondo de zanja | I37: =IF(G37="","",IFERROR(VLOOKUP(G37&"",'Presupuesto Base'!$A$7:$G$24,3,FALSE),"")) -> ml | K37: 100 | L37: =IF(G37="",0,IFERROR(VLOOKUP(G37&"",'Presupuesto Base'!$A$7:$G$24,5,FALSE),0)) -> 477.5023 | M37: =IFERROR(K37*L37,0) -> 47750.23
A38: 1 | B38: 46262 | C38: =+CONCATENATE(D38,"-",E38) -> N28-N27 | D38: N28 | E38: N27 | F38: Pasaje 8 | G38: 3 | H38: =IF(G38="","",IFERROR(VLOOKUP(G38&"",'Presupuesto Base'!$A$7:$G$24,2,FALSE),"Ítem no encontrado")) -> Nivelación y conformación del fondo de zanja | I38: =IF(G38="","",IFERROR(VLOOKUP(G38&"",'Presupuesto Base'!$A$7:$G$24,3,FALSE),"")) -> ml | K38: 82 | L38: =IF(G38="",0,IFERROR(VLOOKUP(G38&"",'Presupuesto Base'!$A$7:$G$24,5,FALSE),0)) -> 477.5023 | M38: =IFERROR(K38*L38,0) -> 39155.188 | Q38: =IFERROR(VLOOKUP(A38,'Historial Certificados'!$A$6:$E$29,5,FALSE),"") -> 0 | R38: =IF(A38="","",IF(Q38="CERRADO","CERTIFICADO CERRADO - NO MODIFICAR","ABIERTO")) -> ABIERTO
A39: 1 | B39: 46262 | C39: =+CONCATENATE(D39,"-",E39) -> N30-N29 | D39: N30 | E39: N29 | F39: Pasaje 8 | G39: 4 | H39: =IF(G39="","",IFERROR(VLOOKUP(G39&"",'Presupuesto Base'!$A$7:$G$24,2,FALSE),"Ítem no encontrado")) -> Cama de asiento compactada | I39: =IF(G39="","",IFERROR(VLOOKUP(G39&"",'Presupuesto Base'!$A$7:$G$24,3,FALSE),"")) -> ml | K39: 106 | L39: =IF(G39="",0,IFERROR(VLOOKUP(G39&"",'Presupuesto Base'!$A$7:$G$24,5,FALSE),0)) -> 1705.3653 | M39: =IFERROR(K39*L39,0) -> 180768.73 | Q39: =IFERROR(VLOOKUP(A39,'Historial Certificados'!$A$6:$E$29,5,FALSE),"") -> 0 | R39: =IF(A39="","",IF(Q39="CERRADO","CERTIFICADO CERRADO - NO MODIFICAR","ABIERTO")) -> ABIERTO
A40: 1 | B40: 46262 | C40: =+CONCATENATE(D40,"-",E40) -> N30-N25 | D40: N30 | E40: N25 | F40: Pasaje 3 | G40: 4 | H40: =IF(G40="","",IFERROR(VLOOKUP(G40&"",'Presupuesto Base'!$A$7:$G$24,2,FALSE),"Ítem no encontrado")) -> Cama de asiento compactada | I40: =IF(G40="","",IFERROR(VLOOKUP(G40&"",'Presupuesto Base'!$A$7:$G$24,3,FALSE),"")) -> ml | K40: 76 | L40: =IF(G40="",0,IFERROR(VLOOKUP(G40&"",'Presupuesto Base'!$A$7:$G$24,5,FALSE),0)) -> 1705.3653 | M40: =IFERROR(K40*L40,0) -> 129607.77 | Q40: =IFERROR(VLOOKUP(A40,'Historial Certificados'!$A$6:$E$29,5,FALSE),"") -> 0 | R40: =IF(A40="","",IF(Q40="CERRADO","CERTIFICADO CERRADO - NO MODIFICAR","ABIERTO")) -> ABIERTO
A41: 1 | B41: 46262 | C41: =+CONCATENATE(D41,"-",E41) -> N25-N24 | D41: N25 | E41: N24 | F41: Pasaje 2 | G41: 4 | H41: =IF(G41="","",IFERROR(VLOOKUP(G41&"",'Presupuesto Base'!$A$7:$G$24,2,FALSE),"Ítem no encontrado")) -> Cama de asiento compactada | I41: =IF(G41="","",IFERROR(VLOOKUP(G41&"",'Presupuesto Base'!$A$7:$G$24,3,FALSE),"")) -> ml | K41: 15 | L41: =IF(G41="",0,IFERROR(VLOOKUP(G41&"",'Presupuesto Base'!$A$7:$G$24,5,FALSE),0)) -> 1705.3653 | M41: =IFERROR(K41*L41,0) -> 25580.48 | Q41: =IFERROR(VLOOKUP(A41,'Historial Certificados'!$A$6:$E$29,5,FALSE),"") -> 0 | R41: =IF(A41="","",IF(Q41="CERRADO","CERTIFICADO CERRADO - NO MODIFICAR","ABIERTO")) -> ABIERTO
A42: 1 | B42: 46262 | C42: =+CONCATENATE(D42,"-",E42) -> N24-N22 | D42: N24 | E42: N22 | F42: Pasaje 2 | G42: 4 | H42: =IF(G42="","",IFERROR(VLOOKUP(G42&"",'Presupuesto Base'!$A$7:$G$24,2,FALSE),"Ítem no encontrado")) -> Cama de asiento compactada | I42: =IF(G42="","",IFERROR(VLOOKUP(G42&"",'Presupuesto Base'!$A$7:$G$24,3,FALSE),"")) -> ml | K42: 96 | L42: =IF(G42="",0,IFERROR(VLOOKUP(G42&"",'Presupuesto Base'!$A$7:$G$24,5,FALSE),0)) -> 1705.3653 | M42: =IFERROR(K42*L42,0) -> 163715.07 | Q42: =IFERROR(VLOOKUP(A42,'Historial Certificados'!$A$6:$E$29,5,FALSE),"") -> 0 | R42: =IF(A42="","",IF(Q42="CERRADO","CERTIFICADO CERRADO - NO MODIFICAR","ABIERTO")) -> ABIERTO
...

Sheet Certificado
A1: CERTIFICADO DE OBRA – RED DISTRIBUIDORA DE AGUA POTABLE
A4: Certificado N° | B4: 1 | D4: Obra | E4: =Configuracion!B5 -> Red Distribuidora de Agua Potable – Loteo Roque | H4: Estado | I4: =IFERROR(VLOOKUP($B$4,'Historial Certificados'!$A$6:$O$29,5,FALSE),"") -> 0
A5: Período desde | B5: =IFERROR(VLOOKUP($B$4,'Historial Certificados'!$A$6:$O$29,2,FALSE),"") -> 0 | D5: Comitente | E5: =Configuracion!B7 -> VALDIVIESO GROUP S.R.L. | H5: Control | I5: =IFERROR(VLOOKUP($B$4,'Historial Certificados'!$A$6:$O$29,14,FALSE),"") -> OK
A6: Período hasta | B6: =IFERROR(VLOOKUP($B$4,'Historial Certificados'!$A$6:$O$29,3,FALSE),"") -> 0 | D6: Contratista | E6: =Configuracion!B8 -> ECAR SAS | H6: Registros | I6: =IFERROR(VLOOKUP($B$4,'Historial Certificados'!$A$6:$O$29,6,FALSE),0) -> 72
A7: Fecha emisión | B7: =IFERROR(VLOOKUP($B$4,'Historial Certificados'!$A$6:$O$29,4,FALSE),"") -> 0 | D7: Base económica | E7: Saldo certificable Agua s/IVA | F7: =Configuracion!B18 -> 1.1460055e+08
A9: Ítem | B9: Descripción | C9: Un. | D9: Cant. contractual | E9: P.U. s/IVA | F9: Importe contractual | G9: Cant. anterior | H9: Cant. período | I9: Cant. acumulada | J9: % avance acum. | K9: Importe anterior | L9: Importe período | M9: Importe acumulado | N9: Saldo | O9: Control
A10: ='Presupuesto Base'!A7 -> 1 | B10: ='Presupuesto Base'!B7 -> Replanteo y marcación de traza | C10: ='Presupuesto Base'!C7 -> ml | D10: ='Presupuesto Base'!D7 -> 4200 | E10: ='Presupuesto Base'!E7 -> 204.64384 | F10: ='Presupuesto Base'!F7 -> 859504.13 | G10: =SUMIFS(Medicion!$K$6:$K$511,Medicion!$G$6:$G$511,$A10,Medicion!$A$6:$A$511,"<"&$B$4) -> 0 | H10: =SUMIFS(Medicion!$K$6:$K$511,Medicion!$G$6:$G$511,$A10,Medicion!$A$6:$A$511,$B$4) -> 845 | I10: =MIN(D10,G10+H10) -> 845 | J10: =IFERROR(I10/D10,0) -> 0.20119048 | K10: =MIN(F10,G10*E10) -> 0 | L10: =MIN(F10-K10,H10*E10) -> 172924.05 | M10: =K10+L10 -> 172924.05 | N10: =MAX(0,F10-M10) -> 686580.09 | O10: =IF(OR(G10+H10>D10+0.000001,G10<0,H10<0),"REVISAR","OK") -> OK
A11: ='Presupuesto Base'!A8 -> 2 | B11: ='Presupuesto Base'!B8 -> Excavación de zanja | C11: ='Presupuesto Base'!C8 -> ml | D11: ='Presupuesto Base'!D8 -> 4200 | E11: ='Presupuesto Base'!E8 -> 3683.5891 | F11: ='Presupuesto Base'!F8 -> 15471074 | G11: =SUMIFS(Medicion!$K$6:$K$511,Medicion!$G$6:$G$511,$A11,Medicion!$A$6:$A$511,"<"&$B$4) -> 0 | H11: =SUMIFS(Medicion!$K$6:$K$511,Medicion!$G$6:$G$511,$A11,Medicion!$A$6:$A$511,$B$4) -> 845 | I11: =MIN(D11,G11+H11) -> 845 | J11: =IFERROR(I11/D11,0) -> 0.20119048 | K11: =MIN(F11,G11*E11) -> 0 | L11: =MIN(F11-K11,H11*E11) -> 3112632.8 | M11: =K11+L11 -> 3112632.8 | N11: =MAX(0,F11-M11) -> 12358442 | O11: =IF(OR(G11+H11>D11+0.000001,G11<0,H11<0),"REVISAR","OK") -> OK
A12: ='Presupuesto Base'!A9 -> 3 | B12: ='Presupuesto Base'!B9 -> Nivelación y conformación del fondo de zanja | C12: ='Presupuesto Base'!C9 -> ml | D12: ='Presupuesto Base'!D9 -> 4200 | E12: ='Presupuesto Base'!E9 -> 477.5023 | F12: ='Presupuesto Base'!F9 -> 2005509.6 | G12: =SUMIFS(Medicion!$K$6:$K$511,Medicion!$G$6:$G$511,$A12,Medicion!$A$6:$A$511,"<"&$B$4) -> 0 | H12: =SUMIFS(Medicion!$K$6:$K$511,Medicion!$G$6:$G$511,$A12,Medicion!$A$6:$A$511,$B$4) -> 845 | I12: =MIN(D12,G12+H12) -> 845 | J12: =IFERROR(I12/D12,0) -> 0.20119048 | K12: =MIN(F12,G12*E12) -> 0 | L12: =MIN(F12-K12,H12*E12) -> 403489.44 | M12: =K12+L12 -> 403489.44 | N12: =MAX(0,F12-M12) -> 1602020.2 | O12: =IF(OR(G12+H12>D12+0.000001,G12<0,H12<0),"REVISAR","OK") -> OK
A13: ='Presupuesto Base'!A10 -> 4 | B13: ='Presupuesto Base'!B10 -> Cama de asiento compactada | C13: ='Presupuesto Base'!C10 -> ml | D13: ='Presupuesto Base'!D10 -> 4200 | E13: ='Presupuesto Base'!E10 -> 1705.3653 | F13: ='Presupuesto Base'!F10 -> 7162534.4 | G13: =SUMIFS(Medicion!$K$6:$K$511,Medicion!$G$6:$G$511,$A13,Medicion!$A$6:$A$511,"<"&$B$4) -> 0 | H13: =SUMIFS(Medicion!$K$6:$K$511,Medicion!$G$6:$G$511,$A13,Medicion!$A$6:$A$511,$B$4) -> 845 | I13: =MIN(D13,G13+H13) -> 845 | J13: =IFERROR(I13/D13,0) -> 0.20119048 | K13: =MIN(F13,G13*E13) -> 0 | L13: =MIN(F13-K13,H13*E13) -> 1441033.7 | M13: =K13+L13 -> 1441033.7 | N13: =MAX(0,F13-M13) -> 5721500.7 | O13: =IF(OR(G13+H13>D13+0.000001,G13<0,H13<0),"REVISAR","OK") -> OK
A14: ='Presupuesto Base'!A11 -> 5.1 | B14: ='Presupuesto Base'!B11 -> PEAD PN10 Ø75 – provisión e instalación | C14: ='Presupuesto Base'!C11 -> ml | D14: ='Presupuesto Base'!D11 -> 3170 | E14: ='Presupuesto Base'!E11 -> 5784.2549 | F14: ='Presupuesto Base'!F11 -> 18336088 | G14: =SUMIFS(Medicion!$K$6:$K$511,Medicion!$G$6:$G$511,$A14,Medicion!$A$6:$A$511,"<"&$B$4) -> 0 | H14: =SUMIFS(Medicion!$K$6:$K$511,Medicion!$G$6:$G$511,$A14,Medicion!$A$6:$A$511,$B$4) -> 558 | I14: =MIN(D14,G14+H14) -> 558 | J14: =IFERROR(I14/D14,0) -> 0.17602524 | K14: =MIN(F14,G14*E14) -> 0 | L14: =MIN(F14-K14,H14*E14) -> 3227614.3 | M14: =K14+L14 -> 3227614.3 | N14: =MAX(0,F14-M14) -> 15108474 | O14: =IF(OR(G14+H14>D14+0.000001,G14<0,H14<0),"REVISAR","OK") -> OK
A15: ='Presupuesto Base'!A12 -> 5.2 | B15: ='Presupuesto Base'!B12 -> PEAD PN10 Ø110 – provisión e instalación | C15: ='Presupuesto Base'!C12 -> ml | D15: ='Presupuesto Base'!D12 -> 1030 | E15: ='Presupuesto Base'!E12 -> 12238.894 | F15: ='Presupuesto Base'!F12 -> 12606061 | G15: =SUMIFS(Medicion!$K$6:$K$511,Medicion!$G$6:$G$511,$A15,Medicion!$A$6:$A$511,"<"&$B$4) -> 0 | H15: =SUMIFS(Medicion!$K$6:$K$511,Medicion!$G$6:$G$511,$A15,Medicion!$A$6:$A$511,$B$4) -> 287 | I15: =MIN(D15,G15+H15) -> 287 | J15: =IFERROR(I15/D15,0) -> 0.27864078 | K15: =MIN(F15,G15*E15) -> 0 | L15: =MIN(F15-K15,H15*E15) -> 3512562.5 | M15: =K15+L15 -> 3512562.5 | N15: =MAX(0,F15-M15) -> 9093498.1 | O15: =IF(OR(G15+H15>D15+0.000001,G15<0,H15<0),"REVISAR","OK") -> OK
A16: ='Presupuesto Base'!A13 -> 6 | B16: ='Presupuesto Base'!B13 -> Ejecución de paquete estructural de 30 cm | C16: ='Presupuesto Base'!C13 -> ml | D16: ='Presupuesto Base'!D13 -> 4200 | E16: ='Presupuesto Base'!E13 -> 3274.3015 | F16: ='Presupuesto Base'!F13 -> 13752066 | G16: =SUMIFS(Medicion!$K$6:$K$511,Medicion!$G$6:$G$511,$A16,Medicion!$A$6:$A$511,"<"&$B$4) -> 0 | H16: =SUMIFS(Medicion!$K$6:$K$511,Medicion!$G$6:$G$511,$A16,Medicion!$A$6:$A$511,$B$4) -> 763 | I16: =MIN(D16,G16+H16) -> 763 | J16: =IFERROR(I16/D16,0) -> 0.18166667 | K16: =MIN(F16,G16*E16) -> 0 | L16: =MIN(F16-K16,H16*E16) -> 2498292 | M16: =K16+L16 -> 2498292 | N16: =MAX(0,F16-M16) -> 11253774 | O16: =IF(OR(G16+H16>D16+0.000001,G16<0,H16<0),"REVISAR","OK") -> OK
A17: ='Presupuesto Base'!A14 -> 7 | B17: ='Presupuesto Base'!B14 -> Compactación del paquete estructural de 30 cm | C17: ='Presupuesto Base'!C14 -> ml | D17: ='Presupuesto Base'!D14 -> 4200 | E17: ='Presupuesto Base'!E14 -> 1227.863 | F17: ='Presupuesto Base'!F14 -> 5157024.8 | G17: =SUMIFS(Medicion!$K$6:$K$511,Medicion!$G$6:$G$511,$A17,Medicion!$A$6:$A$511,"<"&$B$4) -> 0 | H17: =SUMIFS(Medicion!$K$6:$K$511,Medicion!$G$6:$G$511,$A17,Medicion!$A$6:$A$511,$B$4) -> 0 | I17: =MIN(D17,G17+H17) -> 0 | J17: =IFERROR(I17/D17,0) -> 0 | K17: =MIN(F17,G17*E17) -> 0 | L17: =MIN(F17-K17,H17*E17) -> 0 | M17: =K17+L17 -> 0 | N17: =MAX(0,F17-M17) -> 5157024.8 | O17: =IF(OR(G17+H17>D17+0.000001,G17<0,H17<0),"REVISAR","OK") -> OK
A18: ='Presupuesto Base'!A15 -> 8 | B18: ='Presupuesto Base'!B15 -> Ejecución y compactación de capa cota -0,60 | C18: ='Presupuesto Base'!C15 -> ml | D18: ='Presupuesto Base'!D15 -> 4200 | E18: ='Presupuesto Base'!E15 -> 2592.1553 | F18: ='Presupuesto Base'!F15 -> 10887052 | G18: =SUMIFS(Medicion!$K$6:$K$511,Medicion!$G$6:$G$511,$A18,Medicion!$A$6:$A$511,"<"&$B$4) -> 0 | H18: =SUMIFS(Medicion!$K$6:$K$511,Medicion!$G$6:$G$511,$A18,Medicion!$A$6:$A$511,$B$4) -> 0 | I18: =MIN(D18,G18+H18) -> 0 | J18: =IFERROR(I18/D18,0) -> 0 | K18: =MIN(F18,G18*E18) -> 0 | L18: =MIN(F18-K18,H18*E18) -> 0 | M18: =K18+L18 -> 0 | N18: =MAX(0,F18-M18) -> 10887052 | O18: =IF(OR(G18+H18>D18+0.000001,G18<0,H18<0),"REVISAR","OK") -> OK
A19: ='Presupuesto Base'!A16 -> 9 | B19: ='Presupuesto Base'!B16 -> Ejecución y compactación de capa cota -0,30 | C19: ='Presupuesto Base'!C16 -> ml | D19: ='Presupuesto Base'!D16 -> 4200 | E19: ='Presupuesto Base'!E16 -> 2182.8676 | F19: ='Presupuesto Base'!F16 -> 9168044.1 | G19: =SUMIFS(Medicion!$K$6:$K$511,Medicion!$G$6:$G$511,$A19,Medicion!$A$6:$A$511,"<"&$B$4) -> 0 | H19: =SUMIFS(Medicion!$K$6:$K$511,Medicion!$G$6:$G$511,$A19,Medicion!$A$6:$A$511,$B$4) -> 0 | I19: =MIN(D19,G19+H19) -> 0 | J19: =IFERROR(I19/D19,0) -> 0 | K19: =MIN(F19,G19*E19) -> 0 | L19: =MIN(F19-K19,H19*E19) -> 0 | M19: =K19+L19 -> 0 | N19: =MAX(0,F19-M19) -> 9168044.1 | O19: =IF(OR(G19+H19>D19+0.000001,G19<0,H19<0),"REVISAR","OK") -> OK
A20: ='Presupuesto Base'!A17 -> 10.1 | B20: ='Presupuesto Base'!B17 -> Conexión domiciliaria sobre red Ø75 | C20: ='Presupuesto Base'!C17 -> un | D20: ='Presupuesto Base'!D17 -> 165 | E20: ='Presupuesto Base'!E17 -> 48618.416 | F20: ='Presupuesto Base'!F17 -> 8022038.6 | G20: =SUMIFS(Medicion!$K$6:$K$511,Medicion!$G$6:$G$511,$A20,Medicion!$A$6:$A$511,"<"&$B$4) -> 0 | H20: =SUMIFS(Medicion!$K$6:$K$511,Medicion!$G$6:$G$511,$A20,Medicion!$A$6:$A$511,$B$4) -> 5 | I20: =MIN(D20,G20+H20) -> 5 | J20: =IFERROR(I20/D20,0) -> 0.03030303 | K20: =MIN(F20,G20*E20) -> 0 | L20: =MIN(F20-K20,H20*E20) -> 243092.08 | M20: =K20+L20 -> 243092.08 | N20: =MAX(0,F20-M20) -> 7778946.5 | O20: =IF(OR(G20+H20>D20+0.000001,G20<0,H20<0),"REVISAR","OK") -> OK
A21: ='Presupuesto Base'!A18 -> 10.2 | B21: ='Presupuesto Base'!B18 -> Conexión domiciliaria sobre red Ø110 | C21: ='Presupuesto Base'!C18 -> un | D21: ='Presupuesto Base'!D18 -> 62 | E21: ='Presupuesto Base'!E18 -> 55451.879 | F21: ='Presupuesto Base'!F18 -> 3438016.5 | G21: =SUMIFS(Medicion!$K$6:$K$511,Medicion!$G$6:$G$511,$A21,Medicion!$A$6:$A$511,"<"&$B$4) -> 0 | H21: =SUMIFS(Medicion!$K$6:$K$511,Medicion!$G$6:$G$511,$A21,Medicion!$A$6:$A$511,$B$4) -> 2 | I21: =MIN(D21,G21+H21) -> 2 | J21: =IFERROR(I21/D21,0) -> 0.032258065 | K21: =MIN(F21,G21*E21) -> 0 | L21: =MIN(F21-K21,H21*E21) -> 110903.76 | M21: =K21+L21 -> 110903.76 | N21: =MAX(0,F21-M21) -> 3327112.8 | O21: =IF(OR(G21+H21>D21+0.000001,G21<0,H21<0),"REVISAR","OK") -> OK
... A27: ='Presupuesto Base'!A24 -> 13.3 | B27: ='Presupuesto Base'!B24 -> Documentación conforme a obra y cierre | C27: ='Presupuesto Base'!C24 -> gl | D27: ='Presupuesto Base'!D24 -> 1 | E27: ='Presupuesto Base'!E24 -> 859504.13 | F27: ='Presupuesto Base'!F24 -> 859504.13 | G27: =SUMIFS(Medicion!$K$6:$K$511,Medicion!$G$6:$G$511,$A27,Medicion!$A$6:$A$511,"<"&$B$4) -> 0 | H27: =SUMIFS(Medicion!$K$6:$K$511,Medicion!$G$6:$G$511,$A27,Medicion!$A$6:$A$511,$B$4) -> 0 | I27: =MIN(D27,G27+H27) -> 0 | J27: =IFERROR(I27/D27,0) -> 0 | K27: =MIN(F27,G27*E27) -> 0 | L27: =MIN(F27-K27,H27*E27) -> 0 | M27: =K27+L27 -> 0 | N27: =MAX(0,F27-M27) -> 859504.13 | O27: =IF(OR(G27+H27>D27+0.000001,G27<0,H27<0),"REVISAR","OK") -> OK
B28: TOTAL | K28: =SUM(K10:K27) -> 0 | L28: =SUM(L10:L27) -> 14722545 | M28: =SUM(M10:M27) -> 14722545 | N28: =SUM(N10:N27) -> 99878006
J31: RESUMEN ECONÓMICO
J32: Saldo base certificable s/IVA | N32: =Configuracion!B18 -> 1.1460055e+08
J33: Certificado anteriormente | N33: =K28 -> 0
J34: Certificación del período s/IVA | N34: =L28 -> 14722545
J35: Total acumulado certificado | N35: =M28 -> 14722545
J36: Saldo certificable pendiente | N36: =N28 -> 99878006
J37: IVA del período | N37: =N34*Configuracion!B16 -> 3091734.4
J38: Total período c/IVA | N38: =N34+N37 -> 17814279
J39: Amortización anticipo (manual) | N39: 0
J40: Retención / fondo de reparo (manual) | N40: 0
J41: Otros descuentos / ajustes (manual) | N41: 0
J42: Neto estimado del período | N42: =N38-N39-N40-N41 -> 17814279
J44: Base del certificado: saldo de Red de Agua asignado proporcionalmente sobre $374.400.000 IVA incluido. Mes base contractual: JULIO 2026 – índice UOCRA.
A45: HISTORIAL: seleccionar el N° de certificado en B4 para consultar cualquier emisión. Las columnas ANTERIOR, PRESENTE y ACUMULADO se reconstruyen automáticamente. Una vez CERRADO el certificado, no modificar sus mediciones.

Sheet Conexiones
A1: CONTROL DE CONEXIONES DOMICILIARIAS – 227 UNIDADES
A3: Completar este registro como respaldo del ítem 10.1 / 10.2. Una conexión se considera certificable cuando está completamente ejecutada.
A5: N° | B5: Lote | C5: Manzana | D5: Tramo | E5: Diámetro red | F5: Ítem cert. | G5: Fecha apertura | H5: Fecha ejecución | I5: Fecha tapado | J5: Estado | K5: Inspección OSSE | L5: Observaciones
A6: 1 | F6: =IF(E6="Ø75","10.1",IF(E6="Ø110","10.2",""))
A7: 2 | F7: =IF(E7="Ø75","10.1",IF(E7="Ø110","10.2",""))
A8: 3 | F8: =IF(E8="Ø75","10.1",IF(E8="Ø110","10.2",""))
A9: 4 | F9: =IF(E9="Ø75","10.1",IF(E9="Ø110","10.2",""))
A10: 5 | F10: =IF(E10="Ø75","10.1",IF(E10="Ø110","10.2",""))
A11: 6 | F11: =IF(E11="Ø75","10.1",IF(E11="Ø110","10.2",""))
A12: 7 | F12: =IF(E12="Ø75","10.1",IF(E12="Ø110","10.2",""))
A13: 8 | F13: =IF(E13="Ø75","10.1",IF(E13="Ø110","10.2",""))
A14: 9 | F14: =IF(E14="Ø75","10.1",IF(E14="Ø110","10.2",""))
A15: 10 | F15: =IF(E15="Ø75","10.1",IF(E15="Ø110","10.2",""))
A16: 11 | F16: =IF(E16="Ø75","10.1",IF(E16="Ø110","10.2",""))
A17: 12 | F17: =IF(E17="Ø75","10.1",IF(E17="Ø110","10.2",""))
... A232: 227 | F232: =IF(E232="Ø75","10.1",IF(E232="Ø110","10.2",""))

Sheet Criterios Medicion
A1: CRITERIOS DE MEDICIÓN Y CERTIFICACIÓN POR ÍTEM
A4: Regla general: certificar cantidades físicamente terminadas y comprobables. Evitar porcentajes subjetivos en ítems lineales o unitarios.
A6: Ítem | B6: Actividad | C6: Unidad | D6: Cómo se mide | E6: Condición para certificar | F6: Carga en hoja Medicion | G6: No incluir / observación | H6: Ejemplo
A7: 1 | B7: Replanteo y marcación | C7: ml | D7: Longitud de traza efectivamente replanteada y marcada en terreno. | E7: Eje y límites de zanja identificados conforme al proyecto. | F7: Ingresar metros lineales terminados. | G7: No volver a certificar el mismo tramo. | H7: 120 ml replanteados = 120
A8: 2 | B8: Excavación de zanja | C8: ml | D8: Longitud de zanja excavada hasta profundidad y geometría necesarias para continuar. | E8: Zanja terminada y apta para acondicionar el fondo. | F8: Ingresar metros lineales de zanja terminada. | G8: Reexcavaciones o correcciones no se duplican salvo adicional aprobado. | H8: 80 ml terminados = 80
A9: 3 | B9: Nivelación y conformación de fondo | C9: ml | D9: Longitud con fondo limpiado, perfilado y nivelado. | E9: Fondo listo para recibir cama de asiento. | F9: Ingresar metros lineales terminados. | G9: No medir excavación; sólo acondicionamiento final del fondo. | H9: 80 ml listos = 80
A10: 4 | B10: Cama de asiento compactada | C10: ml | D10: Longitud donde el material de cama fue colocado, nivelado y compactado. | E10: Cama lista para recibir la cañería. | F10: Ingresar metros lineales terminados. | G10: El material y su compactación quedan incluidos en este ítem. | H10: 75 ml = 75
A11: 5.1 | B11: PEAD PN10 Ø75 – provisión e instalación | C11: ml | D11: Longitud de cañería Ø75 colocada dentro de zanja, unida, alineada y centrada. | E11: Cañería instalada en posición definitiva. | F11: Ingresar metros lineales instalados. | G11: Incluye provisión del caño dentro de esta apertura interna. | H11: 60 ml Ø75 = 60
A12: 5.2 | B12: PEAD PN10 Ø110 – provisión e instalación | C12: ml | D12: Longitud de cañería Ø110 colocada dentro de zanja, unida, alineada y centrada. | E12: Cañería instalada en posición definitiva. | F12: Ingresar metros lineales instalados. | G12: Incluye provisión del caño dentro de esta apertura interna. | H12: 40 ml Ø110 = 40
A13: 6 | B13: Paquete estructural 30 cm | C13: ml | D13: Longitud con material base colocado alrededor/sobre la cañería hasta completar el paquete previsto de 30 cm. | E13: Paquete completamente conformado y emparejado. | F13: Ingresar metros lineales terminados. | G13: No certificar parcialmente el espesor; medir longitud terminada. | H13: 50 ml completos = 50
A14: 7 | B14: Compactación paquete estructural 30 cm | C14: ml | D14: Longitud del paquete de 30 cm efectivamente compactado. | E14: Tramo compactado y en condición de solicitar inspección OSSE. | F14: Ingresar metros lineales compactados. | G14: Si requiere corrección, certificar cuando quede conforme. | H14: 50 ml compactados = 50
A15: 8 | B15: Capa cota -0,60 compactada | C15: ml | D15: Longitud con la capa correspondiente a cota -0,60 ejecutada y compactada. | E15: Capa terminada conforme al procedimiento de obra. | F15: Ingresar metros lineales terminados. | G15: Recomendado ejecutar luego de la liberación del tramo correspondiente. | H15: 40 ml = 40
A16: 9 | B16: Capa cota -0,30 compactada | C16: ml | D16: Longitud con la capa correspondiente a cota -0,30 ejecutada y compactada. | E16: Capa terminada conforme al procedimiento de obra. | F16: Ingresar metros lineales terminados. | G16: No confundir con paquete estructural de 30 cm. | H16: 30 ml = 30
A17: 10.1 | B17: Conexión domiciliaria sobre Ø75 | C17: un | D17: Cantidad de conexiones domiciliarias completas ejecutadas sobre red Ø75. | E17: Conexión realizada, tapada y en condición de quedar definitiva. | F17: Ingresar unidades completas. | G17: No certificar fracciones de una conexión. | H17: 4 conexiones = 4
... A24: 13.3 | B24: Documentación conforme a obra y cierre | C24: gl | D24: Avance de la documentación de cierre efectivamente preparada y aprobada. | E24: Entregables definidos y aceptados. | F24: Preferentemente cargar 1,00 al cierre; si se acuerdan hitos, usar fracciones objetivas. | G24: No anticipar porcentaje sin entregable verificable. | H24: Documentación final aprobada = 1,00
A26: NOTA ECONÓMICA: Los criterios de medición no cambian. Los P.U. se recalculan sobre el saldo certificable de la Red de Agua, distribuido proporcionalmente según la oferta original Agua/Cloaca. | B26: Los criterios de medición no cambian. Los P.U. se recalculan sobre el saldo certificable de la Red de Agua, distribuido proporcionalmente según la oferta original Agua/Cloaca.

Sheet Historial Certificados
A1: HISTORIAL DE CERTIFICADOS – RED DE AGUA | LOTEO ROQUE
A3: Cada emisión queda identificada por N° de certificado. Se calculan automáticamente ANTERIOR, PRESENTE y ACUMULADO. Al marcar un certificado como CERRADO, no deben modificarse sus mediciones.
A5: Cert. N° | B5: Período desde | C5: Período hasta | D5: Fecha emisión | E5: Estado | F5: Registros | G5: Anterior s/IVA | H5: Presente s/IVA | I5: Acumulado s/IVA | J5: Saldo s/IVA | K5: Avance acum. | L5: IVA presente | M5: Presente c/IVA | N5: Control | O5: Observaciones
A6: 1 | F6: =COUNTIF(Medicion!$A$6:$A$511,$A6) -> 72 | G6: =SUMIFS('Historial Detalle'!$K$6:$K$437,'Historial Detalle'!$A$6:$A$437,$A6) -> 0 | H6: =SUMIFS('Historial Detalle'!$L$6:$L$437,'Historial Detalle'!$A$6:$A$437,$A6) -> 14722545 | I6: =SUMIFS('Historial Detalle'!$M$6:$M$437,'Historial Detalle'!$A$6:$A$437,$A6) -> 14722545 | J6: =MAX(0,Configuracion!$B$18-I6) -> 99878006 | K6: =IFERROR(I6/Configuracion!$B$18,0) -> 0.12846836 | L6: =H6*Configuracion!$B$16 -> 3091734.4 | M6: =H6+L6 -> 17814279 | N6: =IF(COUNTIFS('Historial Detalle'!$A$6:$A$437,$A6,'Historial Detalle'!$P$6:$P$437,"REVISAR")>0,"REVISAR",IF(F6=0,"SIN MOVIMIENTO","OK")) -> OK
A7: 2 | F7: =COUNTIF(Medicion!$A$6:$A$511,$A7) -> 0 | G7: =SUMIFS('Historial Detalle'!$K$6:$K$437,'Historial Detalle'!$A$6:$A$437,$A7) -> 14722545 | H7: =SUMIFS('Historial Detalle'!$L$6:$L$437,'Historial Detalle'!$A$6:$A$437,$A7) -> 0 | I7: =SUMIFS('Historial Detalle'!$M$6:$M$437,'Historial Detalle'!$A$6:$A$437,$A7) -> 14722545 | J7: =MAX(0,Configuracion!$B$18-I7) -> 99878006 | K7: =IFERROR(I7/Configuracion!$B$18,0) -> 0.12846836 | L7: =H7*Configuracion!$B$16 -> 0 | M7: =H7+L7 -> 0 | N7: =IF(COUNTIFS('Historial Detalle'!$A$6:$A$437,$A7,'Historial Detalle'!$P$6:$P$437,"REVISAR")>0,"REVISAR",IF(F7=0,"SIN MOVIMIENTO","OK")) -> SIN MOVIMIENTO
A8: 3 | F8: =COUNTIF(Medicion!$A$6:$A$511,$A8) -> 0 | G8: =SUMIFS('Historial Detalle'!$K$6:$K$437,'Historial Detalle'!$A$6:$A$437,$A8) -> 14722545 | H8: =SUMIFS('Historial Detalle'!$L$6:$L$437,'Historial Detalle'!$A$6:$A$437,$A8) -> 0 | I8: =SUMIFS('Historial Detalle'!$M$6:$M$437,'Historial Detalle'!$A$6:$A$437,$A8) -> 14722545 | J8: =MAX(0,Configuracion!$B$18-I8) -> 99878006 | K8: =IFERROR(I8/Configuracion!$B$18,0) -> 0.12846836 | L8: =H8*Configuracion!$B$16 -> 0 | M8: =H8+L8 -> 0 | N8: =IF(COUNTIFS('Historial Detalle'!$A$6:$A$437,$A8,'Historial Detalle'!$P$6:$P$437,"REVISAR")>0,"REVISAR",IF(F8=0,"SIN MOVIMIENTO","OK")) -> SIN MOVIMIENTO
A9: 4 | F9: =COUNTIF(Medicion!$A$6:$A$511,$A9) -> 0 | G9: =SUMIFS('Historial Detalle'!$K$6:$K$437,'Historial Detalle'!$A$6:$A$437,$A9) -> 14722545 | H9: =SUMIFS('Historial Detalle'!$L$6:$L$437,'Historial Detalle'!$A$6:$A$437,$A9) -> 0 | I9: =SUMIFS('Historial Detalle'!$M$6:$M$437,'Historial Detalle'!$A$6:$A$437,$A9) -> 14722545 | J9: =MAX(0,Configuracion!$B$18-I9) -> 99878006 | K9: =IFERROR(I9/Configuracion!$B$18,0) -> 0.12846836 | L9: =H9*Configuracion!$B$16 -> 0 | M9: =H9+L9 -> 0 | N9: =IF(COUNTIFS('Historial Detalle'!$A$6:$A$437,$A9,'Historial Detalle'!$P$6:$P$437,"REVISAR")>0,"REVISAR",IF(F9=0,"SIN MOVIMIENTO","OK")) -> SIN MOVIMIENTO
