Workbook
Name Lista_Anios: LISTAS!$G$2:$G$5
Name Lista_Cargas_Batan: 'CONTROL DE BATAN'!$A$2:$A$301
Name Lista_Codigos: LISTAS!$A$3:$A$202
Name Lista_EstadoProveedor: LISTAS!$F$2:$F$5
Name Lista_Meses: LISTAS!$H$2:$H$13
Name Lista_Meses_Dashboard: LISTAS!$I$2:$I$14
Name Lista_MetodoPago: LISTAS!$E$2:$E$5
Name Lista_Obras: 'MAESTRO DE OBRAS'!$B$2:$B$200
Name Lista_Obras_Dash: LISTAS!$C$2:$C$202
Name Lista_Proveedores: LISTAS!$J$2:$J$6
Name Lista_Responsables: 'MAESTRO DE RESPONSABLES'!$A$2:$A$200
Name Lista_Responsables_Dash: LISTAS!$B$2:$B$202
Name Lista_TipoCombustible: LISTAS!$D$2:$D$5
Name Lista_TipoCombustible_Dash: LISTAS!$D$7:$D$11
Name Lista_Unidades_Dashboard: LISTAS!$K$2:$K$202

Sheet INICIO
A1: CONTROL DE COMBUSTIBLE
A3: Planilla integral para registro, análisis y conciliación mensual con proveedor
A5: Objetivo | B5: Registrar cada carga, controlar consumos, detectar desvíos y validar el pago mensual al proveedor.
A6: Uso sugerido | B6: 1) Completar maestros. 2) Registrar cargas en la hoja principal. 3) Revisar alertas. 4) Conciliar factura en Control Mensual. 5) Analizar KPIs en Dashboard.
A8: Fecha de actualización | B8: =TODAY() -> 46160
A9: Hojas incluidas | B9: Inicio, Maestros, Cargas, Control Mensual Proveedor, Indicadores y Dashboard.
A11: Accesos rápidos
A12: Ir a cargas
A13: Ir a dashboard
A14: Ir a control mensual

Sheet MAESTRO DE UNIDADES
A1: Código interno | B1: Tipo de unidad | C1: Descripción | D1: Marca | E1: Modelo | F1: Patente | G1: Año | H1: Tipo de combustible | I1: Capacidad de tanque | J1: Área / sector | K1: Responsable habitual | L1: Estado
A2: C-001 | B2: Camioneta | C2: Toyota Hilux 2.4 | D2: Toyota | E2: Hilux | F2: AE829HD | G2: 2021 | H2: Diesel V-Power | I2: 80 | J2: G. General | K2: G. Regalado | L2: Activo
A3: C-002 | B3: Camioneta | C3: Toyota Hilux 2.4 | D3: Toyota | E3: Hilux | F3: AG839PV | G3: 2024 | H3: Diesel V-Power | I3: 80 | J3: Directorio | K3: C. Regalado | L3: Activo
A4: C-003 | B4: Camioneta | C4: RAM 1500 5.7 V8 LARAMIE4X4 | D4: RAM | E4: LARAMIE | F4: AE453FS | G4: 2021 | H4: Nafta | I4: 98 | J4: Directorio | K4: C. Regalado | L4: Activo
A5: C-004 | B5: Camioneta | C5: Peugeot Partner confort 1.6 HDI | D5: Peugeot | E5: Partner | F5: OWQ190 | G5: 2015 | H5: Diesel-Evolux | I5: 55 | J5: Obras | L5: Activo
A6: C-005 | B6: Camioneta | C6: Toyota Hilux 4X4 C/S DX2.4 TDI 6M/T | D6: Toyota | E6: Hilux | F6: AE167AT | G6: 2024 | H6: Diesel V-Power | I6: 80 | J6: Directorio | K6: C. Regalado | L6: Activo
A7: CM-001 | B7: Camión | C7: Iveco Tector | D7: Iveco | E7: Tector | F7: AC | G7: 2020 | H7: Diesel V-Power | I7: 150 | J7: Logística | L7: Activo
A8: CM-002 | B8: Camión | C8: IVECO Daily 70c17 PASO 4350 | D8: IVECO | E8: Daily | F8: AD478QW | G8: 2018 | H8: Diesel V-Power | I8: 100 | J8: Obras | L8: Activo
A9: EP-001 | B9: Equipo | C9: Motocompresor | H9: Diesel-Evolux | I9: 70 | J9: Obras | L9: Activo
A10: EP-002 | B10: Equipo | C10: Motosoldador | H10: Diesel-Evolux | J10: Obras
A11: EP-003 | B11: Equipo | C11: Montacarga | D11: Longking | H11: Diesel-Evolux
A12: MC-001 | B12: Mini cargadora | C12: CAT | D12: Caterpillar | G12: 2017 | H12: Diesel-Evolux | K12: Luis Martínez | L12: Activo
A13: MC-002 | B13: Mini cargadora | C13: Longking | H13: Diesel-Evolux
A14: RP-001 | B14: Retroexcavadora | C14: Hidromek | D14: HIDROMEK | G14: 2024 | H14: Diesel-Evolux | I14: 140 | J14: Obras | L14: Activo
A15: RP-002 | B15: Retroexcavadora | C15: MAXION 750 | H15: Diesel-Evolux | L15: Activo
A16: BT-001 | B16: Batan | C16: Batan de 200lts | G16: 2024 | H16: Diesel-Evolux | I16: 200
A17: C-006 | B17: Camioneta | C17: Toyota Hilux 2.4 | D17: Toyota | E17: Hilux | F17: ISB 928 | G17: 2011 | H17: Diesel-Evolux | I17: 80 | J17: Varios | K17: G. Regalado | L17: Activo

Sheet MAESTRO DE RESPONSABLES
A1: Nombre y apellido | B1: Cargo | C1: Área | D1: Observaciones
A2: Ariel Jofre | B2: Chofer | C2: Logística
A3: Bruno Guevara | B3: Encargado de obra | C3: Obras
A4: Enrico | B4: Gerencia | C4: Administracion
A5: Gustavo | B5: Gerencia | C5: Gerencia General
A6: Adolfo | B6: Gerencia | C6: Financiera
A7: Daniel Pereyra | B7: Maquinista | C7: Obras
A8: Martin | B8: Maquinista | C8: Obras
A9: Daniel | B9: Chofer | C9: Obras
A12: Nota: | B12: Para los que usan los vehiculos si o si tiene que tener gestionados los permisos de manejo y el carnet de conducir comun o prefesional según corresponda

Sheet MAESTRO DE OBRAS
A1: Código | B1: Obra / sector | C1: Cliente | D1: Ubicación | E1: Estado
A2: OB-001 | B2: Barrio Don Jose | C2: Gobierno | E2: Activa
A3: OB-002 | B3: Escuela Stgo del Estero | C3: Gobierno | E3: Activa
A4: OB-003 | B4: Mantenimiento Escuelas | C4: Gobierno | E4: Activa
A5: OB-004 | B5: Movimientos Internos | E5: Activa
A6: OB-005 | B6: Barrio ASEC | C6: Borrego | E6: Activa
A7: OB-006 | B7: Barrio San Martin | C7: Gobierno | E7: Activa

Sheet CARGAS DE COMBUSTIBLE
A1: ID de carga | B1: Fecha | C1: Mes | D1: Año | E1: Día de semana | F1: Vehículo / equipo | G1: Código interno | H1: Patente | I1: Tipo de unidad | J1: Responsable | K1: Obra / centro de costo | L1: Proveedor / estación | M1: Tipo de combustible | N1: Litros cargados | O1: Precio por litro | P1: Importe total | Q1: Kilometraje al cargar | R1: Horómetro al cargar | S1: Kilómetros recorridos desde la carga anterior | T1: Horas trabajadas desde la carga anterior | U1: Rendimiento estimado | V1: Método de pago | W1: VALE DE COMBUSTIBLE | X1: Observaciones | Y1: Validación / estado del registro | Z1: Origen de carga | AA1: ID carga de batán | AB1: Precio batán aplicado | AC1: Saldo batán luego de la carga
A2: =IF(B2="","","CARGA-"&TEXT(ROW()-1,"0000")) -> CARGA-0001 | B2: 46147 | C2: =IF(B2="","",CHOOSE(MONTH(B2),"Enero","Febrero","Marzo","Abril","Mayo","Junio","Julio","Agosto","Septiembre","Octubre","Noviembre","Diciembre")) -> Mayo | D2: =IF(B2="","",YEAR(B2)) -> 2026 | E2: =IF(B2="","",CHOOSE(WEEKDAY(B2,2),"Lunes","Martes","Miércoles","Jueves","Viernes","Sábado","Domingo")) -> Martes | F2: =+tblUnidades[[#This Row],[Descripción]] -> Toyota Hilux 2.4 | G2: C-002 | H2: =IF($G2="","",IFERROR(INDEX('MAESTRO DE UNIDADES'!$F$2:$F$208,MATCH($G2,'MAESTRO DE UNIDADES'!$A$2:$A$208,0)),"")) -> AG839PV | I2: =IF($G2="","",IFERROR(INDEX('MAESTRO DE UNIDADES'!$B$2:$B$208,MATCH($G2,'MAESTRO DE UNIDADES'!$A$2:$A$208,0)),"")) -> Camioneta | J2: Adolfo | K2: Movimientos Internos | L2: Shell Agro | M2: =IF($G2="","",IFERROR(INDEX('MAESTRO DE UNIDADES'!$H$2:$H$208,MATCH($G2,'MAESTRO DE UNIDADES'!$A$2:$A$208,0)),"")) -> Diesel V-Power | N2: 40 | P2: =IF($N2="","",IF($AA2<>"",IF($AB2="","",$N2*$AB2),IF($O2="","",$N2*$O2))) | S2: =IF(OR($G2="",$Q2="",COUNTIF($G$1:G2,$G2)=0),"",$Q2-LOOKUP(2,1/($G$1:G2=$G2),$Q$1:Q2)) | T2: =IF(OR($G2="",$R2="",COUNTIF($G$1:G2,$G2)=0),"",$R2-LOOKUP(2,1/($G$1:G2=$G2),$R$1:R2)) | U2: =IF(N2="","",IF(S2<>"",S2/N2,IF(T2<>"",T2/N2,""))) | W2: 205 | X2: N°205 / REMITO N° 7687 | Y2: =IF($B2="","",IF((IF($G2="","Sin unidad | ","")&IF($J2="","Sin responsable | ","")&IF($K2="","Sin obra | ","")&IF(AND($N2<>"",$G2<>"",$N2>IFERROR(INDEX('MAESTRO DE UNIDADES'!$I$2:$I$208,MATCH($G2,'MAESTRO DE UNIDADES'!$A$2:$A$208,0)),0)),"Litros > tanque | ","")&IF(AND($W2<>"",COUNTIF($W$2:$W2,$W2)>1),"Ticket duplicado | ","")&IF(AND($G2<>"",IFERROR(INDEX('MAESTRO DE UNIDADES'!$L$2:$L$208,MATCH($G2,'MAESTRO DE UNIDADES'!$A$2:$A$208,0)),"")="Inactivo"),"Unidad inactiva | ","")&IF(AND($AA2<>"",$N2=""),"Carga de batán sin litros | ","")&IF(AND($AA2<>"",$AC2<0),"Supera saldo batán | ",""))="","OK",LEFT((IF($G2="","Sin unidad | ","")&IF($J2="","Sin responsable | ","")&IF($K2="","Sin obra | ","")&IF(AND($N2<>"",$G2<>"",$N2>IFERROR(INDEX('MAESTRO DE UNIDADES'!$I$2:$I$208,MATCH($G2,'MAESTRO DE UNIDADES'!$A$2:$A$208,0)),0)),"Litros > tanque | ","")&IF(AND($W2<>"",COUNTIF($W$2:$W2,$W2)>1),"Ticket duplicado | ","")&IF(AND($G2<>"",IFERROR(INDEX('MAESTRO DE UNIDADES'!$L$2:$L$208,MATCH($G2,'MAESTRO DE UNIDADES'!$A$2:$A$208,0)),"")="Inactivo"),"Unidad inactiva | ","")&IF(AND($AA2<>"",$N2=""),"Carga de batán sin litros | ","")&IF(AND($AA2<>"",$AC2<0),"Supera saldo batán | ","")),LEN((IF($G2="","Sin unidad | ","")&IF($J2="","Sin responsable | ","")&IF($K2="","Sin obra | ","")&IF(AND($N2<>"",$G2<>"",$N2>IFERROR(INDEX('MAESTRO DE UNIDADES'!$I$2:$I$208,MATCH($G2,'MAESTRO DE UNIDADES'!$A$2:$A$208,0)),0)),"Litros > tanque | ","")&IF(AND($W2<>"",COUNTIF($W$2:$W2,$W2)>1),"Ticket duplicado | ","")&IF(AND($G2<>"",IFERROR(INDEX('MAESTRO DE UNIDADES'!$L$2:$L$208,MATCH($G2,'MAESTRO DE UNIDADES'!$A$2:$A$208,0)),"")="Inactivo"),"Unidad inactiva | ","")&IF(AND($AA2<>"",$N2=""),"Carga de batán sin litros | ","")&IF(AND($AA2<>"",$AC2<0),"Supera saldo batán | ","")))-3))) -> OK | Z2: =IF($B2="","",IF($AA2<>"","Batán","Estación de servicio")) -> Estación de servicio
A3: =IF(B3="","","CARGA-"&TEXT(ROW()-1,"0000")) -> CARGA-0002 | B3: 46157 | C3: =IF(B3="","",CHOOSE(MONTH(B3),"Enero","Febrero","Marzo","Abril","Mayo","Junio","Julio","Agosto","Septiembre","Octubre","Noviembre","Diciembre")) -> Mayo | D3: =IF(B3="","",YEAR(B3)) -> 2026 | E3: =IF(B3="","",CHOOSE(WEEKDAY(B3,2),"Lunes","Martes","Miércoles","Jueves","Viernes","Sábado","Domingo")) -> Viernes | F3: Iveco tector | G3: CM-002 | H3: =IF($G3="","",IFERROR(INDEX('MAESTRO DE UNIDADES'!$F$2:$F$208,MATCH($G3,'MAESTRO DE UNIDADES'!$A$2:$A$208,0)),"")) -> AD478QW | I3: =IF($G3="","",IFERROR(INDEX('MAESTRO DE UNIDADES'!$B$2:$B$208,MATCH($G3,'MAESTRO DE UNIDADES'!$A$2:$A$208,0)),"")) -> Camión | J3: Bruno Guevara | K3: Barrio Don Jose | L3: Shell Agro | M3: =IF($G3="","",IFERROR(INDEX('MAESTRO DE UNIDADES'!$H$2:$H$208,MATCH($G3,'MAESTRO DE UNIDADES'!$A$2:$A$208,0)),"")) -> Diesel V-Power | N3: 49.65 | W3: S-V | X3: 4174/ S-V | Y3: OK | Z3: Estación de servicio
A4: =IF(B4="","","CARGA-"&TEXT(ROW()-1,"0000")) -> CARGA-0003 | B4: 46157 | C4: =IF(B4="","",CHOOSE(MONTH(B4),"Enero","Febrero","Marzo","Abril","Mayo","Junio","Julio","Agosto","Septiembre","Octubre","Noviembre","Diciembre")) -> Mayo | D4: =IF(B4="","",YEAR(B4)) -> 2026 | E4: =IF(B4="","",CHOOSE(WEEKDAY(B4,2),"Lunes","Martes","Miércoles","Jueves","Viernes","Sábado","Domingo")) -> Viernes | F4: Toyota Hilux 2.4 | G4: C-002 | H4: =IF($G4="","",IFERROR(INDEX('MAESTRO DE UNIDADES'!$F$2:$F$208,MATCH($G4,'MAESTRO DE UNIDADES'!$A$2:$A$208,0)),"")) -> AG839PV | I4: =IF($G4="","",IFERROR(INDEX('MAESTRO DE UNIDADES'!$B$2:$B$208,MATCH($G4,'MAESTRO DE UNIDADES'!$A$2:$A$208,0)),"")) -> Camioneta | J4: Adolfo | K4: Movimientos Internos | L4: Shell Agro | M4: =IF($G4="","",IFERROR(INDEX('MAESTRO DE UNIDADES'!$H$2:$H$208,MATCH($G4,'MAESTRO DE UNIDADES'!$A$2:$A$208,0)),"")) -> Diesel V-Power | N4: 50 | P4: =IF($N4="","",IF($AA4<>"",IF($AB4="","",$N4*$AB4),IF($O4="","",$N4*$O4))) | S4: =IF(OR($G4="",$Q4="",COUNTIF($G$2:G3,$G4)=0),"",$Q4-LOOKUP(2,1/($G$2:G3=$G4),$Q$2:Q3)) | T4: =IF(OR($G4="",$R4="",COUNTIF($G$2:G3,$G4)=0),"",$R4-LOOKUP(2,1/($G$2:G3=$G4),$R$2:R3)) | U4: =IF(N4="","",IF(S4<>"",S4/N4,IF(T4<>"",T4/N4,""))) | W4: S-V | X4: 4175/S-V | Y4: OK | Z4: =IF($B4="","",IF($AA4<>"","Batán","Estación de servicio")) -> Estación de servicio
A5: =IF(B5="","","CARGA-"&TEXT(ROW()-1,"0000")) | C5: =IF(B5="","",CHOOSE(MONTH(B5),"Enero","Febrero","Marzo","Abril","Mayo","Junio","Julio","Agosto","Septiembre","Octubre","Noviembre","Diciembre")) | D5: =IF(B5="","",YEAR(B5)) | E5: =IF(B5="","",CHOOSE(WEEKDAY(B5,2),"Lunes","Martes","Miércoles","Jueves","Viernes","Sábado","Domingo")) | H5: =IF($G5="","",IFERROR(INDEX('MAESTRO DE UNIDADES'!$F$2:$F$208,MATCH($G5,'MAESTRO DE UNIDADES'!$A$2:$A$208,0)),"")) | I5: =IF($G5="","",IFERROR(INDEX('MAESTRO DE UNIDADES'!$B$2:$B$208,MATCH($G5,'MAESTRO DE UNIDADES'!$A$2:$A$208,0)),"")) | P5: =IF($N5="","",IF($AA5<>"",IF($AB5="","",$N5*$AB5),IF($O5="","",$N5*$O5))) | S5: =IF(OR($G5="",$Q5=""),"","") | T5: =IF(OR($G5="",$R5=""),"","") | U5: =IF(N5="","",IF(S5<>"",S5/N5,IF(T5<>"",T5/N5,""))) | Y5: =IF($B5="","",IF((IF($G5="","Sin unidad | ","")&IF($J5="","Sin responsable | ","")&IF($K5="","Sin obra | ","")&IF(AND($N5<>"",$G5<>"",$N5>IFERROR(INDEX('MAESTRO DE UNIDADES'!$I$2:$I$208,MATCH($G5,'MAESTRO DE UNIDADES'!$A$2:$A$208,0)),0)),"Litros > tanque | ","")&IF(AND($W5<>"",COUNTIF($W$2:$W5,$W5)>1),"Ticket duplicado | ","")&IF(AND($G5<>"",IFERROR(INDEX('MAESTRO DE UNIDADES'!$L$2:$L$208,MATCH($G5,'MAESTRO DE UNIDADES'!$A$2:$A$208,0)),"")="Inactivo"),"Unidad inactiva | ","")&IF(AND($AA5<>"",$N5=""),"Carga de batán sin litros | ","")&IF(AND($AA5<>"",$AC5<0),"Supera saldo batán | ",""))="","OK",LEFT((IF($G5="","Sin unidad | ","")&IF($J5="","Sin responsable | ","")&IF($K5="","Sin obra | ","")&IF(AND($N5<>"",$G5<>"",$N5>IFERROR(INDEX('MAESTRO DE UNIDADES'!$I$2:$I$208,MATCH($G5,'MAESTRO DE UNIDADES'!$A$2:$A$208,0)),0)),"Litros > tanque | ","")&IF(AND($W5<>"",COUNTIF($W$2:$W5,$W5)>1),"Ticket duplicado | ","")&IF(AND($G5<>"",IFERROR(INDEX('MAESTRO DE UNIDADES'!$L$2:$L$208,MATCH($G5,'MAESTRO DE UNIDADES'!$A$2:$A$208,0)),"")="Inactivo"),"Unidad inactiva | ","")&IF(AND($AA5<>"",$N5=""),"Carga de batán sin litros | ","")&IF(AND($AA5<>"",$AC5<0),"Supera saldo batán | ","")),LEN((IF($G5="","Sin unidad | ","")&IF($J5="","Sin responsable | ","")&IF($K5="","Sin obra | ","")&IF(AND($N5<>"",$G5<>"",$N5>IFERROR(INDEX('MAESTRO DE UNIDADES'!$I$2:$I$208,MATCH($G5,'MAESTRO DE UNIDADES'!$A$2:$A$208,0)),0)),"Litros > tanque | ","")&IF(AND($W5<>"",COUNTIF($W$2:$W5,$W5)>1),"Ticket duplicado | ","")&IF(AND($G5<>"",IFERROR(INDEX('MAESTRO DE UNIDADES'!$L$2:$L$208,MATCH($G5,'MAESTRO DE UNIDADES'!$A$2:$A$208,0)),"")="Inactivo"),"Unidad inactiva | ","")&IF(AND($AA5<>"",$N5=""),"Carga de batán sin litros | ","")&IF(AND($AA5<>"",$AC5<0),"Supera saldo batán | ","")))-3))) | Z5: =IF($B5="","",IF($AA5<>"","Batán","Estación de servicio"))
A6: =IF(B6="","","CARGA-"&TEXT(ROW()-1,"0000")) | C6: =IF(B6="","",CHOOSE(MONTH(B6),"Enero","Febrero","Marzo","Abril","Mayo","Junio","Julio","Agosto","Septiembre","Octubre","Noviembre","Diciembre")) | D6: =IF(B6="","",YEAR(B6)) | E6: =IF(B6="","",CHOOSE(WEEKDAY(B6,2),"Lunes","Martes","Miércoles","Jueves","Viernes","Sábado","Domingo")) | H6: =IF($G6="","",IFERROR(INDEX('MAESTRO DE UNIDADES'!$F$2:$F$208,MATCH($G6,'MAESTRO DE UNIDADES'!$A$2:$A$208,0)),"")) | I6: =IF($G6="","",IFERROR(INDEX('MAESTRO DE UNIDADES'!$B$2:$B$208,MATCH($G6,'MAESTRO DE UNIDADES'!$A$2:$A$208,0)),"")) | M6: =IF($G6="","",IFERROR(INDEX('MAESTRO DE UNIDADES'!$H$2:$H$208,MATCH($G6,'MAESTRO DE UNIDADES'!$A$2:$A$208,0)),"")) | P6: =IF($N6="","",IF($AA6<>"",IF($AB6="","",$N6*$AB6),IF($O6="","",$N6*$O6))) | S6: =IF(OR($G6="",$Q6="",COUNTIF($G$2:G5,$G6)=0),"",$Q6-LOOKUP(2,1/($G$2:G5=$G6),$Q$2:Q5)) | T6: =IF(OR($G6="",$R6="",COUNTIF($G$2:G5,$G6)=0),"",$R6-LOOKUP(2,1/($G$2:G5=$G6),$R$2:R5)) | U6: =IF(N6="","",IF(S6<>"",S6/N6,IF(T6<>"",T6/N6,""))) | Y6: =IF($B6="","",IF((IF($G6="","Sin unidad | ","")&IF($J6="","Sin responsable | ","")&IF($K6="","Sin obra | ","")&IF(AND($N6<>"",$G6<>"",$N6>IFERROR(INDEX('MAESTRO DE UNIDADES'!$I$2:$I$208,MATCH($G6,'MAESTRO DE UNIDADES'!$A$2:$A$208,0)),0)),"Litros > tanque | ","")&IF(AND($W6<>"",COUNTIF($W$2:$W6,$W6)>1),"Ticket duplicado | ","")&IF(AND($G6<>"",IFERROR(INDEX('MAESTRO DE UNIDADES'!$L$2:$L$208,MATCH($G6,'MAESTRO DE UNIDADES'!$A$2:$A$208,0)),"")="Inactivo"),"Unidad inactiva | ","")&IF(AND($AA6<>"",$N6=""),"Carga de batán sin litros | ","")&IF(AND($AA6<>"",$AC6<0),"Supera saldo batán | ",""))="","OK",LEFT((IF($G6="","Sin unidad | ","")&IF($J6="","Sin responsable | ","")&IF($K6="","Sin obra | ","")&IF(AND($N6<>"",$G6<>"",$N6>IFERROR(INDEX('MAESTRO DE UNIDADES'!$I$2:$I$208,MATCH($G6,'MAESTRO DE UNIDADES'!$A$2:$A$208,0)),0)),"Litros > tanque | ","")&IF(AND($W6<>"",COUNTIF($W$2:$W6,$W6)>1),"Ticket duplicado | ","")&IF(AND($G6<>"",IFERROR(INDEX('MAESTRO DE UNIDADES'!$L$2:$L$208,MATCH($G6,'MAESTRO DE UNIDADES'!$A$2:$A$208,0)),"")="Inactivo"),"Unidad inactiva | ","")&IF(AND($AA6<>"",$N6=""),"Carga de batán sin litros | ","")&IF(AND($AA6<>"",$AC6<0),"Supera saldo batán | ","")),LEN((IF($G6="","Sin unidad | ","")&IF($J6="","Sin responsable | ","")&IF($K6="","Sin obra | ","")&IF(AND($N6<>"",$G6<>"",$N6>IFERROR(INDEX('MAESTRO DE UNIDADES'!$I$2:$I$208,MATCH($G6,'MAESTRO DE UNIDADES'!$A$2:$A$208,0)),0)),"Litros > tanque | ","")&IF(AND($W6<>"",COUNTIF($W$2:$W6,$W6)>1),"Ticket duplicado | ","")&IF(AND($G6<>"",IFERROR(INDEX('MAESTRO DE UNIDADES'!$L$2:$L$208,MATCH($G6,'MAESTRO DE UNIDADES'!$A$2:$A$208,0)),"")="Inactivo"),"Unidad inactiva | ","")&IF(AND($AA6<>"",$N6=""),"Carga de batán sin litros | ","")&IF(AND($AA6<>"",$AC6<0),"Supera saldo batán | ","")))-3))) | Z6: =IF($B6="","",IF($AA6<>"","Batán","Estación de servicio"))
A7: =IF(B7="","","CARGA-"&TEXT(ROW()-1,"0000")) | C7: =IF(B7="","",CHOOSE(MONTH(B7),"Enero","Febrero","Marzo","Abril","Mayo","Junio","Julio","Agosto","Septiembre","Octubre","Noviembre","Diciembre")) | D7: =IF(B7="","",YEAR(B7)) | E7: =IF(B7="","",CHOOSE(WEEKDAY(B7,2),"Lunes","Martes","Miércoles","Jueves","Viernes","Sábado","Domingo")) | H7: =IF($G7="","",IFERROR(INDEX('MAESTRO DE UNIDADES'!$F$2:$F$208,MATCH($G7,'MAESTRO DE UNIDADES'!$A$2:$A$208,0)),"")) | I7: =IF($G7="","",IFERROR(INDEX('MAESTRO DE UNIDADES'!$B$2:$B$208,MATCH($G7,'MAESTRO DE UNIDADES'!$A$2:$A$208,0)),"")) | M7: =IF($G7="","",IFERROR(INDEX('MAESTRO DE UNIDADES'!$H$2:$H$208,MATCH($G7,'MAESTRO DE UNIDADES'!$A$2:$A$208,0)),"")) | P7: =IF($N7="","",IF($AA7<>"",IF($AB7="","",$N7*$AB7),IF($O7="","",$N7*$O7))) | S7: =IF(OR($G7="",$Q7="",COUNTIF($G$2:G6,$G7)=0),"",$Q7-LOOKUP(2,1/($G$2:G6=$G7),$Q$2:Q6)) | T7: =IF(OR($G7="",$R7="",COUNTIF($G$2:G6,$G7)=0),"",$R7-LOOKUP(2,1/($G$2:G6=$G7),$R$2:R6)) | U7: =IF(N7="","",IF(S7<>"",S7/N7,IF(T7<>"",T7/N7,""))) | Y7: =IF($B7="","",IF((IF($G7="","Sin unidad | ","")&IF($J7="","Sin responsable | ","")&IF($K7="","Sin obra | ","")&IF(AND($N7<>"",$G7<>"",$N7>IFERROR(INDEX('MAESTRO DE UNIDADES'!$I$2:$I$208,MATCH($G7,'MAESTRO DE UNIDADES'!$A$2:$A$208,0)),0)),"Litros > tanque | ","")&IF(AND($W7<>"",COUNTIF($W$2:$W7,$W7)>1),"Ticket duplicado | ","")&IF(AND($G7<>"",IFERROR(INDEX('MAESTRO DE UNIDADES'!$L$2:$L$208,MATCH($G7,'MAESTRO DE UNIDADES'!$A$2:$A$208,0)),"")="Inactivo"),"Unidad inactiva | ","")&IF(AND($AA7<>"",$N7=""),"Carga de batán sin litros | ","")&IF(AND($AA7<>"",$AC7<0),"Supera saldo batán | ",""))="","OK",LEFT((IF($G7="","Sin unidad | ","")&IF($J7="","Sin responsable | ","")&IF($K7="","Sin obra | ","")&IF(AND($N7<>"",$G7<>"",$N7>IFERROR(INDEX('MAESTRO DE UNIDADES'!$I$2:$I$208,MATCH($G7,'MAESTRO DE UNIDADES'!$A$2:$A$208,0)),0)),"Litros > tanque | ","")&IF(AND($W7<>"",COUNTIF($W$2:$W7,$W7)>1),"Ticket duplicado | ","")&IF(AND($G7<>"",IFERROR(INDEX('MAESTRO DE UNIDADES'!$L$2:$L$208,MATCH($G7,'MAESTRO DE UNIDADES'!$A$2:$A$208,0)),"")="Inactivo"),"Unidad inactiva | ","")&IF(AND($AA7<>"",$N7=""),"Carga de batán sin litros | ","")&IF(AND($AA7<>"",$AC7<0),"Supera saldo batán | ","")),LEN((IF($G7="","Sin unidad | ","")&IF($J7="","Sin responsable | ","")&IF($K7="","Sin obra | ","")&IF(AND($N7<>"",$G7<>"",$N7>IFERROR(INDEX('MAESTRO DE UNIDADES'!$I$2:$I$208,MATCH($G7,'MAESTRO DE UNIDADES'!$A$2:$A$208,0)),0)),"Litros > tanque | ","")&IF(AND($W7<>"",COUNTIF($W$2:$W7,$W7)>1),"Ticket duplicado | ","")&IF(AND($G7<>"",IFERROR(INDEX('MAESTRO DE UNIDADES'!$L$2:$L$208,MATCH($G7,'MAESTRO DE UNIDADES'!$A$2:$A$208,0)),"")="Inactivo"),"Unidad inactiva | ","")&IF(AND($AA7<>"",$N7=""),"Carga de batán sin litros | ","")&IF(AND($AA7<>"",$AC7<0),"Supera saldo batán | ","")))-3))) | Z7: =IF($B7="","",IF($AA7<>"","Batán","Estación de servicio"))
A8: =IF(B8="","","CARGA-"&TEXT(ROW()-1,"0000")) | C8: =IF(B8="","",CHOOSE(MONTH(B8),"Enero","Febrero","Marzo","Abril","Mayo","Junio","Julio","Agosto","Septiembre","Octubre","Noviembre","Diciembre")) | D8: =IF(B8="","",YEAR(B8)) | E8: =IF(B8="","",CHOOSE(WEEKDAY(B8,2),"Lunes","Martes","Miércoles","Jueves","Viernes","Sábado","Domingo")) | H8: =IF($G8="","",IFERROR(INDEX('MAESTRO DE UNIDADES'!$F$2:$F$208,MATCH($G8,'MAESTRO DE UNIDADES'!$A$2:$A$208,0)),"")) | I8: =IF($G8="","",IFERROR(INDEX('MAESTRO DE UNIDADES'!$B$2:$B$208,MATCH($G8,'MAESTRO DE UNIDADES'!$A$2:$A$208,0)),"")) | M8: =IF($G8="","",IFERROR(INDEX('MAESTRO DE UNIDADES'!$H$2:$H$208,MATCH($G8,'MAESTRO DE UNIDADES'!$A$2:$A$208,0)),"")) | P8: =IF($N8="","",IF($AA8<>"",IF($AB8="","",$N8*$AB8),IF($O8="","",$N8*$O8))) | S8: =IF(OR($G8="",$Q8="",COUNTIF($G$2:G7,$G8)=0),"",$Q8-LOOKUP(2,1/($G$2:G7=$G8),$Q$2:Q7)) | T8: =IF(OR($G8="",$R8="",COUNTIF($G$2:G7,$G8)=0),"",$R8-LOOKUP(2,1/($G$2:G7=$G8),$R$2:R7)) | U8: =IF(N8="","",IF(S8<>"",S8/N8,IF(T8<>"",T8/N8,""))) | Y8: =IF($B8="","",IF((IF($G8="","Sin unidad | ","")&IF($J8="","Sin responsable | ","")&IF($K8="","Sin obra | ","")&IF(AND($N8<>"",$G8<>"",$N8>IFERROR(INDEX('MAESTRO DE UNIDADES'!$I$2:$I$208,MATCH($G8,'MAESTRO DE UNIDADES'!$A$2:$A$208,0)),0)),"Litros > tanque | ","")&IF(AND($W8<>"",COUNTIF($W$2:$W8,$W8)>1),"Ticket duplicado | ","")&IF(AND($G8<>"",IFERROR(INDEX('MAESTRO DE UNIDADES'!$L$2:$L$208,MATCH($G8,'MAESTRO DE UNIDADES'!$A$2:$A$208,0)),"")="Inactivo"),"Unidad inactiva | ","")&IF(AND($AA8<>"",$N8=""),"Carga de batán sin litros | ","")&IF(AND($AA8<>"",$AC8<0),"Supera saldo batán | ",""))="","OK",LEFT((IF($G8="","Sin unidad | ","")&IF($J8="","Sin responsable | ","")&IF($K8="","Sin obra | ","")&IF(AND($N8<>"",$G8<>"",$N8>IFERROR(INDEX('MAESTRO DE UNIDADES'!$I$2:$I$208,MATCH($G8,'MAESTRO DE UNIDADES'!$A$2:$A$208,0)),0)),"Litros > tanque | ","")&IF(AND($W8<>"",COUNTIF($W$2:$W8,$W8)>1),"Ticket duplicado | ","")&IF(AND($G8<>"",IFERROR(INDEX('MAESTRO DE UNIDADES'!$L$2:$L$208,MATCH($G8,'MAESTRO DE UNIDADES'!$A$2:$A$208,0)),"")="Inactivo"),"Unidad inactiva | ","")&IF(AND($AA8<>"",$N8=""),"Carga de batán sin litros | ","")&IF(AND($AA8<>"",$AC8<0),"Supera saldo batán | ","")),LEN((IF($G8="","Sin unidad | ","")&IF($J8="","Sin responsable | ","")&IF($K8="","Sin obra | ","")&IF(AND($N8<>"",$G8<>"",$N8>IFERROR(INDEX('MAESTRO DE UNIDADES'!$I$2:$I$208,MATCH($G8,'MAESTRO DE UNIDADES'!$A$2:$A$208,0)),0)),"Litros > tanque | ","")&IF(AND($W8<>"",COUNTIF($W$2:$W8,$W8)>1),"Ticket duplicado | ","")&IF(AND($G8<>"",IFERROR(INDEX('MAESTRO DE UNIDADES'!$L$2:$L$208,MATCH($G8,'MAESTRO DE UNIDADES'!$A$2:$A$208,0)),"")="Inactivo"),"Unidad inactiva | ","")&IF(AND($AA8<>"",$N8=""),"Carga de batán sin litros | ","")&IF(AND($AA8<>"",$AC8<0),"Supera saldo batán | ","")))-3))) | Z8: =IF($B8="","",IF($AA8<>"","Batán","Estación de servicio"))
A9: =IF(B9="","","CARGA-"&TEXT(ROW()-1,"0000")) | C9: =IF(B9="","",CHOOSE(MONTH(B9),"Enero","Febrero","Marzo","Abril","Mayo","Junio","Julio","Agosto","Septiembre","Octubre","Noviembre","Diciembre")) | D9: =IF(B9="","",YEAR(B9)) | E9: =IF(B9="","",CHOOSE(WEEKDAY(B9,2),"Lunes","Martes","Miércoles","Jueves","Viernes","Sábado","Domingo")) | H9: =IF($G9="","",IFERROR(INDEX('MAESTRO DE UNIDADES'!$F$2:$F$208,MATCH($G9,'MAESTRO DE UNIDADES'!$A$2:$A$208,0)),"")) | I9: =IF($G9="","",IFERROR(INDEX('MAESTRO DE UNIDADES'!$B$2:$B$208,MATCH($G9,'MAESTRO DE UNIDADES'!$A$2:$A$208,0)),"")) | M9: =IF($G9="","",IFERROR(INDEX('MAESTRO DE UNIDADES'!$H$2:$H$208,MATCH($G9,'MAESTRO DE UNIDADES'!$A$2:$A$208,0)),"")) | P9: =IF($N9="","",IF($AA9<>"",IF($AB9="","",$N9*$AB9),IF($O9="","",$N9*$O9))) | S9: =IF(OR($G9="",$Q9="",COUNTIF($G$2:G8,$G9)=0),"",$Q9-LOOKUP(2,1/($G$2:G8=$G9),$Q$2:Q8)) | T9: =IF(OR($G9="",$R9="",COUNTIF($G$2:G8,$G9)=0),"",$R9-LOOKUP(2,1/($G$2:G8=$G9),$R$2:R8)) | U9: =IF(N9="","",IF(S9<>"",S9/N9,IF(T9<>"",T9/N9,""))) | Y9: =IF($B9="","",IF((IF($G9="","Sin unidad | ","")&IF($J9="","Sin responsable | ","")&IF($K9="","Sin obra | ","")&IF(AND($N9<>"",$G9<>"",$N9>IFERROR(INDEX('MAESTRO DE UNIDADES'!$I$2:$I$208,MATCH($G9,'MAESTRO DE UNIDADES'!$A$2:$A$208,0)),0)),"Litros > tanque | ","")&IF(AND($W9<>"",COUNTIF($W$2:$W9,$W9)>1),"Ticket duplicado | ","")&IF(AND($G9<>"",IFERROR(INDEX('MAESTRO DE UNIDADES'!$L$2:$L$208,MATCH($G9,'MAESTRO DE UNIDADES'!$A$2:$A$208,0)),"")="Inactivo"),"Unidad inactiva | ","")&IF(AND($AA9<>"",$N9=""),"Carga de batán sin litros | ","")&IF(AND($AA9<>"",$AC9<0),"Supera saldo batán | ",""))="","OK",LEFT((IF($G9="","Sin unidad | ","")&IF($J9="","Sin responsable | ","")&IF($K9="","Sin obra | ","")&IF(AND($N9<>"",$G9<>"",$N9>IFERROR(INDEX('MAESTRO DE UNIDADES'!$I$2:$I$208,MATCH($G9,'MAESTRO DE UNIDADES'!$A$2:$A$208,0)),0)),"Litros > tanque | ","")&IF(AND($W9<>"",COUNTIF($W$2:$W9,$W9)>1),"Ticket duplicado | ","")&IF(AND($G9<>"",IFERROR(INDEX('MAESTRO DE UNIDADES'!$L$2:$L$208,MATCH($G9,'MAESTRO DE UNIDADES'!$A$2:$A$208,0)),"")="Inactivo"),"Unidad inactiva | ","")&IF(AND($AA9<>"",$N9=""),"Carga de batán sin litros | ","")&IF(AND($AA9<>"",$AC9<0),"Supera saldo batán | ","")),LEN((IF($G9="","Sin unidad | ","")&IF($J9="","Sin responsable | ","")&IF($K9="","Sin obra | ","")&IF(AND($N9<>"",$G9<>"",$N9>IFERROR(INDEX('MAESTRO DE UNIDADES'!$I$2:$I$208,MATCH($G9,'MAESTRO DE UNIDADES'!$A$2:$A$208,0)),0)),"Litros > tanque | ","")&IF(AND($W9<>"",COUNTIF($W$2:$W9,$W9)>1),"Ticket duplicado | ","")&IF(AND($G9<>"",IFERROR(INDEX('MAESTRO DE UNIDADES'!$L$2:$L$208,MATCH($G9,'MAESTRO DE UNIDADES'!$A$2:$A$208,0)),"")="Inactivo"),"Unidad inactiva | ","")&IF(AND($AA9<>"",$N9=""),"Carga de batán sin litros | ","")&IF(AND($AA9<>"",$AC9<0),"Supera saldo batán | ","")))-3))) | Z9: =IF($B9="","",IF($AA9<>"","Batán","Estación de servicio"))
A10: =IF(B10="","","CARGA-"&TEXT(ROW()-1,"0000")) | C10: =IF(B10="","",CHOOSE(MONTH(B10),"Enero","Febrero","Marzo","Abril","Mayo","Junio","Julio","Agosto","Septiembre","Octubre","Noviembre","Diciembre")) | D10: =IF(B10="","",YEAR(B10)) | E10: =IF(B10="","",CHOOSE(WEEKDAY(B10,2),"Lunes","Martes","Miércoles","Jueves","Viernes","Sábado","Domingo")) | H10: =IF($G10="","",IFERROR(INDEX('MAESTRO DE UNIDADES'!$F$2:$F$208,MATCH($G10,'MAESTRO DE UNIDADES'!$A$2:$A$208,0)),"")) | I10: =IF($G10="","",IFERROR(INDEX('MAESTRO DE UNIDADES'!$B$2:$B$208,MATCH($G10,'MAESTRO DE UNIDADES'!$A$2:$A$208,0)),"")) | M10: =IF($G10="","",IFERROR(INDEX('MAESTRO DE UNIDADES'!$H$2:$H$208,MATCH($G10,'MAESTRO DE UNIDADES'!$A$2:$A$208,0)),"")) | P10: =IF($N10="","",IF($AA10<>"",IF($AB10="","",$N10*$AB10),IF($O10="","",$N10*$O10))) | S10: =IF(OR($G10="",$Q10="",COUNTIF($G$2:G9,$G10)=0),"",$Q10-LOOKUP(2,1/($G$2:G9=$G10),$Q$2:Q9)) | T10: =IF(OR($G10="",$R10="",COUNTIF($G$2:G9,$G10)=0),"",$R10-LOOKUP(2,1/($G$2:G9=$G10),$R$2:R9)) | U10: =IF(N10="","",IF(S10<>"",S10/N10,IF(T10<>"",T10/N10,""))) | Y10: =IF($B10="","",IF((IF($G10="","Sin unidad | ","")&IF($J10="","Sin responsable | ","")&IF($K10="","Sin obra | ","")&IF(AND($N10<>"",$G10<>"",$N10>IFERROR(INDEX('MAESTRO DE UNIDADES'!$I$2:$I$208,MATCH($G10,'MAESTRO DE UNIDADES'!$A$2:$A$208,0)),0)),"Litros > tanque | ","")&IF(AND($W10<>"",COUNTIF($W$2:$W10,$W10)>1),"Ticket duplicado | ","")&IF(AND($G10<>"",IFERROR(INDEX('MAESTRO DE UNIDADES'!$L$2:$L$208,MATCH($G10,'MAESTRO DE UNIDADES'!$A$2:$A$208,0)),"")="Inactivo"),"Unidad inactiva | ","")&IF(AND($AA10<>"",$N10=""),"Carga de batán sin litros | ","")&IF(AND($AA10<>"",$AC10<0),"Supera saldo batán | ",""))="","OK",LEFT((IF($G10="","Sin unidad | ","")&IF($J10="","Sin responsable | ","")&IF($K10="","Sin obra | ","")&IF(AND($N10<>"",$G10<>"",$N10>IFERROR(INDEX('MAESTRO DE UNIDADES'!$I$2:$I$208,MATCH($G10,'MAESTRO DE UNIDADES'!$A$2:$A$208,0)),0)),"Litros > tanque | ","")&IF(AND($W10<>"",COUNTIF($W$2:$W10,$W10)>1),"Ticket duplicado | ","")&IF(AND($G10<>"",IFERROR(INDEX('MAESTRO DE UNIDADES'!$L$2:$L$208,MATCH($G10,'MAESTRO DE UNIDADES'!$A$2:$A$208,0)),"")="Inactivo"),"Unidad inactiva | ","")&IF(AND($AA10<>"",$N10=""),"Carga de batán sin litros | ","")&IF(AND($AA10<>"",$AC10<0),"Supera saldo batán | ","")),LEN((IF($G10="","Sin unidad | ","")&IF($J10="","Sin responsable | ","")&IF($K10="","Sin obra | ","")&IF(AND($N10<>"",$G10<>"",$N10>IFERROR(INDEX('MAESTRO DE UNIDADES'!$I$2:$I$208,MATCH($G10,'MAESTRO DE UNIDADES'!$A$2:$A$208,0)),0)),"Litros > tanque | ","")&IF(AND($W10<>"",COUNTIF($W$2:$W10,$W10)>1),"Ticket duplicado | ","")&IF(AND($G10<>"",IFERROR(INDEX('MAESTRO DE UNIDADES'!$L$2:$L$208,MATCH($G10,'MAESTRO DE UNIDADES'!$A$2:$A$208,0)),"")="Inactivo"),"Unidad inactiva | ","")&IF(AND($AA10<>"",$N10=""),"Carga de batán sin litros | ","")&IF(AND($AA10<>"",$AC10<0),"Supera saldo batán | ","")))-3))) | Z10: =IF($B10="","",IF($AA10<>"","Batán","Estación de servicio"))
A11: =IF(B11="","","CARGA-"&TEXT(ROW()-1,"0000")) | C11: =IF(B11="","",CHOOSE(MONTH(B11),"Enero","Febrero","Marzo","Abril","Mayo","Junio","Julio","Agosto","Septiembre","Octubre","Noviembre","Diciembre")) | D11: =IF(B11="","",YEAR(B11)) | E11: =IF(B11="","",CHOOSE(WEEKDAY(B11,2),"Lunes","Martes","Miércoles","Jueves","Viernes","Sábado","Domingo")) | H11: =IF($G11="","",IFERROR(INDEX('MAESTRO DE UNIDADES'!$F$2:$F$208,MATCH($G11,'MAESTRO DE UNIDADES'!$A$2:$A$208,0)),"")) | I11: =IF($G11="","",IFERROR(INDEX('MAESTRO DE UNIDADES'!$B$2:$B$208,MATCH($G11,'MAESTRO DE UNIDADES'!$A$2:$A$208,0)),"")) | M11: =IF($G11="","",IFERROR(INDEX('MAESTRO DE UNIDADES'!$H$2:$H$208,MATCH($G11,'MAESTRO DE UNIDADES'!$A$2:$A$208,0)),"")) | P11: =IF($N11="","",IF($AA11<>"",IF($AB11="","",$N11*$AB11),IF($O11="","",$N11*$O11))) | S11: =IF(OR($G11="",$Q11="",COUNTIF($G$2:G10,$G11)=0),"",$Q11-LOOKUP(2,1/($G$2:G10=$G11),$Q$2:Q10)) | T11: =IF(OR($G11="",$R11="",COUNTIF($G$2:G10,$G11)=0),"",$R11-LOOKUP(2,1/($G$2:G10=$G11),$R$2:R10)) | U11: =IF(N11="","",IF(S11<>"",S11/N11,IF(T11<>"",T11/N11,""))) | Y11: =IF($B11="","",IF((IF($G11="","Sin unidad | ","")&IF($J11="","Sin responsable | ","")&IF($K11="","Sin obra | ","")&IF(AND($N11<>"",$G11<>"",$N11>IFERROR(INDEX('MAESTRO DE UNIDADES'!$I$2:$I$208,MATCH($G11,'MAESTRO DE UNIDADES'!$A$2:$A$208,0)),0)),"Litros > tanque | ","")&IF(AND($W11<>"",COUNTIF($W$2:$W11,$W11)>1),"Ticket duplicado | ","")&IF(AND($G11<>"",IFERROR(INDEX('MAESTRO DE UNIDADES'!$L$2:$L$208,MATCH($G11,'MAESTRO DE UNIDADES'!$A$2:$A$208,0)),"")="Inactivo"),"Unidad inactiva | ","")&IF(AND($AA11<>"",$N11=""),"Carga de batán sin litros | ","")&IF(AND($AA11<>"",$AC11<0),"Supera saldo batán | ",""))="","OK",LEFT((IF($G11="","Sin unidad | ","")&IF($J11="","Sin responsable | ","")&IF($K11="","Sin obra | ","")&IF(AND($N11<>"",$G11<>"",$N11>IFERROR(INDEX('MAESTRO DE UNIDADES'!$I$2:$I$208,MATCH($G11,'MAESTRO DE UNIDADES'!$A$2:$A$208,0)),0)),"Litros > tanque | ","")&IF(AND($W11<>"",COUNTIF($W$2:$W11,$W11)>1),"Ticket duplicado | ","")&IF(AND($G11<>"",IFERROR(INDEX('MAESTRO DE UNIDADES'!$L$2:$L$208,MATCH($G11,'MAESTRO DE UNIDADES'!$A$2:$A$208,0)),"")="Inactivo"),"Unidad inactiva | ","")&IF(AND($AA11<>"",$N11=""),"Carga de batán sin litros | ","")&IF(AND($AA11<>"",$AC11<0),"Supera saldo batán | ","")),LEN((IF($G11="","Sin unidad | ","")&IF($J11="","Sin responsable | ","")&IF($K11="","Sin obra | ","")&IF(AND($N11<>"",$G11<>"",$N11>IFERROR(INDEX('MAESTRO DE UNIDADES'!$I$2:$I$208,MATCH($G11,'MAESTRO DE UNIDADES'!$A$2:$A$208,0)),0)),"Litros > tanque | ","")&IF(AND($W11<>"",COUNTIF($W$2:$W11,$W11)>1),"Ticket duplicado | ","")&IF(AND($G11<>"",IFERROR(INDEX('MAESTRO DE UNIDADES'!$L$2:$L$208,MATCH($G11,'MAESTRO DE UNIDADES'!$A$2:$A$208,0)),"")="Inactivo"),"Unidad inactiva | ","")&IF(AND($AA11<>"",$N11=""),"Carga de batán sin litros | ","")&IF(AND($AA11<>"",$AC11<0),"Supera saldo batán | ","")))-3))) | Z11: =IF($B11="","",IF($AA11<>"","Batán","Estación de servicio"))
A12: =IF(B12="","","CARGA-"&TEXT(ROW()-1,"0000")) | C12: =IF(B12="","",CHOOSE(MONTH(B12),"Enero","Febrero","Marzo","Abril","Mayo","Junio","Julio","Agosto","Septiembre","Octubre","Noviembre","Diciembre")) | D12: =IF(B12="","",YEAR(B12)) | E12: =IF(B12="","",CHOOSE(WEEKDAY(B12,2),"Lunes","Martes","Miércoles","Jueves","Viernes","Sábado","Domingo")) | H12: =IF($G12="","",IFERROR(INDEX('MAESTRO DE UNIDADES'!$F$2:$F$208,MATCH($G12,'MAESTRO DE UNIDADES'!$A$2:$A$208,0)),"")) | I12: =IF($G12="","",IFERROR(INDEX('MAESTRO DE UNIDADES'!$B$2:$B$208,MATCH($G12,'MAESTRO DE UNIDADES'!$A$2:$A$208,0)),"")) | M12: =IF($G12="","",IFERROR(INDEX('MAESTRO DE UNIDADES'!$H$2:$H$208,MATCH($G12,'MAESTRO DE UNIDADES'!$A$2:$A$208,0)),"")) | P12: =IF($N12="","",IF($AA12<>"",IF($AB12="","",$N12*$AB12),IF($O12="","",$N12*$O12))) | S12: =IF(OR($G12="",$Q12="",COUNTIF($G$2:G11,$G12)=0),"",$Q12-LOOKUP(2,1/($G$2:G11=$G12),$Q$2:Q11)) | T12: =IF(OR($G12="",$R12="",COUNTIF($G$2:G11,$G12)=0),"",$R12-LOOKUP(2,1/($G$2:G11=$G12),$R$2:R11)) | U12: =IF(N12="","",IF(S12<>"",S12/N12,IF(T12<>"",T12/N12,""))) | Y12: =IF($B12="","",IF((IF($G12="","Sin unidad | ","")&IF($J12="","Sin responsable | ","")&IF($K12="","Sin obra | ","")&IF(AND($N12<>"",$G12<>"",$N12>IFERROR(INDEX('MAESTRO DE UNIDADES'!$I$2:$I$208,MATCH($G12,'MAESTRO DE UNIDADES'!$A$2:$A$208,0)),0)),"Litros > tanque | ","")&IF(AND($W12<>"",COUNTIF($W$2:$W12,$W12)>1),"Ticket duplicado | ","")&IF(AND($G12<>"",IFERROR(INDEX('MAESTRO DE UNIDADES'!$L$2:$L$208,MATCH($G12,'MAESTRO DE UNIDADES'!$A$2:$A$208,0)),"")="Inactivo"),"Unidad inactiva | ","")&IF(AND($AA12<>"",$N12=""),"Carga de batán sin litros | ","")&IF(AND($AA12<>"",$AC12<0),"Supera saldo batán | ",""))="","OK",LEFT((IF($G12="","Sin unidad | ","")&IF($J12="","Sin responsable | ","")&IF($K12="","Sin obra | ","")&IF(AND($N12<>"",$G12<>"",$N12>IFERROR(INDEX('MAESTRO DE UNIDADES'!$I$2:$I$208,MATCH($G12,'MAESTRO DE UNIDADES'!$A$2:$A$208,0)),0)),"Litros > tanque | ","")&IF(AND($W12<>"",COUNTIF($W$2:$W12,$W12)>1),"Ticket duplicado | ","")&IF(AND($G12<>"",IFERROR(INDEX('MAESTRO DE UNIDADES'!$L$2:$L$208,MATCH($G12,'MAESTRO DE UNIDADES'!$A$2:$A$208,0)),"")="Inactivo"),"Unidad inactiva | ","")&IF(AND($AA12<>"",$N12=""),"Carga de batán sin litros | ","")&IF(AND($AA12<>"",$AC12<0),"Supera saldo batán | ","")),LEN((IF($G12="","Sin unidad | ","")&IF($J12="","Sin responsable | ","")&IF($K12="","Sin obra | ","")&IF(AND($N12<>"",$G12<>"",$N12>IFERROR(INDEX('MAESTRO DE UNIDADES'!$I$2:$I$208,MATCH($G12,'MAESTRO DE UNIDADES'!$A$2:$A$208,0)),0)),"Litros > tanque | ","")&IF(AND($W12<>"",COUNTIF($W$2:$W12,$W12)>1),"Ticket duplicado | ","")&IF(AND($G12<>"",IFERROR(INDEX('MAESTRO DE UNIDADES'!$L$2:$L$208,MATCH($G12,'MAESTRO DE UNIDADES'!$A$2:$A$208,0)),"")="Inactivo"),"Unidad inactiva | ","")&IF(AND($AA12<>"",$N12=""),"Carga de batán sin litros | ","")&IF(AND($AA12<>"",$AC12<0),"Supera saldo batán | ","")))-3))) | Z12: =IF($B12="","",IF($AA12<>"","Batán","Estación de servicio"))
A13: =IF(B13="","","CARGA-"&TEXT(ROW()-1,"0000")) | C13: =IF(B13="","",CHOOSE(MONTH(B13),"Enero","Febrero","Marzo","Abril","Mayo","Junio","Julio","Agosto","Septiembre","Octubre","Noviembre","Diciembre")) | D13: =IF(B13="","",YEAR(B13)) | E13: =IF(B13="","",CHOOSE(WEEKDAY(B13,2),"Lunes","Martes","Miércoles","Jueves","Viernes","Sábado","Domingo")) | H13: =IF($G13="","",IFERROR(INDEX('MAESTRO DE UNIDADES'!$F$2:$F$208,MATCH($G13,'MAESTRO DE UNIDADES'!$A$2:$A$208,0)),"")) | I13: =IF($G13="","",IFERROR(INDEX('MAESTRO DE UNIDADES'!$B$2:$B$208,MATCH($G13,'MAESTRO DE UNIDADES'!$A$2:$A$208,0)),"")) | M13: =IF($G13="","",IFERROR(INDEX('MAESTRO DE UNIDADES'!$H$2:$H$208,MATCH($G13,'MAESTRO DE UNIDADES'!$A$2:$A$208,0)),"")) | P13: =IF($N13="","",IF($AA13<>"",IF($AB13="","",$N13*$AB13),IF($O13="","",$N13*$O13))) | S13: =IF(OR($G13="",$Q13="",COUNTIF($G$2:G12,$G13)=0),"",$Q13-LOOKUP(2,1/($G$2:G12=$G13),$Q$2:Q12)) | T13: =IF(OR($G13="",$R13="",COUNTIF($G$2:G12,$G13)=0),"",$R13-LOOKUP(2,1/($G$2:G12=$G13),$R$2:R12)) | U13: =IF(N13="","",IF(S13<>"",S13/N13,IF(T13<>"",T13/N13,""))) | Y13: =IF($B13="","",IF((IF($G13="","Sin unidad | ","")&IF($J13="","Sin responsable | ","")&IF($K13="","Sin obra | ","")&IF(AND($N13<>"",$G13<>"",$N13>IFERROR(INDEX('MAESTRO DE UNIDADES'!$I$2:$I$208,MATCH($G13,'MAESTRO DE UNIDADES'!$A$2:$A$208,0)),0)),"Litros > tanque | ","")&IF(AND($W13<>"",COUNTIF($W$2:$W13,$W13)>1),"Ticket duplicado | ","")&IF(AND($G13<>"",IFERROR(INDEX('MAESTRO DE UNIDADES'!$L$2:$L$208,MATCH($G13,'MAESTRO DE UNIDADES'!$A$2:$A$208,0)),"")="Inactivo"),"Unidad inactiva | ","")&IF(AND($AA13<>"",$N13=""),"Carga de batán sin litros | ","")&IF(AND($AA13<>"",$AC13<0),"Supera saldo batán | ",""))="","OK",LEFT((IF($G13="","Sin unidad | ","")&IF($J13="","Sin responsable | ","")&IF($K13="","Sin obra | ","")&IF(AND($N13<>"",$G13<>"",$N13>IFERROR(INDEX('MAESTRO DE UNIDADES'!$I$2:$I$208,MATCH($G13,'MAESTRO DE UNIDADES'!$A$2:$A$208,0)),0)),"Litros > tanque | ","")&IF(AND($W13<>"",COUNTIF($W$2:$W13,$W13)>1),"Ticket duplicado | ","")&IF(AND($G13<>"",IFERROR(INDEX('MAESTRO DE UNIDADES'!$L$2:$L$208,MATCH($G13,'MAESTRO DE UNIDADES'!$A$2:$A$208,0)),"")="Inactivo"),"Unidad inactiva | ","")&IF(AND($AA13<>"",$N13=""),"Carga de batán sin litros | ","")&IF(AND($AA13<>"",$AC13<0),"Supera saldo batán | ","")),LEN((IF($G13="","Sin unidad | ","")&IF($J13="","Sin responsable | ","")&IF($K13="","Sin obra | ","")&IF(AND($N13<>"",$G13<>"",$N13>IFERROR(INDEX('MAESTRO DE UNIDADES'!$I$2:$I$208,MATCH($G13,'MAESTRO DE UNIDADES'!$A$2:$A$208,0)),0)),"Litros > tanque | ","")&IF(AND($W13<>"",COUNTIF($W$2:$W13,$W13)>1),"Ticket duplicado | ","")&IF(AND($G13<>"",IFERROR(INDEX('MAESTRO DE UNIDADES'!$L$2:$L$208,MATCH($G13,'MAESTRO DE UNIDADES'!$A$2:$A$208,0)),"")="Inactivo"),"Unidad inactiva | ","")&IF(AND($AA13<>"",$N13=""),"Carga de batán sin litros | ","")&IF(AND($AA13<>"",$AC13<0),"Supera saldo batán | ","")))-3))) | Z13: =IF($B13="","",IF($AA13<>"","Batán","Estación de servicio"))
A14: =IF(B14="","","CARGA-"&TEXT(ROW()-1,"0000")) | C14: =IF(B14="","",CHOOSE(MONTH(B14),"Enero","Febrero","Marzo","Abril","Mayo","Junio","Julio","Agosto","Septiembre","Octubre","Noviembre","Diciembre")) | D14: =IF(B14="","",YEAR(B14)) | E14: =IF(B14="","",CHOOSE(WEEKDAY(B14,2),"Lunes","Martes","Miércoles","Jueves","Viernes","Sábado","Domingo")) | H14: =IF($G14="","",IFERROR(INDEX('MAESTRO DE UNIDADES'!$F$2:$F$208,MATCH($G14,'MAESTRO DE UNIDADES'!$A$2:$A$208,0)),"")) | I14: =IF($G14="","",IFERROR(INDEX('MAESTRO DE UNIDADES'!$B$2:$B$208,MATCH($G14,'MAESTRO DE UNIDADES'!$A$2:$A$208,0)),"")) | M14: =IF($G14="","",IFERROR(INDEX('MAESTRO DE UNIDADES'!$H$2:$H$208,MATCH($G14,'MAESTRO DE UNIDADES'!$A$2:$A$208,0)),"")) | P14: =IF($N14="","",IF($AA14<>"",IF($AB14="","",$N14*$AB14),IF($O14="","",$N14*$O14))) | S14: =IF(OR($G14="",$Q14="",COUNTIF($G$2:G13,$G14)=0),"",$Q14-LOOKUP(2,1/($G$2:G13=$G14),$Q$2:Q13)) | T14: =IF(OR($G14="",$R14="",COUNTIF($G$2:G13,$G14)=0),"",$R14-LOOKUP(2,1/($G$2:G13=$G14),$R$2:R13)) | U14: =IF(N14="","",IF(S14<>"",S14/N14,IF(T14<>"",T14/N14,""))) | Y14: =IF($B14="","",IF((IF($G14="","Sin unidad | ","")&IF($J14="","Sin responsable | ","")&IF($K14="","Sin obra | ","")&IF(AND($N14<>"",$G14<>"",$N14>IFERROR(INDEX('MAESTRO DE UNIDADES'!$I$2:$I$208,MATCH($G14,'MAESTRO DE UNIDADES'!$A$2:$A$208,0)),0)),"Litros > tanque | ","")&IF(AND($W14<>"",COUNTIF($W$2:$W14,$W14)>1),"Ticket duplicado | ","")&IF(AND($G14<>"",IFERROR(INDEX('MAESTRO DE UNIDADES'!$L$2:$L$208,MATCH($G14,'MAESTRO DE UNIDADES'!$A$2:$A$208,0)),"")="Inactivo"),"Unidad inactiva | ","")&IF(AND($AA14<>"",$N14=""),"Carga de batán sin litros | ","")&IF(AND($AA14<>"",$AC14<0),"Supera saldo batán | ",""))="","OK",LEFT((IF($G14="","Sin unidad | ","")&IF($J14="","Sin responsable | ","")&IF($K14="","Sin obra | ","")&IF(AND($N14<>"",$G14<>"",$N14>IFERROR(INDEX('MAESTRO DE UNIDADES'!$I$2:$I$208,MATCH($G14,'MAESTRO DE UNIDADES'!$A$2:$A$208,0)),0)),"Litros > tanque | ","")&IF(AND($W14<>"",COUNTIF($W$2:$W14,$W14)>1),"Ticket duplicado | ","")&IF(AND($G14<>"",IFERROR(INDEX('MAESTRO DE UNIDADES'!$L$2:$L$208,MATCH($G14,'MAESTRO DE UNIDADES'!$A$2:$A$208,0)),"")="Inactivo"),"Unidad inactiva | ","")&IF(AND($AA14<>"",$N14=""),"Carga de batán sin litros | ","")&IF(AND($AA14<>"",$AC14<0),"Supera saldo batán | ","")),LEN((IF($G14="","Sin unidad | ","")&IF($J14="","Sin responsable | ","")&IF($K14="","Sin obra | ","")&IF(AND($N14<>"",$G14<>"",$N14>IFERROR(INDEX('MAESTRO DE UNIDADES'!$I$2:$I$208,MATCH($G14,'MAESTRO DE UNIDADES'!$A$2:$A$208,0)),0)),"Litros > tanque | ","")&IF(AND($W14<>"",COUNTIF($W$2:$W14,$W14)>1),"Ticket duplicado | ","")&IF(AND($G14<>"",IFERROR(INDEX('MAESTRO DE UNIDADES'!$L$2:$L$208,MATCH($G14,'MAESTRO DE UNIDADES'!$A$2:$A$208,0)),"")="Inactivo"),"Unidad inactiva | ","")&IF(AND($AA14<>"",$N14=""),"Carga de batán sin litros | ","")&IF(AND($AA14<>"",$AC14<0),"Supera saldo batán | ","")))-3))) | Z14: =IF($B14="","",IF($AA14<>"","Batán","Estación de servicio"))
A15: =IF(B15="","","CARGA-"&TEXT(ROW()-1,"0000")) | C15: =IF(B15="","",CHOOSE(MONTH(B15),"Enero","Febrero","Marzo","Abril","Mayo","Junio","Julio","Agosto","Septiembre","Octubre","Noviembre","Diciembre")) | D15: =IF(B15="","",YEAR(B15)) | E15: =IF(B15="","",CHOOSE(WEEKDAY(B15,2),"Lunes","Martes","Miércoles","Jueves","Viernes","Sábado","Domingo")) | H15: =IF($G15="","",IFERROR(INDEX('MAESTRO DE UNIDADES'!$F$2:$F$208,MATCH($G15,'MAESTRO DE UNIDADES'!$A$2:$A$208,0)),"")) | I15: =IF($G15="","",IFERROR(INDEX('MAESTRO DE UNIDADES'!$B$2:$B$208,MATCH($G15,'MAESTRO DE UNIDADES'!$A$2:$A$208,0)),"")) | M15: =IF($G15="","",IFERROR(INDEX('MAESTRO DE UNIDADES'!$H$2:$H$208,MATCH($G15,'MAESTRO DE UNIDADES'!$A$2:$A$208,0)),"")) | P15: =IF($N15="","",IF($AA15<>"",IF($AB15="","",$N15*$AB15),IF($O15="","",$N15*$O15))) | S15: =IF(OR($G15="",$Q15="",COUNTIF($G$2:G14,$G15)=0),"",$Q15-LOOKUP(2,1/($G$2:G14=$G15),$Q$2:Q14)) | T15: =IF(OR($G15="",$R15="",COUNTIF($G$2:G14,$G15)=0),"",$R15-LOOKUP(2,1/($G$2:G14=$G15),$R$2:R14)) | U15: =IF(N15="","",IF(S15<>"",S15/N15,IF(T15<>"",T15/N15,""))) | Y15: =IF($B15="","",IF((IF($G15="","Sin unidad | ","")&IF($J15="","Sin responsable | ","")&IF($K15="","Sin obra | ","")&IF(AND($N15<>"",$G15<>"",$N15>IFERROR(INDEX('MAESTRO DE UNIDADES'!$I$2:$I$208,MATCH($G15,'MAESTRO DE UNIDADES'!$A$2:$A$208,0)),0)),"Litros > tanque | ","")&IF(AND($W15<>"",COUNTIF($W$2:$W15,$W15)>1),"Ticket duplicado | ","")&IF(AND($G15<>"",IFERROR(INDEX('MAESTRO DE UNIDADES'!$L$2:$L$208,MATCH($G15,'MAESTRO DE UNIDADES'!$A$2:$A$208,0)),"")="Inactivo"),"Unidad inactiva | ","")&IF(AND($AA15<>"",$N15=""),"Carga de batán sin litros | ","")&IF(AND($AA15<>"",$AC15<0),"Supera saldo batán | ",""))="","OK",LEFT((IF($G15="","Sin unidad | ","")&IF($J15="","Sin responsable | ","")&IF($K15="","Sin obra | ","")&IF(AND($N15<>"",$G15<>"",$N15>IFERROR(INDEX('MAESTRO DE UNIDADES'!$I$2:$I$208,MATCH($G15,'MAESTRO DE UNIDADES'!$A$2:$A$208,0)),0)),"Litros > tanque | ","")&IF(AND($W15<>"",COUNTIF($W$2:$W15,$W15)>1),"Ticket duplicado | ","")&IF(AND($G15<>"",IFERROR(INDEX('MAESTRO DE UNIDADES'!$L$2:$L$208,MATCH($G15,'MAESTRO DE UNIDADES'!$A$2:$A$208,0)),"")="Inactivo"),"Unidad inactiva | ","")&IF(AND($AA15<>"",$N15=""),"Carga de batán sin litros | ","")&IF(AND($AA15<>"",$AC15<0),"Supera saldo batán | ","")),LEN((IF($G15="","Sin unidad | ","")&IF($J15="","Sin responsable | ","")&IF($K15="","Sin obra | ","")&IF(AND($N15<>"",$G15<>"",$N15>IFERROR(INDEX('MAESTRO DE UNIDADES'!$I$2:$I$208,MATCH($G15,'MAESTRO DE UNIDADES'!$A$2:$A$208,0)),0)),"Litros > tanque | ","")&IF(AND($W15<>"",COUNTIF($W$2:$W15,$W15)>1),"Ticket duplicado | ","")&IF(AND($G15<>"",IFERROR(INDEX('MAESTRO DE UNIDADES'!$L$2:$L$208,MATCH($G15,'MAESTRO DE UNIDADES'!$A$2:$A$208,0)),"")="Inactivo"),"Unidad inactiva | ","")&IF(AND($AA15<>"",$N15=""),"Carga de batán sin litros | ","")&IF(AND($AA15<>"",$AC15<0),"Supera saldo batán | ","")))-3))) | Z15: =IF($B15="","",IF($AA15<>"","Batán","Estación de servicio"))
A16: =IF(B16="","","CARGA-"&TEXT(ROW()-1,"0000")) | C16: =IF(B16="","",CHOOSE(MONTH(B16),"Enero","Febrero","Marzo","Abril","Mayo","Junio","Julio","Agosto","Septiembre","Octubre","Noviembre","Diciembre")) | D16: =IF(B16="","",YEAR(B16)) | E16: =IF(B16="","",CHOOSE(WEEKDAY(B16,2),"Lunes","Martes","Miércoles","Jueves","Viernes","Sábado","Domingo")) | I16: =IF($G16="","",IFERROR(INDEX('MAESTRO DE UNIDADES'!$B$2:$B$208,MATCH($G16,'MAESTRO DE UNIDADES'!$A$2:$A$208,0)),"")) | M16: =IF($G16="","",IFERROR(INDEX('MAESTRO DE UNIDADES'!$H$2:$H$208,MATCH($G16,'MAESTRO DE UNIDADES'!$A$2:$A$208,0)),"")) | P16: =IF($N16="","",IF($AA16<>"",IF($AB16="","",$N16*$AB16),IF($O16="","",$N16*$O16))) | S16: =IF(OR($G16="",$Q16="",COUNTIF($G$2:G15,$G16)=0),"",$Q16-LOOKUP(2,1/($G$2:G15=$G16),$Q$2:Q15)) | T16: =IF(OR($G16="",$R16="",COUNTIF($G$2:G15,$G16)=0),"",$R16-LOOKUP(2,1/($G$2:G15=$G16),$R$2:R15)) | U16: =IF(N16="","",IF(S16<>"",S16/N16,IF(T16<>"",T16/N16,""))) | Y16: =IF($B16="","",IF((IF($G16="","Sin unidad | ","")&IF($J16="","Sin responsable | ","")&IF($K16="","Sin obra | ","")&IF(AND($N16<>"",$G16<>"",$N16>IFERROR(INDEX('MAESTRO DE UNIDADES'!$I$2:$I$208,MATCH($G16,'MAESTRO DE UNIDADES'!$A$2:$A$208,0)),0)),"Litros > tanque | ","")&IF(AND($W16<>"",COUNTIF($W$2:$W16,$W16)>1),"Ticket duplicado | ","")&IF(AND($G16<>"",IFERROR(INDEX('MAESTRO DE UNIDADES'!$L$2:$L$208,MATCH($G16,'MAESTRO DE UNIDADES'!$A$2:$A$208,0)),"")="Inactivo"),"Unidad inactiva | ","")&IF(AND($AA16<>"",$N16=""),"Carga de batán sin litros | ","")&IF(AND($AA16<>"",$AC16<0),"Supera saldo batán | ",""))="","OK",LEFT((IF($G16="","Sin unidad | ","")&IF($J16="","Sin responsable | ","")&IF($K16="","Sin obra | ","")&IF(AND($N16<>"",$G16<>"",$N16>IFERROR(INDEX('MAESTRO DE UNIDADES'!$I$2:$I$208,MATCH($G16,'MAESTRO DE UNIDADES'!$A$2:$A$208,0)),0)),"Litros > tanque | ","")&IF(AND($W16<>"",COUNTIF($W$2:$W16,$W16)>1),"Ticket duplicado | ","")&IF(AND($G16<>"",IFERROR(INDEX('MAESTRO DE UNIDADES'!$L$2:$L$208,MATCH($G16,'MAESTRO DE UNIDADES'!$A$2:$A$208,0)),"")="Inactivo"),"Unidad inactiva | ","")&IF(AND($AA16<>"",$N16=""),"Carga de batán sin litros | ","")&IF(AND($AA16<>"",$AC16<0),"Supera saldo batán | ","")),LEN((IF($G16="","Sin unidad | ","")&IF($J16="","Sin responsable | ","")&IF($K16="","Sin obra | ","")&IF(AND($N16<>"",$G16<>"",$N16>IFERROR(INDEX('MAESTRO DE UNIDADES'!$I$2:$I$208,MATCH($G16,'MAESTRO DE UNIDADES'!$A$2:$A$208,0)),0)),"Litros > tanque | ","")&IF(AND($W16<>"",COUNTIF($W$2:$W16,$W16)>1),"Ticket duplicado | ","")&IF(AND($G16<>"",IFERROR(INDEX('MAESTRO DE UNIDADES'!$L$2:$L$208,MATCH($G16,'MAESTRO DE UNIDADES'!$A$2:$A$208,0)),"")="Inactivo"),"Unidad inactiva | ","")&IF(AND($AA16<>"",$N16=""),"Carga de batán sin litros | ","")&IF(AND($AA16<>"",$AC16<0),"Supera saldo batán | ","")))-3))) | Z16: =IF($B16="","",IF($AA16<>"","Batán","Estación de servicio")) | AB16: =IF($AA16="","",IFERROR(INDEX('CONTROL DE BATAN'!$J$2:$J$301,MATCH($AA16,'CONTROL DE BATAN'!$A$2:$A$301,0)),"")) | AC16: =IF($AA16="","",IFERROR(INDEX('CONTROL DE BATAN'!$I$2:$I$301,MATCH($AA16,'CONTROL DE BATAN'!$A$2:$A$301,0)),0)-SUMIFS($N$2:$N16,$AA$2:$AA16,$AA16))
A17: =IF(B17="","","CARGA-"&TEXT(ROW()-1,"0000")) | C17: =IF(B17="","",CHOOSE(MONTH(B17),"Enero","Febrero","Marzo","Abril","Mayo","Junio","Julio","Agosto","Septiembre","Octubre","Noviembre","Diciembre")) | D17: =IF(B17="","",YEAR(B17)) | E17: =IF(B17="","",CHOOSE(WEEKDAY(B17,2),"Lunes","Martes","Miércoles","Jueves","Viernes","Sábado","Domingo")) | H17: =IF($G17="","",IFERROR(INDEX('MAESTRO DE UNIDADES'!$F$2:$F$208,MATCH($G17,'MAESTRO DE UNIDADES'!$A$2:$A$208,0)),"")) | I17: =IF($G17="","",IFERROR(INDEX('MAESTRO DE UNIDADES'!$B$2:$B$208,MATCH($G17,'MAESTRO DE UNIDADES'!$A$2:$A$208,0)),"")) | M17: =IF($G17="","",IFERROR(INDEX('MAESTRO DE UNIDADES'!$H$2:$H$208,MATCH($G17,'MAESTRO DE UNIDADES'!$A$2:$A$208,0)),"")) | P17: =IF($N17="","",IF($AA17<>"",IF($AB17="","",$N17*$AB17),IF($O17="","",$N17*$O17))) | S17: =IF(OR($G17="",$Q17="",COUNTIF($G$2:G16,$G17)=0),"",$Q17-LOOKUP(2,1/($G$2:G16=$G17),$Q$2:Q16)) | T17: =IF(OR($G17="",$R17="",COUNTIF($G$2:G16,$G17)=0),"",$R17-LOOKUP(2,1/($G$2:G16=$G17),$R$2:R16)) | U17: =IF(N17="","",IF(S17<>"",S17/N17,IF(T17<>"",T17/N17,""))) | Y17: =IF($B17="","",IF((IF($G17="","Sin unidad | ","")&IF($J17="","Sin responsable | ","")&IF($K17="","Sin obra | ","")&IF(AND($N17<>"",$G17<>"",$N17>IFERROR(INDEX('MAESTRO DE UNIDADES'!$I$2:$I$208,MATCH($G17,'MAESTRO DE UNIDADES'!$A$2:$A$208,0)),0)),"Litros > tanque | ","")&IF(AND($W17<>"",COUNTIF($W$2:$W17,$W17)>1),"Ticket duplicado | ","")&IF(AND($G17<>"",IFERROR(INDEX('MAESTRO DE UNIDADES'!$L$2:$L$208,MATCH($G17,'MAESTRO DE UNIDADES'!$A$2:$A$208,0)),"")="Inactivo"),"Unidad inactiva | ","")&IF(AND($AA17<>"",$N17=""),"Carga de batán sin litros | ","")&IF(AND($AA17<>"",$AC17<0),"Supera saldo batán | ",""))="","OK",LEFT((IF($G17="","Sin unidad | ","")&IF($J17="","Sin responsable | ","")&IF($K17="","Sin obra | ","")&IF(AND($N17<>"",$G17<>"",$N17>IFERROR(INDEX('MAESTRO DE UNIDADES'!$I$2:$I$208,MATCH($G17,'MAESTRO DE UNIDADES'!$A$2:$A$208,0)),0)),"Litros > tanque | ","")&IF(AND($W17<>"",COUNTIF($W$2:$W17,$W17)>1),"Ticket duplicado | ","")&IF(AND($G17<>"",IFERROR(INDEX('MAESTRO DE UNIDADES'!$L$2:$L$208,MATCH($G17,'MAESTRO DE UNIDADES'!$A$2:$A$208,0)),"")="Inactivo"),"Unidad inactiva | ","")&IF(AND($AA17<>"",$N17=""),"Carga de batán sin litros | ","")&IF(AND($AA17<>"",$AC17<0),"Supera saldo batán | ","")),LEN((IF($G17="","Sin unidad | ","")&IF($J17="","Sin responsable | ","")&IF($K17="","Sin obra | ","")&IF(AND($N17<>"",$G17<>"",$N17>IFERROR(INDEX('MAESTRO DE UNIDADES'!$I$2:$I$208,MATCH($G17,'MAESTRO DE UNIDADES'!$A$2:$A$208,0)),0)),"Litros > tanque | ","")&IF(AND($W17<>"",COUNTIF($W$2:$W17,$W17)>1),"Ticket duplicado | ","")&IF(AND($G17<>"",IFERROR(INDEX('MAESTRO DE UNIDADES'!$L$2:$L$208,MATCH($G17,'MAESTRO DE UNIDADES'!$A$2:$A$208,0)),"")="Inactivo"),"Unidad inactiva | ","")&IF(AND($AA17<>"",$N17=""),"Carga de batán sin litros | ","")&IF(AND($AA17<>"",$AC17<0),"Supera saldo batán | ","")))-3))) | Z17: =IF($B17="","",IF($AA17<>"","Batán","Estación de servicio")) | AB17: =IF($AA17="","",IFERROR(INDEX('CONTROL DE BATAN'!$J$2:$J$301,MATCH($AA17,'CONTROL DE BATAN'!$A$2:$A$301,0)),"")) | AC17: =IF($AA17="","",IFERROR(INDEX('CONTROL DE BATAN'!$I$2:$I$301,MATCH($AA17,'CONTROL DE BATAN'!$A$2:$A$301,0)),0)-SUMIFS($N$2:$N17,$AA$2:$AA17,$AA17))
A18: =IF(B18="","","CARGA-"&TEXT(ROW()-1,"0000")) | C18: =IF(B18="","",CHOOSE(MONTH(B18),"Enero","Febrero","Marzo","Abril","Mayo","Junio","Julio","Agosto","Septiembre","Octubre","Noviembre","Diciembre")) | D18: =IF(B18="","",YEAR(B18)) | E18: =IF(B18="","",CHOOSE(WEEKDAY(B18,2),"Lunes","Martes","Miércoles","Jueves","Viernes","Sábado","Domingo")) | H18: =IF($G18="","",IFERROR(INDEX('MAESTRO DE UNIDADES'!$F$2:$F$208,MATCH($G18,'MAESTRO DE UNIDADES'!$A$2:$A$208,0)),"")) | I18: =IF($G18="","",IFERROR(INDEX('MAESTRO DE UNIDADES'!$B$2:$B$208,MATCH($G18,'MAESTRO DE UNIDADES'!$A$2:$A$208,0)),"")) | M18: =IF($G18="","",IFERROR(INDEX('MAESTRO DE UNIDADES'!$H$2:$H$208,MATCH($G18,'MAESTRO DE UNIDADES'!$A$2:$A$208,0)),"")) | P18: =IF($N18="","",IF($AA18<>"",IF($AB18="","",$N18*$AB18),IF($O18="","",$N18*$O18))) | S18: =IF(OR($G18="",$Q18="",COUNTIF($G$2:G17,$G18)=0),"",$Q18-LOOKUP(2,1/($G$2:G17=$G18),$Q$2:Q17)) | T18: =IF(OR($G18="",$R18="",COUNTIF($G$2:G17,$G18)=0),"",$R18-LOOKUP(2,1/($G$2:G17=$G18),$R$2:R17)) | U18: =IF(N18="","",IF(S18<>"",S18/N18,IF(T18<>"",T18/N18,""))) | Y18: =IF($B18="","",IF((IF($G18="","Sin unidad | ","")&IF($J18="","Sin responsable | ","")&IF($K18="","Sin obra | ","")&IF(AND($N18<>"",$G18<>"",$N18>IFERROR(INDEX('MAESTRO DE UNIDADES'!$I$2:$I$208,MATCH($G18,'MAESTRO DE UNIDADES'!$A$2:$A$208,0)),0)),"Litros > tanque | ","")&IF(AND($W18<>"",COUNTIF($W$2:$W18,$W18)>1),"Ticket duplicado | ","")&IF(AND($G18<>"",IFERROR(INDEX('MAESTRO DE UNIDADES'!$L$2:$L$208,MATCH($G18,'MAESTRO DE UNIDADES'!$A$2:$A$208,0)),"")="Inactivo"),"Unidad inactiva | ","")&IF(AND($AA18<>"",$N18=""),"Carga de batán sin litros | ","")&IF(AND($AA18<>"",$AC18<0),"Supera saldo batán | ",""))="","OK",LEFT((IF($G18="","Sin unidad | ","")&IF($J18="","Sin responsable | ","")&IF($K18="","Sin obra | ","")&IF(AND($N18<>"",$G18<>"",$N18>IFERROR(INDEX('MAESTRO DE UNIDADES'!$I$2:$I$208,MATCH($G18,'MAESTRO DE UNIDADES'!$A$2:$A$208,0)),0)),"Litros > tanque | ","")&IF(AND($W18<>"",COUNTIF($W$2:$W18,$W18)>1),"Ticket duplicado | ","")&IF(AND($G18<>"",IFERROR(INDEX('MAESTRO DE UNIDADES'!$L$2:$L$208,MATCH($G18,'MAESTRO DE UNIDADES'!$A$2:$A$208,0)),"")="Inactivo"),"Unidad inactiva | ","")&IF(AND($AA18<>"",$N18=""),"Carga de batán sin litros | ","")&IF(AND($AA18<>"",$AC18<0),"Supera saldo batán | ","")),LEN((IF($G18="","Sin unidad | ","")&IF($J18="","Sin responsable | ","")&IF($K18="","Sin obra | ","")&IF(AND($N18<>"",$G18<>"",$N18>IFERROR(INDEX('MAESTRO DE UNIDADES'!$I$2:$I$208,MATCH($G18,'MAESTRO DE UNIDADES'!$A$2:$A$208,0)),0)),"Litros > tanque | ","")&IF(AND($W18<>"",COUNTIF($W$2:$W18,$W18)>1),"Ticket duplicado | ","")&IF(AND($G18<>"",IFERROR(INDEX('MAESTRO DE UNIDADES'!$L$2:$L$208,MATCH($G18,'MAESTRO DE UNIDADES'!$A$2:$A$208,0)),"")="Inactivo"),"Unidad inactiva | ","")&IF(AND($AA18<>"",$N18=""),"Carga de batán sin litros | ","")&IF(AND($AA18<>"",$AC18<0),"Supera saldo batán | ","")))-3))) | Z18: =IF($B18="","",IF($AA18<>"","Batán","Estación de servicio")) | AB18: =IF($AA18="","",IFERROR(INDEX('CONTROL DE BATAN'!$J$2:$J$301,MATCH($AA18,'CONTROL DE BATAN'!$A$2:$A$301,0)),"")) | AC18: =IF($AA18="","",IFERROR(INDEX('CONTROL DE BATAN'!$I$2:$I$301,MATCH($AA18,'CONTROL DE BATAN'!$A$2:$A$301,0)),0)-SUMIFS($N$2:$N18,$AA$2:$AA18,$AA18))
A19: =IF(B19="","","CARGA-"&TEXT(ROW()-1,"0000")) | C19: =IF(B19="","",CHOOSE(MONTH(B19),"Enero","Febrero","Marzo","Abril","Mayo","Junio","Julio","Agosto","Septiembre","Octubre","Noviembre","Diciembre")) | D19: =IF(B19="","",YEAR(B19)) | E19: =IF(B19="","",CHOOSE(WEEKDAY(B19,2),"Lunes","Martes","Miércoles","Jueves","Viernes","Sábado","Domingo")) | H19: =IF($G19="","",IFERROR(INDEX('MAESTRO DE UNIDADES'!$F$2:$F$208,MATCH($G19,'MAESTRO DE UNIDADES'!$A$2:$A$208,0)),"")) | I19: =IF($G19="","",IFERROR(INDEX('MAESTRO DE UNIDADES'!$B$2:$B$208,MATCH($G19,'MAESTRO DE UNIDADES'!$A$2:$A$208,0)),"")) | M19: =IF($G19="","",IFERROR(INDEX('MAESTRO DE UNIDADES'!$H$2:$H$208,MATCH($G19,'MAESTRO DE UNIDADES'!$A$2:$A$208,0)),"")) | P19: =IF($N19="","",IF($AA19<>"",IF($AB19="","",$N19*$AB19),IF($O19="","",$N19*$O19))) | S19: =IF(OR($G19="",$Q19="",COUNTIF($G$2:G18,$G19)=0),"",$Q19-LOOKUP(2,1/($G$2:G18=$G19),$Q$2:Q18)) | T19: =IF(OR($G19="",$R19="",COUNTIF($G$2:G18,$G19)=0),"",$R19-LOOKUP(2,1/($G$2:G18=$G19),$R$2:R18)) | U19: =IF(N19="","",IF(S19<>"",S19/N19,IF(T19<>"",T19/N19,""))) | Y19: =IF($B19="","",IF((IF($G19="","Sin unidad | ","")&IF($J19="","Sin responsable | ","")&IF($K19="","Sin obra | ","")&IF(AND($N19<>"",$G19<>"",$N19>IFERROR(INDEX('MAESTRO DE UNIDADES'!$I$2:$I$208,MATCH($G19,'MAESTRO DE UNIDADES'!$A$2:$A$208,0)),0)),"Litros > tanque | ","")&IF(AND($W19<>"",COUNTIF($W$2:$W19,$W19)>1),"Ticket duplicado | ","")&IF(AND($G19<>"",IFERROR(INDEX('MAESTRO DE UNIDADES'!$L$2:$L$208,MATCH($G19,'MAESTRO DE UNIDADES'!$A$2:$A$208,0)),"")="Inactivo"),"Unidad inactiva | ","")&IF(AND($AA19<>"",$N19=""),"Carga de batán sin litros | ","")&IF(AND($AA19<>"",$AC19<0),"Supera saldo batán | ",""))="","OK",LEFT((IF($G19="","Sin unidad | ","")&IF($J19="","Sin responsable | ","")&IF($K19="","Sin obra | ","")&IF(AND($N19<>"",$G19<>"",$N19>IFERROR(INDEX('MAESTRO DE UNIDADES'!$I$2:$I$208,MATCH($G19,'MAESTRO DE UNIDADES'!$A$2:$A$208,0)),0)),"Litros > tanque | ","")&IF(AND($W19<>"",COUNTIF($W$2:$W19,$W19)>1),"Ticket duplicado | ","")&IF(AND($G19<>"",IFERROR(INDEX('MAESTRO DE UNIDADES'!$L$2:$L$208,MATCH($G19,'MAESTRO DE UNIDADES'!$A$2:$A$208,0)),"")="Inactivo"),"Unidad inactiva | ","")&IF(AND($AA19<>"",$N19=""),"Carga de batán sin litros | ","")&IF(AND($AA19<>"",$AC19<0),"Supera saldo batán | ","")),LEN((IF($G19="","Sin unidad | ","")&IF($J19="","Sin responsable | ","")&IF($K19="","Sin obra | ","")&IF(AND($N19<>"",$G19<>"",$N19>IFERROR(INDEX('MAESTRO DE UNIDADES'!$I$2:$I$208,MATCH($G19,'MAESTRO DE UNIDADES'!$A$2:$A$208,0)),0)),"Litros > tanque | ","")&IF(AND($W19<>"",COUNTIF($W$2:$W19,$W19)>1),"Ticket duplicado | ","")&IF(AND($G19<>"",IFERROR(INDEX('MAESTRO DE UNIDADES'!$L$2:$L$208,MATCH($G19,'MAESTRO DE UNIDADES'!$A$2:$A$208,0)),"")="Inactivo"),"Unidad inactiva | ","")&IF(AND($AA19<>"",$N19=""),"Carga de batán sin litros | ","")&IF(AND($AA19<>"",$AC19<0),"Supera saldo batán | ","")))-3))) | Z19: =IF($B19="","",IF($AA19<>"","Batán","Estación de servicio")) | AB19: =IF($AA19="","",IFERROR(INDEX('CONTROL DE BATAN'!$J$2:$J$301,MATCH($AA19,'CONTROL DE BATAN'!$A$2:$A$301,0)),"")) | AC19: =IF($AA19="","",IFERROR(INDEX('CONTROL DE BATAN'!$I$2:$I$301,MATCH($AA19,'CONTROL DE BATAN'!$A$2:$A$301,0)),0)-SUMIFS($N$2:$N19,$AA$2:$AA19,$AA19))
A20: =IF(B20="","","CARGA-"&TEXT(ROW()-1,"0000")) | C20: =IF(B20="","",CHOOSE(MONTH(B20),"Enero","Febrero","Marzo","Abril","Mayo","Junio","Julio","Agosto","Septiembre","Octubre","Noviembre","Diciembre")) | D20: =IF(B20="","",YEAR(B20)) | E20: =IF(B20="","",CHOOSE(WEEKDAY(B20,2),"Lunes","Martes","Miércoles","Jueves","Viernes","Sábado","Domingo")) | H20: =IF($G20="","",IFERROR(INDEX('MAESTRO DE UNIDADES'!$F$2:$F$208,MATCH($G20,'MAESTRO DE UNIDADES'!$A$2:$A$208,0)),"")) | I20: =IF($G20="","",IFERROR(INDEX('MAESTRO DE UNIDADES'!$B$2:$B$208,MATCH($G20,'MAESTRO DE UNIDADES'!$A$2:$A$208,0)),"")) | P20: =IF($N20="","",IF($AA20<>"",IF($AB20="","",$N20*$AB20),IF($O20="","",$N20*$O20))) | S20: =IF(OR($G20="",$Q20="",COUNTIF($G$2:G19,$G20)=0),"",$Q20-LOOKUP(2,1/($G$2:G19=$G20),$Q$2:Q19)) | T20: =IF(OR($G20="",$R20="",COUNTIF($G$2:G19,$G20)=0),"",$R20-LOOKUP(2,1/($G$2:G19=$G20),$R$2:R19)) | U20: =IF(N20="","",IF(S20<>"",S20/N20,IF(T20<>"",T20/N20,""))) | Y20: =IF($B20="","",IF((IF($G20="","Sin unidad | ","")&IF($J20="","Sin responsable | ","")&IF($K20="","Sin obra | ","")&IF(AND($N20<>"",$G20<>"",$N20>IFERROR(INDEX('MAESTRO DE UNIDADES'!$I$2:$I$208,MATCH($G20,'MAESTRO DE UNIDADES'!$A$2:$A$208,0)),0)),"Litros > tanque | ","")&IF(AND($W20<>"",COUNTIF($W$2:$W20,$W20)>1),"Ticket duplicado | ","")&IF(AND($G20<>"",IFERROR(INDEX('MAESTRO DE UNIDADES'!$L$2:$L$208,MATCH($G20,'MAESTRO DE UNIDADES'!$A$2:$A$208,0)),"")="Inactivo"),"Unidad inactiva | ","")&IF(AND($AA20<>"",$N20=""),"Carga de batán sin litros | ","")&IF(AND($AA20<>"",$AC20<0),"Supera saldo batán | ",""))="","OK",LEFT((IF($G20="","Sin unidad | ","")&IF($J20="","Sin responsable | ","")&IF($K20="","Sin obra | ","")&IF(AND($N20<>"",$G20<>"",$N20>IFERROR(INDEX('MAESTRO DE UNIDADES'!$I$2:$I$208,MATCH($G20,'MAESTRO DE UNIDADES'!$A$2:$A$208,0)),0)),"Litros > tanque | ","")&IF(AND($W20<>"",COUNTIF($W$2:$W20,$W20)>1),"Ticket duplicado | ","")&IF(AND($G20<>"",IFERROR(INDEX('MAESTRO DE UNIDADES'!$L$2:$L$208,MATCH($G20,'MAESTRO DE UNIDADES'!$A$2:$A$208,0)),"")="Inactivo"),"Unidad inactiva | ","")&IF(AND($AA20<>"",$N20=""),"Carga de batán sin litros | ","")&IF(AND($AA20<>"",$AC20<0),"Supera saldo batán | ","")),LEN((IF($G20="","Sin unidad | ","")&IF($J20="","Sin responsable | ","")&IF($K20="","Sin obra | ","")&IF(AND($N20<>"",$G20<>"",$N20>IFERROR(INDEX('MAESTRO DE UNIDADES'!$I$2:$I$208,MATCH($G20,'MAESTRO DE UNIDADES'!$A$2:$A$208,0)),0)),"Litros > tanque | ","")&IF(AND($W20<>"",COUNTIF($W$2:$W20,$W20)>1),"Ticket duplicado | ","")&IF(AND($G20<>"",IFERROR(INDEX('MAESTRO DE UNIDADES'!$L$2:$L$208,MATCH($G20,'MAESTRO DE UNIDADES'!$A$2:$A$208,0)),"")="Inactivo"),"Unidad inactiva | ","")&IF(AND($AA20<>"",$N20=""),"Carga de batán sin litros | ","")&IF(AND($AA20<>"",$AC20<0),"Supera saldo batán | ","")))-3))) | Z20: =IF($B20="","",IF($AA20<>"","Batán","Estación de servicio")) | AB20: =IF($AA20="","",IFERROR(INDEX('CONTROL DE BATAN'!$J$2:$J$301,MATCH($AA20,'CONTROL DE BATAN'!$A$2:$A$301,0)),"")) | AC20: =IF($AA20="","",IFERROR(INDEX('CONTROL DE BATAN'!$I$2:$I$301,MATCH($AA20,'CONTROL DE BATAN'!$A$2:$A$301,0)),0)-SUMIFS($N$2:$N20,$AA$2:$AA20,$AA20))
