Workbook

Sheet RESUMEN DICIEMBRE 2025
A1: RESUMEN FINANCIERO DICIEMBRE 2025
A2: ECHEQ A DEVENGAR
A3: INVERSIONES BALANZ | B3: 55510999
A4: SALDO BANCO ECAR | B4: 840000
A5: DISPONIBILIDAD FINANCIERA DICIEMBRE 2025- ECAR | B5: =+SUM(B2:B4) -> 56350999
A6: FALTA PAGOS DICIEMBRE 2025 | B6: =+'GASTOS MENSUALES 2026 '!D55 -> 0
A7: DISPONIBILIDAD - DESEMBOLSO | B7: =+B5-B6 -> 56350999

Sheet RESUMEN FINANCIERO ENERO 2026
A1: RESUMEN FINANCIERO ENERO 2026
A2: ECHEQ A ACREDITAR
A3: INVERSIONES BALANZ | B3: =+B5-B4 -> 29936476
A4: SALDO BANCO ECAR | B4: 1658909.6
A5: DISPONIBILIDAD FINANCIERA ENERO 2026 - ECAR | B5: =+B7 -> 31595386
A6: FALTA PAGOS ENERO 2026
A7: DISPONIBILIDAD FINAL ENERO 2026 | B7: 31595386

Sheet RESUMEN FEBRERO 2026 
A1: RESUMEN FINANCIERO FEBRERO 2026
A2: ECHEQ A ACREDITAR
A3: INVERSIONES BALANZ | B3: 58849928
A4: SALDO BANCO ECAR | B4: 587574
A5: DISPONIBILIDAD FINANCIERA FEBRERO 2026 - ECAR | B5: =+SUM(B2:B4) -> 59437502
A6: FALTA PAGOS FEBRERO 2026 | B6: =+'GASTOS MENSUALES 2026 '!G55 -> 0
A7: DISPONIBILIDAD FINAL FEBRERO 2026 | B7: =+B5-B6 -> 59437502

Sheet RESUMEN MARZO 2026
A1: RESUMEN FINANCIERO MARZO 2026
A2: EFECTIVO | B2: 2723800
A3: INVERSIONES BALANZ | B3: 73647952 | C3: 22800000 | D3: venta de maxion 4x4
A4: SALDO BANCO ECAR | B4: 2939598
A5: DISPONIBILIDAD FINANCIERA MARZO 2026 - ECAR | B5: =+B3+B4+B2 -> 79311350
A6: FALTAN PAGOS ECAR MARZO 2026 | B6: =+'GASTOS MENSUALES 2026 '!I55 -> 0
A7: DISPONIBILIDAD FINAL MARZO 2026 AL 31/03/2026 | B7: =+B5-B6 -> 79311350

Sheet CHEQUES EMITIDOS 
A1: CHEQUES O ECHEQ EMITIDOS 2026
B2: MATRIGAS | C2: 337000 | D2: 46024 | E2: BCO. SANTANDER | F2: 46024
B3: FICAMEN | C3: 372236.18 | D3: 46024 | E3: BCO. SANTANDER | F3: 46024
A4: 477 | B4: HERREMAQ | C4: 423000 | D4: 46011 | E4: BCO. SANTANDER | F4: 46013
A5: ECHEQ | B5: UOCRA | C5: 206505.25 | D5: 46020 | E5: BCO. SANTANDER | F5: 46020 | G5: 30640033173 | H5: CUIT
A6: ECHEQ | B6: OSPECON | C6: 167036.5 | D6: 46020 | E6: BCO. SANTANDER | F6: 46020 | G6: 30640033173 | H6: CUIT
B7: PLACAS ARGENTINA | C7: 234000 | D7: 46028 | E7: BCO. SANTANDER | F7: 46028
A8: 480 | B8: MIASA | C8: 3466387 | D8: 46032 | E8: BCO. SANTANDER | F8: 45669
A9: ECEHQ | B9: MAR-SAN | C9: 151100 | D9: 46032 | E9: BCO. SANTANDER | F9: 45669
A10: 442 | B10: MATRIGAS | C10: 2427932.1 | D10: 46037 | E10: BCO. SANTANDER | F10: 46037
A11: ECHEQ | B11: ITAL VINIL | C11: 2542821 | D11: 46037 | E11: BCO. SANTANDER | F11: 46037 | H11: =+SUM(C2:C22) -> 58246232
A12: ECHEQ | B12: CUYO PARTS | C12: 486029.2 | D12: 46038 | E12: BCO. SANTANDER | F12: 46038
A13: 489 | B13: MARIO VILLARROEL | C13: 564923 | D13: 46038 | E13: BCO. SANTANDER | F13: 46038
A14: 431 | B14: FATE | C14: 236045 | D14: 46042 | E14: BCO. SANTANDER | F14: 46042
B15: TRANSP. GONZALITO | C15: 665500 | D15: 45677 | E15: BCO. SANTANDER | F15: 45677
A16: 488 | B16: ESTACION CENTRAL | C16: 2917830 | D16: 46045 | E16: BCO. SANTANDER | F16: 45680
A17: ECEHQ | B17: OSCAR SCORZA | C17: 13000000 | D17: 46048 | E17: BCO. SANTANDER | F17: 46048
B18: DANIEL BOLLATTI | C18: 378000 | D18: 45680 | E18: BCO. SANTANDER | F18: 45680
B19: 46023 | C19: =+SUM(C2:C18) -> 28576345
A20: 484 | B20: DISCO COMPUTADORA | C20: 720000 | D20: 46039 | E20: BCO. SANTANDER | F20: 46041
A21: ECHEQ 539 | B21: UOCRA | C21: 206505.25 | D21: 46051 | E21: BCO. SANTANDER | F21: 46051 | G21: 30640033173 | H21: CUIT
A22: ECHEQ 540 | B22: OSPECON | C22: 167036.5 | D22: 46051 | E22: BCO. SANTANDER | F22: 46051 | G22: 30640033173 | H22: CUIT
A23: ECHEQ | B23: ITAL VINIL | C23: 2542822 | D23: 46059 | E23: BCO. SANTANDER | F23: 46059
A24: 487 | B24: RESSI | C24: 319484.74 | D24: 46056 | E24: BCO. SANTANDER | F24: 46056
A25: 481 | B25: MIASA | C25: 3466387 | D25: 45698 | E25: BCO. SANTANDER | F25: 45698
A26: 492 | B26: VOXOIL ( RAM) | C26: 678568 | D26: 46068 | E26: BCO. SANTANDER | F26: 46071
A27: ECHEQ 542 | B27: ITAL VINIL | C27: 1851974.9 | D27: 46069 | E27: BCO. SANTANDER | F27: 46071
A28: 485 | B28: DISCO COMPUTADORA | C28: 720000 | D28: 46070 | E28: BCO. SANTANDER | F28: 46071
A29: 490 | B29: MARIO VILLARROEL | C29: 414409 | D29: 46069 | E29: BCO. SANTANDER | F29: 46071
B30: DANIEL BOLLATTI | C30: 378000 | D30: 46073 | E30: BCO. SANTANDER | F30: 46073 | G30: =+SUM(C20:C37) -> 28186931
A31: 491 | B31: INDUSTRIAS HORMAT | C31: 625000 | D31: 46076 | E31: BCO. SANTANDER | F31: 46076
A32: 514 | B32: ESTACION CENTRAL | C32: 2504575 | D32: 46076 | E32: BCO. SANTANDER | F32: 46076
A33: ECEHQ | B33: OSCAR SCORZA | C33: 13000000 | D33: 46079 | E33: BCO. SANTANDER | F33: 46079
B34: 46054 | G34: =+SUM(C20:C33) -> 27594762
A35: ECHEQ 544 | B35: DAGFALT | C35: 218626.88 | D35: 46084 | E35: BCO. SANTANDER | F35: 46084
A36: 38600001 | B36: UOCRA | C36: 206505.25 | D36: 46081 | E36: BCO. SANTANDER | F36: 46083 | G36: 30640033173 | H36: CUIT
A37: 38600002 | B37: OSPECON | C37: 167036.5 | D37: 46081 | E37: BCO. SANTANDER | F37: 46083 | G37: 30640033173 | H37: CUIT
A38: 512 | B38: KATSUDA | C38: 228737.47 | D38: 46084 | E38: BCO. SANTANDER | F38: 46084
A39: 513 | B39: JANIN | C39: 594400 | D39: 46087 | E39: BCO. SANTANDER | F39: 46087
A40: ECHEQ 541 | B40: ITAL VINIL | C40: 1851974.9 | D40: 46087 | E40: BCO. SANTANDER | F40: 46087
...

Sheet ECHEQ RECIBIDOC
B1: ENERO
A2: Valdivieso Group SRL | B2: 46032 | C2: 1643018.4 | D2: 45669 | E2: COBRADO
C3: =+C2 -> 1643018.4
B4: ABRIL
A5: GALVARINI Y ASOCIADOS SRL | B5: 46134 | C5: 2814417.6 | D5: 46134 | E5: COBRADO

Sheet OBRAS
A1: RESUMEN OBRAS | J1: A COBRAR OBRAS | K1: COBRADO OCTUBRE 2025 | L1: COBRADO NOV 2025 | M1: A COBRAR DICIEMBRE | N1: A COBRADO ENERO 2026 | O1: COBRADO FEBRERO 2026 | P1: COBRADO MARZO 2026 | Q1: A COBRAR ABRIL 2026
S2: ESTIMADO A COBRAR
A3: CALIDRA OC N°1616 | B3: 70%( COBRADO) | C3: SALDO | S3: FACURADO
A4: 54891681 | B4: 38424177 | C4: =+A4-B4 -> 16467504 | D4: IVA INCLUIDO | J4: =+C4 -> 16467504 | S4: COBRADO
A6: REPARACIONES GALVARINI - CALIDRA | C6: 2985806
C7: 2814417.6 | Q7: =+C7 -> 2814417.6
A9: BARRIO SAN MARTIN
D10: CERTIFICADO 1 | E10: CERTIFICADO 2 | F10: CERTIFICADO 3 | G10: CERTIFICADO 4 | H10: CERTIFICADO 5 | I10: CERTIFICADO 6
A11: CONTRATO | B11: ANTICIPO(30%) | C11: REDETERMINACION ANTICIPO | D11: CERT REDETER. 01/09/2025 | E11: CERT REDETER. 02/10/2025 | F11: CERT REDETER. 03/11/2025 | G11: CERT REDETER. 04/12/2025 | H11: CERT REDETER. 18/02/2026 | I11: CERT REDETER. 31/03/2026
A12: 1.7266506e+08 | B12: 51799519 | C12: 2688941.3 | D12: 35260237 | E12: 22520107 | F12: 41962706 | G12: 2792808.1 | H12: 13535071 | I12: 4794614.4 | J12: =+A12-B12-D12-E12-F12-G12-H12 -> 4794614.4
D13: 1138182.9 | E13: 1846986.9 | F13: 3134739.9 | G13: 293203.69 | H13: 1740323.6 | I13: 635172.55 | O13: =+G15 -> 2941981.1
D14: =+D12+D13 -> 36398420 | E14: =+E12+E13 -> 24367094 | F14: =+F12+F13 -> 45097445 | G14: =+G12+G13 -> 3086011.8 | H14: =+H12+H13 -> 15275395 | I14: =+I12+I13 -> 5429786.9 | O14: =+F15 -> 42974364
A15: DEPOSITO BANCO | B15: 49073040 | C15: 2563615.6 | D15: 34685127 | E15: 23220566 | F15: 42974364 | G15: 2941981.1 | H15: 14509971 | K15: =+SUM(B15:C15) -> 51636655 | L15: =+D15 -> 34685127 | M15: =+E15 -> 23220566 | Q15: =+H15 -> 14509971
A17: ESCUELA SANTIAGO DEL ESTERO
D18: CERTIFICADO 1 | E18: CERTIFICADO 2 | F18: CERTIFICADO 3 | G18: CERTIFICADO 4
A19: CONTRATO | B19: ANTICIPO | C19: REDETERMINACION ANTICIPO | D19: CERT REDETER 09/2025 | E19: CERT REDETER. 02/10 | F19: CERT REDETER. 03/11 | G19: CERT REDETER. 04/12
A20: 79457864 | B20: 7945786.4 | C20: 229128.31 | D20: 30635324 | E20: 27296344 | F20: 7822754.6 | G20: 5757654.8 | J20: =+A20-B20-D20-E20-F20-G20 -> 0
D21: 784891.34 | E21: 1569281.9 | F21: 539013.17 | G21: 546710.77
D22: =+D20+D21 -> 31420215 | E22: =+E20+E21 -> 28865626 | F22: =+F20+F21 -> 8361767.8 | G22: =+G20+G21 -> 6304365.6
A23: DEPOSITO BANCO | B23: 7572824.2 | C23: 219678.05 | D23: 20019134 | E23: 27507184 | F23: 7969209.7 | G23: 6008726.5 | K23: =+SUM(B23:C23) -> 7792502.2 | M23: =+E23 -> 27507184 | N23: =+F23 -> 7969209.7 | O23: =+G23 -> 6008726.5
D24: 9922298.8 | G24: FINAL
D25: =+D23+D24 -> 29941433 | L25: =+D25 -> 29941433
A26: BARRIO ASEC I ( MDO )
A27: CONTRATO | B27: CERTIFICADO Nº1
A28: 67500000 | B28: 30037500 | J28: =+A28-B28 -> 37462500 | O28: 30037500
A30: BARRIO LA TRANQUERA (MDO )
A31: CONTRATO
A32: 42900000
A34: BARRIO DON JOSE
A35: CONTRATO | B35: ANTICIPO(10%) | C35: REDETERMINACION ANTICIPO | D35: CERTIFICADO 1 | E35: CERTIFICADO 2 | F35: CERTIFICADO 3 | G35: CERTIFICADO 4 | H35: CERTIFICADO 5
A36: 1.8175296e+08 | B36: 18175296 | C36: 1730179.3 | D36: CERT REDETER 01/11/2025 | E36: CERT REDETER. 02/12/2025 | F36: CERT REDETER. 03/01/2026 | G36: CERT REDETER. 04/2/2026 | H36: CERT REDETER. 04/2/2026 | J36: =+A36-B36-D37-E37-F37-G37 -> 84443390
D37: 10085647 | E37: 9343580.6 | F37: 14364663 | G37: 45340385 | H37: 50645033
D38: 931276.22 | E38: 925689.51 | F38: 1794766.2 | G38: 6631635.4 | H38: 8239263.2
A39: DEPOSITO BANCO | B39: 17125176 | C39: 1631429.7 | D39: =+SUM(D37:D38) -> 11016923 | E39: =+E37+E38 -> 10269270 | F39: =+F38+F37 -> 16159429 | G39: =+G37+G38 -> 51972021 | H39: =+H37+H38 -> 58884297 | N39: =+B39+C39 -> 18756606 | P39: =+F40 -> 15225930
D40: 10380924 | E40: 9676523.5 | F40: 15225930 | O40: =+D40 -> 10380924 | P40: 9676523.5
F41: 46122 | G41: 25459331
F42: 46125 | G42: 23507387
G43: =+G41+G42 -> 48966718 | Q43: =+G43 -> 48966718
A44: SERVICIOS BARRIO DON JOSE | C44: 28/02/206 | D44: 46090 | E44: 46099 | F44: 46112 | G44: MARZO
C45: 6000000 | D45: 1600000 | E45: 2300000 | F45: 2275000 | G45: =+SUM(C45:F45) -> 12175000 | P45: =+C45+D45+E45+F45 -> 12175000
...

Sheet Hoja1

Sheet GASTOS MENSUALES 2026 
A1: RESUMEN GASTOS MESUALES 2025- 2026 ECAR
A2: DESCRIPCION | C2: 45992 | D2: PAGADO EN DIC | E2: 46023 | F2: 46054 | G2: FALTA PAGO FEBRERO 2026 | H2: 46082 | I2: FALTAN PAGOS MARZO 2026 | J2: 46113 | K2: 46143 | L2: FALTAN PAGOS MAYO 2026
A3: PERSONAL ECAR- HONORARIOS | B3: SUELDOS OBREROS | C3: 8462000 | E3: 875000 | F3: 2300985.3 | H3: 2970050 | J3: 1773760 | K3: 2200000
E4: 1875000 | F4: 1865000 | H4: 2054600 | J4: 2034760 | K4: 2200000
E5: 2030000 | F5: 1925000 | H5: 1710600 | J5: 1499520 | K5: 2200000
E6: 2531851.3 | F6: 1913800 | H6: 1706920 | J6: 1596800 | K6: 2200000
E7: 2155985.3 | J7: 1700480
B8: GUSTAVO REGALADO | C8: 2000000 | E8: 2225000 | F8: 2500000 | H8: 2500000 | J8: 3500000 | K8: 2500000
B9: ADOLFO | F9: 2500000 | K9: 2500000
B10: FERNANDO ORTIZ (DPRG) | C10: 700000 | J10: 500000
B11: ELIO | C11: 960000 | E11: 960000 | F11: =960000+480000 -> 1440000 | H11: 480000 | J11: 960000
B12: GABRIELA | C12: 400000 | E12: 500000
B13: ENRICO | F13: 480000 | H13: 500000 | J13: 500000 | K13: 500000
B14: DEBORA REC. HYS ALBARDON | C14: 220000 | F14: 300000 | H14: 300000 | J14: 300000 | K14: 300000
B15: BRUNO GUEVARA | C15: 200000 | E15: 400000 | F15: 500000 | H15: 500000 | J15: 1000000 | K15: 1000000
E16: 1000000 | J16: 1000000
A17: ESTUDIO CONTABLE(HONORARIOS)SE PAGA CON ECHEQ
A18: SEGUROS | B18: ACCID. PERSONALES
B19: SEGUROS LIDERAR | C19: 403700 | E19: 407600 | F19: 407600 | H19: 447600 | J19: =473500+240000 -> 713500 | K19: 240000
A20: SERVICIOS | B20: OSSE ALMAFUERTE Y SANTA FE | H20: =562589.64+566442.66 -> 1129032.3
B21: NATURGY ALMAFUERTE | C21: 109000 | E21: 48113.54 | F21: =64151.77+64925.23 -> 129077 | H21: 88310.69 | J21: 88099.02 | K21: 110119.81
B22: NATURGY CORDOBA | E22: 16493.47 | F22: 36160.56 | H22: 36947.36 | J22: 44166.02 | K22: 44148.85
B23: NATURGY Bº RIVADAVIA | E23: =2970.59+6287.59 -> 9258.18 | F23: =8642+8663.3 -> 17305.3 | H23: 4352.73 | J23: 8518.75
B24: NATURGY ORO | F24: 3026.32 | H24: 3118.57 | J24: 3492.78
B25: GAS CORDOBA | C25: 3973.33 | E25: 3747.49 | F25: =3983.62+3839.62 -> 7823.24 | H25: 4104.45 | J25: 4029.72
B26: GAS Bº RIVADAVIA | E26: 31492.47 | F26: 3765.87 | H26: =5252.13+3963.79 -> 9215.92 | J26: 4156.55
B27: GAS ORO | E27: 120367.79 | F27: 13823.25 | H27: 4044.23
B28: EXPENSAS CORDOBA | E28: 29000 | F28: 35000 | H28: 40000 | J28: 56000
B29: EXPENSAS ORO | E29: 31901.18 | F29: 16156.08 | H29: 26554.51 | J29: 91637.48
B30: TELEFONIA GUSTAVO | C30: 163000 | E30: 62120.45 | F30: 63562.55 | H30: 65521.7 | J30: 65965.08 | K30: 67592.39
B31: TELEFONIA ADOLFO | E31: 48600.01 | F31: 49849.91 | H31: 50699.99 | J31: 51695.14 | K31: 52695.14
B32: TELEFONIA GABRIELA | E32: 63814.21 | F32: 65480.22 | H32: 66699.6 | J32: 68128.63 | K32: 69525.12
B33: INTERNET DEPO | C33: 63000 | E33: 27400 | F33: 64151.77 | H33: 27000 | J33: 24800
B34: INTERNET OFICINA | E34: 75450.22 | F34: 0 | H34: 44942.41 | J34: 49839.74 | K34: 58069.59
A35: IMPUESTOS ARCA/ PROVINCIA | B35: FORM. 931 | C35: 2768061.8 | E35: 4315469.7 | F35: 2568957.7 | H35: 2254509.5 | J35: 3322811 | K35: 3322811
B36: AUTONOMOS | C36: 119660.24 | E36: 122460.3 | F36: 125485.06 | H36: 129061.38 | J36: 132778.36 | K36: 136628.92
B37: IVA | C37: 8237589.5 | E37: 4023724.5 | F37: 10293676 | H37: 3989738.8 | J37: 2823525.2 | K37: 7249102.5
B38: PLAN DE PAGO AFIP | C38: 113840.32 | E38: 111784.34 | F38: 109728.34 | H38: 107672.35 | J38: 101731.03
B39: AUTOMOTORES | C39: 238986 | K39: =25040.01+68281.49+125736.69+49781.51+63253.28 -> 332092.98
B40: INMOBILIARIO Vº AMERICA | F40: 44997.3
...

Sheet RESUMEN ABRIL 2026
A1: RESUMEN FINANCIERO ABRIL 2026
A2: EFECTIVO | B2: 975000
A3: INVERSIONES BALANZ | B3: 103045454
A4: SALDO BANCO ECAR | B4: 3504828
A5: DISPONIBILIDAD FINANCIERA ABRIL 2026 - ECAR | B5: =+B3+B4+B2 -> 107525282
A6: PAGOS REALIZADOS ECAR ABRIL 2026
A7: DISPONIBILIDAD FINAL ABRIL 2026 | B7: =+B5-B6 -> 107525282
